return {{["x"] = 0, ["y"] = 1, ["z"] = 7, ["name"] = "cloud_items:cloud"}, {["x"] = 0, ["y"] = 1, ["z"] = 8, ["name"] = "cloud_items:cloud"}, {["x"] = 0, ["y"] = 1, ["z"] = 9, ["name"] = "cloud_items:cloud"}, {["x"] = 0, ["y"] = 1, ["z"] = 10, ["name"] = "cloud_items:cloud"}, {["x"] = 1, ["y"] = 1, ["z"] = 4, ["name"] = "cloud_items:cloud"}, {["x"] = 1, ["y"] = 1, ["z"] = 5, ["name"] = "cloud_items:cloud"}, {["x"] = 1, ["y"] = 1, ["z"] = 6, ["name"] = "cloud_items:cloud"}, {["x"] = 1, ["y"] = 1, ["z"] = 7, ["name"] = "cloud_items:cloud"}, {["x"] = 1, ["y"] = 1, ["z"] = 8, ["name"] = "cloud_items:cloud"}, {["x"] = 1, ["y"] = 1, ["z"] = 9, ["name"] = "cloud_items:cloud"}, {["x"] = 1, ["y"] = 1, ["z"] = 10, ["name"] = "cloud_items:cloud"}, {["x"] = 1, ["y"] = 1, ["z"] = 11, ["name"] = "cloud_items:cloud"}, {["x"] = 1, ["y"] = 2, ["z"] = 7, ["name"] = "cloud_items:cloud"}, {["x"] = 1, ["y"] = 2, ["z"] = 8, ["name"] = "cloud_items:cloud"}, {["x"] = 1, ["y"] = 2, ["z"] = 9, ["name"] = "cloud_items:cloud"}, {["x"] = 2, ["y"] = 1, ["z"] = 3, ["name"] = "cloud_items:cloud"}, {["x"] = 2, ["y"] = 1, ["z"] = 4, ["name"] = "cloud_items:cloud"}, {["x"] = 2, ["y"] = 1, ["z"] = 5, ["name"] = "cloud_items:cloud"}, {["x"] = 2, ["y"] = 1, ["z"] = 6, ["name"] = "cloud_items:cloud"}, {["x"] = 2, ["y"] = 1, ["z"] = 7, ["name"] = "cloud_items:cloud"}, {["x"] = 2, ["y"] = 1, ["z"] = 8, ["name"] = "cloud_items:cloud"}, {["x"] = 2, ["y"] = 1, ["z"] = 9, ["name"] = "cloud_items:cloud"}, {["x"] = 2, ["y"] = 1, ["z"] = 10, ["name"] = "cloud_items:cloud"}, {["x"] = 2, ["y"] = 1, ["z"] = 11, ["name"] = "cloud_items:cloud"}, {["x"] = 2, ["y"] = 1, ["z"] = 12, ["name"] = "cloud_items:cloud"}, {["x"] = 2, ["y"] = 2, ["z"] = 4, ["name"] = "cloud_items:cloud"}, {["x"] = 2, ["y"] = 2, ["z"] = 5, ["name"] = "cloud_items:cloud"}, {["x"] = 2, ["y"] = 2, ["z"] = 6, ["name"] = "cloud_items:cloud"}, {["x"] = 2, ["y"] = 2, ["z"] = 7, ["name"] = "cloud_items:cloud"}, {["x"] = 2, ["y"] = 2, ["z"] = 8, ["name"] = "cloud_items:cloud"}, {["x"] = 2, ["y"] = 2, ["z"] = 9, ["name"] = "cloud_items:cloud"}, {["x"] = 2, ["y"] = 2, ["z"] = 10, ["name"] = "cloud_items:cloud"}, {["x"] = 2, ["y"] = 2, ["z"] = 11, ["name"] = "cloud_items:cloud"}, {["x"] = 2, ["y"] = 2, ["z"] = 12, ["name"] = "cloud_items:cloud"}, {["x"] = 2, ["y"] = 3, ["z"] = 5, ["name"] = "cloud_items:cloud"}, {["x"] = 2, ["y"] = 3, ["z"] = 6, ["name"] = "cloud_items:cloud"}, {["x"] = 2, ["y"] = 3, ["z"] = 7, ["name"] = "cloud_items:cloud"}, {["x"] = 2, ["y"] = 3, ["z"] = 8, ["name"] = "cloud_items:cloud"}, {["x"] = 2, ["y"] = 3, ["z"] = 9, ["name"] = "cloud_items:cloud"}, {["x"] = 2, ["y"] = 3, ["z"] = 10, ["name"] = "cloud_items:cloud"}, {["x"] = 2, ["y"] = 3, ["z"] = 11, ["name"] = "cloud_items:cloud"}, {["x"] = 3, ["y"] = 1, ["z"] = 2, ["name"] = "cloud_items:cloud"}, {["x"] = 3, ["y"] = 1, ["z"] = 3, ["name"] = "cloud_items:cloud"}, {["x"] = 3, ["y"] = 1, ["z"] = 4, ["name"] = "cloud_items:cloud"}, {["x"] = 3, ["y"] = 1, ["z"] = 5, ["name"] = "cloud_items:cloud"}, {["x"] = 3, ["y"] = 1, ["z"] = 6, ["name"] = "cloud_items:cloud"}, {["x"] = 3, ["y"] = 1, ["z"] = 7, ["name"] = "cloud_items:cloud"}, {["x"] = 3, ["y"] = 1, ["z"] = 8, ["name"] = "cloud_items:cloud"}, {["x"] = 3, ["y"] = 1, ["z"] = 9, ["name"] = "cloud_items:cloud"}, {["x"] = 3, ["y"] = 1, ["z"] = 10, ["name"] = "cloud_items:cloud"}, {["x"] = 3, ["y"] = 1, ["z"] = 11, ["name"] = "cloud_items:cloud"}, {["x"] = 3, ["y"] = 1, ["z"] = 12, ["name"] = "cloud_items:cloud"}, {["x"] = 3, ["y"] = 1, ["z"] = 13, ["name"] = "cloud_items:cloud"}, {["x"] = 3, ["y"] = 2, ["z"] = 4, ["name"] = "cloud_items:cloud"}, {["x"] = 3, ["y"] = 2, ["z"] = 5, ["name"] = "cloud_items:cloud"}, {["x"] = 3, ["y"] = 2, ["z"] = 6, ["name"] = "cloud_items:cloud"}, {["x"] = 3, ["y"] = 2, ["z"] = 7, ["name"] = "cloud_items:cloud"}, {["x"] = 3, ["y"] = 2, ["z"] = 8, ["name"] = "cloud_items:cloud"}, {["x"] = 3, ["y"] = 2, ["z"] = 9, ["name"] = "cloud_items:cloud"}, {["x"] = 3, ["y"] = 2, ["z"] = 10, ["name"] = "cloud_items:cloud"}, {["x"] = 3, ["y"] = 2, ["z"] = 11, ["name"] = "cloud_items:cloud"}, {["x"] = 3, ["y"] = 2, ["z"] = 12, ["name"] = "cloud_items:cloud"}, {["x"] = 3, ["y"] = 3, ["z"] = 4, ["name"] = "cloud_items:cloud"}, {["x"] = 3, ["y"] = 3, ["z"] = 5, ["name"] = "cloud_items:cloud"}, {["x"] = 3, ["y"] = 3, ["z"] = 6, ["name"] = "cloud_items:cloud"}, {["x"] = 3, ["y"] = 3, ["z"] = 7, ["name"] = "cloud_items:cloud"}, {["x"] = 3, ["y"] = 3, ["z"] = 8, ["name"] = "cloud_items:cloud"}, {["x"] = 3, ["y"] = 3, ["z"] = 9, ["name"] = "cloud_items:cloud"}, {["x"] = 3, ["y"] = 3, ["z"] = 10, ["name"] = "cloud_items:cloud"}, {["x"] = 3, ["y"] = 3, ["z"] = 11, ["name"] = "cloud_items:cloud"}, {["x"] = 3, ["y"] = 3, ["z"] = 12, ["name"] = "cloud_items:cloud"}, {["x"] = 3, ["y"] = 4, ["z"] = 6, ["name"] = "cloud_items:cloud"}, {["x"] = 3, ["y"] = 4, ["z"] = 7, ["name"] = "cloud_items:cloud"}, {["x"] = 3, ["y"] = 4, ["z"] = 8, ["name"] = "cloud_items:cloud"}, {["x"] = 3, ["y"] = 4, ["z"] = 9, ["name"] = "cloud_items:cloud"}, {["x"] = 3, ["y"] = 4, ["z"] = 10, ["name"] = "cloud_items:cloud"}, {["x"] = 4, ["y"] = 1, ["z"] = 1, ["name"] = "cloud_items:cloud"}, {["x"] = 4, ["y"] = 1, ["z"] = 2, ["name"] = "cloud_items:cloud"}, {["x"] = 4, ["y"] = 1, ["z"] = 3, ["name"] = "cloud_items:cloud"}, {["x"] = 4, ["y"] = 1, ["z"] = 4, ["name"] = "cloud_items:cloud"}, {["x"] = 4, ["y"] = 1, ["z"] = 5, ["name"] = "cloud_items:cloud"}, {["x"] = 4, ["y"] = 1, ["z"] = 6, ["name"] = "cloud_items:cloud"}, {["x"] = 4, ["y"] = 1, ["z"] = 7, ["name"] = "cloud_items:cloud"}, {["x"] = 4, ["y"] = 1, ["z"] = 8, ["name"] = "cloud_items:cloud"}, {["x"] = 4, ["y"] = 1, ["z"] = 9, ["name"] = "cloud_items:cloud"}, {["x"] = 4, ["y"] = 1, ["z"] = 10, ["name"] = "cloud_items:cloud"}, {["x"] = 4, ["y"] = 1, ["z"] = 11, ["name"] = "cloud_items:cloud"}, {["x"] = 4, ["y"] = 1, ["z"] = 12, ["name"] = "cloud_items:cloud"}, {["x"] = 4, ["y"] = 1, ["z"] = 13, ["name"] = "cloud_items:cloud"}, {["x"] = 4, ["y"] = 1, ["z"] = 14, ["name"] = "cloud_items:cloud"}, {["x"] = 4, ["y"] = 2, ["z"] = 3, ["name"] = "cloud_items:cloud"}, {["x"] = 4, ["y"] = 2, ["z"] = 4, ["name"] = "cloud_items:cloud"}, {["x"] = 4, ["y"] = 2, ["z"] = 5, ["name"] = "cloud_items:cloud"}, {["x"] = 4, ["y"] = 2, ["z"] = 6, ["name"] = "cloud_items:cloud"}, {["x"] = 4, ["y"] = 2, ["z"] = 7, ["name"] = "cloud_items:cloud"}, {["x"] = 4, ["y"] = 2, ["z"] = 8, ["name"] = "cloud_items:cloud"}, {["x"] = 4, ["y"] = 2, ["z"] = 9, ["name"] = "cloud_items:cloud"}, {["x"] = 4, ["y"] = 2, ["z"] = 10, ["name"] = "cloud_items:cloud"}, {["x"] = 4, ["y"] = 2, ["z"] = 11, ["name"] = "cloud_items:cloud"}, {["x"] = 4, ["y"] = 2, ["z"] = 12, ["name"] = "cloud_items:cloud"}, {["x"] = 4, ["y"] = 2, ["z"] = 13, ["name"] = "cloud_items:cloud"}, {["x"] = 4, ["y"] = 3, ["z"] = 4, ["name"] = "cloud_items:cloud"}, {["x"] = 4, ["y"] = 3, ["z"] = 5, ["name"] = "cloud_items:cloud"}, {["x"] = 4, ["y"] = 3, ["z"] = 6, ["name"] = "cloud_items:cloud"}, {["x"] = 4, ["y"] = 3, ["z"] = 7, ["name"] = "cloud_items:cloud"}, {["x"] = 4, ["y"] = 3, ["z"] = 8, ["name"] = "cloud_items:cloud"}, {["x"] = 4, ["y"] = 3, ["z"] = 9, ["name"] = "cloud_items:cloud"}, {["x"] = 4, ["y"] = 3, ["z"] = 10, ["name"] = "cloud_items:cloud"}, {["x"] = 4, ["y"] = 3, ["z"] = 11, ["name"] = "cloud_items:cloud"}, {["x"] = 4, ["y"] = 3, ["z"] = 12, ["name"] = "cloud_items:cloud"}, {["x"] = 4, ["y"] = 4, ["z"] = 5, ["name"] = "cloud_items:cloud"}, {["x"] = 4, ["y"] = 4, ["z"] = 6, ["name"] = "cloud_items:cloud"}, {["x"] = 4, ["y"] = 4, ["z"] = 7, ["name"] = "cloud_items:cloud"}, {["x"] = 4, ["y"] = 4, ["z"] = 8, ["name"] = "cloud_items:cloud"}, {["x"] = 4, ["y"] = 4, ["z"] = 9, ["name"] = "cloud_items:cloud"}, {["x"] = 4, ["y"] = 4, ["z"] = 10, ["name"] = "cloud_items:cloud"}, {["x"] = 4, ["y"] = 4, ["z"] = 11, ["name"] = "cloud_items:cloud"}, {["x"] = 4, ["y"] = 5, ["z"] = 7, ["name"] = "cloud_items:cloud"}, {["x"] = 4, ["y"] = 5, ["z"] = 8, ["name"] = "cloud_items:cloud"}, {["x"] = 4, ["y"] = 5, ["z"] = 9, ["name"] = "cloud_items:cloud"}, {["x"] = 5, ["y"] = 1, ["z"] = 0, ["name"] = "cloud_items:cloud"}, {["x"] = 5, ["y"] = 1, ["z"] = 1, ["name"] = "cloud_items:cloud"}, {["x"] = 5, ["y"] = 1, ["z"] = 2, ["name"] = "cloud_items:cloud"}, {["x"] = 5, ["y"] = 1, ["z"] = 3, ["name"] = "cloud_items:cloud"}, {["x"] = 5, ["y"] = 1, ["z"] = 4, ["name"] = "cloud_items:cloud"}, {["x"] = 5, ["y"] = 1, ["z"] = 5, ["name"] = "cloud_items:cloud"}, {["x"] = 5, ["y"] = 1, ["z"] = 6, ["name"] = "cloud_items:cloud"}, {["x"] = 5, ["y"] = 1, ["z"] = 7, ["name"] = "cloud_items:cloud"}, {["x"] = 5, ["y"] = 1, ["z"] = 8, ["name"] = "cloud_items:cloud"}, {["x"] = 5, ["y"] = 1, ["z"] = 9, ["name"] = "cloud_items:cloud"}, {["x"] = 5, ["y"] = 1, ["z"] = 10, ["name"] = "cloud_items:cloud"}, {["x"] = 5, ["y"] = 1, ["z"] = 11, ["name"] = "cloud_items:cloud"}, {["x"] = 5, ["y"] = 1, ["z"] = 12, ["name"] = "cloud_items:cloud"}, {["x"] = 5, ["y"] = 1, ["z"] = 13, ["name"] = "cloud_items:cloud"}, {["x"] = 5, ["y"] = 1, ["z"] = 14, ["name"] = "cloud_items:cloud"}, {["x"] = 5, ["y"] = 1, ["z"] = 15, ["name"] = "cloud_items:cloud"}, {["x"] = 5, ["y"] = 2, ["z"] = 2, ["name"] = "cloud_items:cloud"}, {["x"] = 5, ["y"] = 2, ["z"] = 3, ["name"] = "cloud_items:cloud"}, {["x"] = 5, ["y"] = 2, ["z"] = 4, ["name"] = "cloud_items:cloud"}, {["x"] = 5, ["y"] = 2, ["z"] = 5, ["name"] = "cloud_items:cloud"}, {["x"] = 5, ["y"] = 2, ["z"] = 6, ["name"] = "cloud_items:cloud"}, {["x"] = 5, ["y"] = 2, ["z"] = 7, ["name"] = "cloud_items:cloud"}, {["x"] = 5, ["y"] = 2, ["z"] = 8, ["name"] = "cloud_items:cloud"}, {["x"] = 5, ["y"] = 2, ["z"] = 9, ["name"] = "cloud_items:cloud"}, {["x"] = 5, ["y"] = 2, ["z"] = 10, ["name"] = "cloud_items:cloud"}, {["x"] = 5, ["y"] = 2, ["z"] = 11, ["name"] = "cloud_items:cloud"}, {["x"] = 5, ["y"] = 2, ["z"] = 12, ["name"] = "cloud_items:cloud"}, {["x"] = 5, ["y"] = 2, ["z"] = 13, ["name"] = "cloud_items:cloud"}, {["x"] = 5, ["y"] = 2, ["z"] = 14, ["name"] = "cloud_items:cloud"}, {["x"] = 5, ["y"] = 3, ["z"] = 3, ["name"] = "cloud_items:cloud"}, {["x"] = 5, ["y"] = 3, ["z"] = 4, ["name"] = "cloud_items:cloud"}, {["x"] = 5, ["y"] = 3, ["z"] = 5, ["name"] = "cloud_items:cloud"}, {["x"] = 5, ["y"] = 3, ["z"] = 11, ["name"] = "cloud_items:cloud"}, {["x"] = 5, ["y"] = 3, ["z"] = 12, ["name"] = "cloud_items:cloud"}, {["x"] = 5, ["y"] = 4, ["z"] = 4, ["name"] = "cloud_items:cloud"}, {["x"] = 5, ["y"] = 4, ["z"] = 5, ["name"] = "cloud_items:cloud"}, {["x"] = 5, ["y"] = 4, ["z"] = 6, ["name"] = "cloud_items:cloud"}, {["x"] = 5, ["y"] = 4, ["z"] = 7, ["name"] = "cloud_items:cloud"}, {["x"] = 5, ["y"] = 4, ["z"] = 8, ["name"] = "cloud_items:cloud"}, {["x"] = 5, ["y"] = 4, ["z"] = 9, ["name"] = "cloud_items:cloud"}, {["x"] = 5, ["y"] = 4, ["z"] = 10, ["name"] = "cloud_items:cloud"}, {["x"] = 5, ["y"] = 4, ["z"] = 11, ["name"] = "cloud_items:cloud"}, {["x"] = 5, ["y"] = 5, ["z"] = 6, ["name"] = "cloud_items:cloud"}, {["x"] = 5, ["y"] = 5, ["z"] = 7, ["name"] = "cloud_items:cloud"}, {["x"] = 5, ["y"] = 5, ["z"] = 8, ["name"] = "cloud_items:cloud"}, {["x"] = 5, ["y"] = 5, ["z"] = 9, ["name"] = "cloud_items:cloud"}, {["x"] = 5, ["y"] = 5, ["z"] = 10, ["name"] = "cloud_items:cloud"}, {["x"] = 5, ["y"] = 6, ["z"] = 7, ["name"] = "cloud_items:cloud"}, {["x"] = 5, ["y"] = 6, ["z"] = 8, ["name"] = "cloud_items:cloud"}, {["x"] = 5, ["y"] = 6, ["z"] = 9, ["name"] = "cloud_items:cloud"}, {["x"] = 6, ["y"] = 1, ["z"] = 0, ["name"] = "cloud_items:cloud"}, {["x"] = 6, ["y"] = 1, ["z"] = 1, ["name"] = "cloud_items:cloud"}, {["x"] = 6, ["y"] = 1, ["z"] = 2, ["name"] = "cloud_items:cloud"}, {["x"] = 6, ["y"] = 1, ["z"] = 3, ["name"] = "cloud_items:cloud"}, {["x"] = 6, ["y"] = 1, ["z"] = 4, ["name"] = "cloud_items:cloud"}, {["x"] = 6, ["y"] = 1, ["z"] = 5, ["name"] = "cloud_items:cloud"}, {["x"] = 6, ["y"] = 1, ["z"] = 6, ["name"] = "cloud_items:cloud"}, {["x"] = 6, ["y"] = 1, ["z"] = 7, ["name"] = "cloud_items:cloud"}, {["x"] = 6, ["y"] = 1, ["z"] = 8, ["name"] = "cloud_items:cloud"}, {["x"] = 6, ["y"] = 1, ["z"] = 9, ["name"] = "cloud_items:cloud"}, {["x"] = 6, ["y"] = 1, ["z"] = 10, ["name"] = "cloud_items:cloud"}, {["x"] = 6, ["y"] = 1, ["z"] = 11, ["name"] = "cloud_items:cloud"}, {["x"] = 6, ["y"] = 1, ["z"] = 12, ["name"] = "cloud_items:cloud"}, {["x"] = 6, ["y"] = 1, ["z"] = 13, ["name"] = "cloud_items:cloud"}, {["x"] = 6, ["y"] = 1, ["z"] = 14, ["name"] = "cloud_items:cloud"}, {["x"] = 6, ["y"] = 1, ["z"] = 15, ["name"] = "cloud_items:cloud"}, {["x"] = 6, ["y"] = 2, ["z"] = 1, ["name"] = "cloud_items:cloud"}, {["x"] = 6, ["y"] = 2, ["z"] = 2, ["name"] = "cloud_items:cloud"}, {["x"] = 6, ["y"] = 2, ["z"] = 3, ["name"] = "cloud_items:cloud"}, {["x"] = 6, ["y"] = 2, ["z"] = 4, ["name"] = "cloud_items:cloud"}, {["x"] = 6, ["y"] = 2, ["z"] = 5, ["name"] = "cloud_items:cloud"}, {["x"] = 6, ["y"] = 2, ["z"] = 6, ["name"] = "cloud_items:cloud"}, {["x"] = 6, ["y"] = 2, ["z"] = 7, ["name"] = "cloud_items:cloud"}, {["x"] = 6, ["y"] = 2, ["z"] = 8, ["name"] = "cloud_items:cloud"}, {["x"] = 6, ["y"] = 2, ["z"] = 9, ["name"] = "cloud_items:cloud"}, {["x"] = 6, ["y"] = 2, ["z"] = 10, ["name"] = "cloud_items:cloud"}, {["x"] = 6, ["y"] = 2, ["z"] = 11, ["name"] = "cloud_items:cloud"}, {["x"] = 6, ["y"] = 2, ["z"] = 12, ["name"] = "cloud_items:cloud"}, {["x"] = 6, ["y"] = 2, ["z"] = 13, ["name"] = "cloud_items:cloud"}, {["x"] = 6, ["y"] = 2, ["z"] = 14, ["name"] = "cloud_items:cloud"}, {["x"] = 6, ["y"] = 3, ["z"] = 3, ["name"] = "cloud_items:cloud"}, {["x"] = 6, ["y"] = 3, ["z"] = 4, ["name"] = "cloud_items:cloud"}, {["x"] = 6, ["y"] = 3, ["z"] = 5, ["name"] = "cloud_items:cloud"}, {["x"] = 6, ["y"] = 3, ["z"] = 8, ["name"] = "cloud_items:cloud_ore"}, {["x"] = 6, ["y"] = 3, ["z"] = 9, ["name"] = "cloud_items:cloud_ore"}, {["x"] = 6, ["y"] = 3, ["z"] = 11, ["name"] = "cloud_items:cloud"}, {["x"] = 6, ["y"] = 3, ["z"] = 12, ["name"] = "cloud_items:cloud"}, {["x"] = 6, ["y"] = 4, ["z"] = 4, ["name"] = "cloud_items:cloud"}, {["x"] = 6, ["y"] = 4, ["z"] = 5, ["name"] = "cloud_items:cloud"}, {["x"] = 6, ["y"] = 4, ["z"] = 6, ["name"] = "cloud_items:cloud"}, {["x"] = 6, ["y"] = 4, ["z"] = 7, ["name"] = "cloud_items:cloud"}, {["x"] = 6, ["y"] = 4, ["z"] = 8, ["name"] = "cloud_items:cloud"}, {["x"] = 6, ["y"] = 4, ["z"] = 9, ["name"] = "cloud_items:cloud"}, {["x"] = 6, ["y"] = 4, ["z"] = 10, ["name"] = "cloud_items:cloud"}, {["x"] = 6, ["y"] = 4, ["z"] = 11, ["name"] = "cloud_items:cloud"}, {["x"] = 6, ["y"] = 5, ["z"] = 5, ["name"] = "cloud_items:cloud"}, {["x"] = 6, ["y"] = 5, ["z"] = 6, ["name"] = "cloud_items:cloud"}, {["x"] = 6, ["y"] = 5, ["z"] = 7, ["name"] = "cloud_items:cloud"}, {["x"] = 6, ["y"] = 5, ["z"] = 8, ["name"] = "cloud_items:cloud"}, {["x"] = 6, ["y"] = 5, ["z"] = 9, ["name"] = "cloud_items:cloud"}, {["x"] = 6, ["y"] = 5, ["z"] = 10, ["name"] = "cloud_items:cloud"}, {["x"] = 6, ["y"] = 6, ["z"] = 7, ["name"] = "cloud_items:cloud"}, {["x"] = 6, ["y"] = 6, ["z"] = 8, ["name"] = "cloud_items:cloud"}, {["x"] = 6, ["y"] = 6, ["z"] = 9, ["name"] = "cloud_items:cloud"}, {["x"] = 6, ["y"] = 7, ["z"] = 8, ["name"] = "cloud_items:cloud"}, {["x"] = 7, ["y"] = 1, ["z"] = 0, ["name"] = "cloud_items:cloud"}, {["x"] = 7, ["y"] = 1, ["z"] = 1, ["name"] = "cloud_items:cloud"}, {["x"] = 7, ["y"] = 1, ["z"] = 2, ["name"] = "cloud_items:cloud"}, {["x"] = 7, ["y"] = 1, ["z"] = 3, ["name"] = "cloud_items:cloud"}, {["x"] = 7, ["y"] = 1, ["z"] = 4, ["name"] = "cloud_items:cloud"}, {["x"] = 7, ["y"] = 1, ["z"] = 5, ["name"] = "cloud_items:cloud"}, {["x"] = 7, ["y"] = 1, ["z"] = 6, ["name"] = "cloud_items:cloud"}, {["x"] = 7, ["y"] = 1, ["z"] = 7, ["name"] = "cloud_items:cloud"}, {["x"] = 7, ["y"] = 1, ["z"] = 8, ["name"] = "cloud_items:cloud"}, {["x"] = 7, ["y"] = 1, ["z"] = 9, ["name"] = "cloud_items:cloud"}, {["x"] = 7, ["y"] = 1, ["z"] = 10, ["name"] = "cloud_items:cloud"}, {["x"] = 7, ["y"] = 1, ["z"] = 11, ["name"] = "cloud_items:cloud"}, {["x"] = 7, ["y"] = 1, ["z"] = 12, ["name"] = "cloud_items:cloud"}, {["x"] = 7, ["y"] = 1, ["z"] = 13, ["name"] = "cloud_items:cloud"}, {["x"] = 7, ["y"] = 1, ["z"] = 14, ["name"] = "cloud_items:cloud"}, {["x"] = 7, ["y"] = 1, ["z"] = 15, ["name"] = "cloud_items:cloud"}, {["x"] = 7, ["y"] = 2, ["z"] = 2, ["name"] = "cloud_items:cloud"}, {["x"] = 7, ["y"] = 2, ["z"] = 3, ["name"] = "cloud_items:cloud"}, {["x"] = 7, ["y"] = 2, ["z"] = 4, ["name"] = "cloud_items:cloud"}, {["x"] = 7, ["y"] = 2, ["z"] = 5, ["name"] = "cloud_items:cloud"}, {["x"] = 7, ["y"] = 2, ["z"] = 6, ["name"] = "cloud_items:cloud"}, {["x"] = 7, ["y"] = 2, ["z"] = 7, ["name"] = "cloud_items:cloud"}, {["x"] = 7, ["y"] = 2, ["z"] = 8, ["name"] = "cloud_items:cloud"}, {["x"] = 7, ["y"] = 2, ["z"] = 9, ["name"] = "cloud_items:cloud"}, {["x"] = 7, ["y"] = 2, ["z"] = 10, ["name"] = "cloud_items:cloud"}, {["x"] = 7, ["y"] = 2, ["z"] = 11, ["name"] = "cloud_items:cloud"}, {["x"] = 7, ["y"] = 2, ["z"] = 12, ["name"] = "cloud_items:cloud"}, {["x"] = 7, ["y"] = 2, ["z"] = 13, ["name"] = "cloud_items:cloud"}, {["x"] = 7, ["y"] = 2, ["z"] = 14, ["name"] = "cloud_items:cloud"}, {["x"] = 7, ["y"] = 3, ["z"] = 3, ["name"] = "cloud_items:cloud"}, {["x"] = 7, ["y"] = 3, ["z"] = 4, ["name"] = "cloud_items:cloud"}, {["x"] = 7, ["y"] = 3, ["z"] = 5, ["name"] = "cloud_items:cloud"}, {["x"] = 7, ["y"] = 3, ["z"] = 9, ["name"] = "cloud_items:cloud_ore"}, {["x"] = 7, ["y"] = 3, ["z"] = 11, ["name"] = "cloud_items:cloud"}, {["x"] = 7, ["y"] = 3, ["z"] = 12, ["name"] = "cloud_items:cloud"}, {["x"] = 7, ["y"] = 4, ["z"] = 4, ["name"] = "cloud_items:cloud"}, {["x"] = 7, ["y"] = 4, ["z"] = 5, ["name"] = "cloud_items:cloud"}, {["x"] = 7, ["y"] = 4, ["z"] = 6, ["name"] = "cloud_items:cloud"}, {["x"] = 7, ["y"] = 4, ["z"] = 7, ["name"] = "cloud_items:cloud"}, {["x"] = 7, ["y"] = 4, ["z"] = 8, ["name"] = "cloud_items:cloud"}, {["x"] = 7, ["y"] = 4, ["z"] = 9, ["name"] = "cloud_items:cloud"}, {["x"] = 7, ["y"] = 4, ["z"] = 10, ["name"] = "cloud_items:cloud"}, {["x"] = 7, ["y"] = 4, ["z"] = 11, ["name"] = "cloud_items:cloud"}, {["x"] = 7, ["y"] = 5, ["z"] = 5, ["name"] = "cloud_items:cloud"}, {["x"] = 7, ["y"] = 5, ["z"] = 6, ["name"] = "cloud_items:cloud"}, {["x"] = 7, ["y"] = 5, ["z"] = 7, ["name"] = "cloud_items:cloud"}, {["x"] = 7, ["y"] = 5, ["z"] = 8, ["name"] = "cloud_items:cloud"}, {["x"] = 7, ["y"] = 5, ["z"] = 9, ["name"] = "cloud_items:cloud"}, {["x"] = 7, ["y"] = 5, ["z"] = 10, ["name"] = "cloud_items:cloud"}, {["x"] = 7, ["y"] = 6, ["z"] = 7, ["name"] = "cloud_items:cloud"}, {["x"] = 7, ["y"] = 6, ["z"] = 8, ["name"] = "cloud_items:cloud"}, {["x"] = 7, ["y"] = 6, ["z"] = 9, ["name"] = "cloud_items:cloud"}, {["x"] = 7, ["y"] = 7, ["z"] = 8, ["name"] = "cloud_items:cloud"}, {["x"] = 8, ["y"] = 1, ["z"] = 1, ["name"] = "cloud_items:cloud"}, {["x"] = 8, ["y"] = 1, ["z"] = 2, ["name"] = "cloud_items:cloud"}, {["x"] = 8, ["y"] = 1, ["z"] = 3, ["name"] = "cloud_items:cloud"}, {["x"] = 8, ["y"] = 1, ["z"] = 4, ["name"] = "cloud_items:cloud"}, {["x"] = 8, ["y"] = 1, ["z"] = 5, ["name"] = "cloud_items:cloud"}, {["x"] = 8, ["y"] = 1, ["z"] = 6, ["name"] = "cloud_items:cloud"}, {["x"] = 8, ["y"] = 1, ["z"] = 7, ["name"] = "cloud_items:cloud"}, {["x"] = 8, ["y"] = 1, ["z"] = 8, ["name"] = "cloud_items:cloud"}, {["x"] = 8, ["y"] = 1, ["z"] = 9, ["name"] = "cloud_items:cloud"}, {["x"] = 8, ["y"] = 1, ["z"] = 10, ["name"] = "cloud_items:cloud"}, {["x"] = 8, ["y"] = 1, ["z"] = 11, ["name"] = "cloud_items:cloud"}, {["x"] = 8, ["y"] = 1, ["z"] = 12, ["name"] = "cloud_items:cloud"}, {["x"] = 8, ["y"] = 1, ["z"] = 13, ["name"] = "cloud_items:cloud"}, {["x"] = 8, ["y"] = 1, ["z"] = 14, ["name"] = "cloud_items:cloud"}, {["x"] = 8, ["y"] = 1, ["z"] = 15, ["name"] = "cloud_items:cloud"}, {["x"] = 8, ["y"] = 2, ["z"] = 2, ["name"] = "cloud_items:cloud"}, {["x"] = 8, ["y"] = 2, ["z"] = 3, ["name"] = "cloud_items:cloud"}, {["x"] = 8, ["y"] = 2, ["z"] = 4, ["name"] = "cloud_items:cloud"}, {["x"] = 8, ["y"] = 2, ["z"] = 5, ["name"] = "cloud_items:cloud"}, {["x"] = 8, ["y"] = 2, ["z"] = 6, ["name"] = "cloud_items:cloud"}, {["x"] = 8, ["y"] = 2, ["z"] = 7, ["name"] = "cloud_items:cloud"}, {["x"] = 8, ["y"] = 2, ["z"] = 8, ["name"] = "cloud_items:cloud"}, {["x"] = 8, ["y"] = 2, ["z"] = 9, ["name"] = "cloud_items:cloud"}, {["x"] = 8, ["y"] = 2, ["z"] = 10, ["name"] = "cloud_items:cloud"}, {["x"] = 8, ["y"] = 2, ["z"] = 11, ["name"] = "cloud_items:cloud"}, {["x"] = 8, ["y"] = 2, ["z"] = 12, ["name"] = "cloud_items:cloud"}, {["x"] = 8, ["y"] = 2, ["z"] = 13, ["name"] = "cloud_items:cloud"}, {["x"] = 8, ["y"] = 3, ["z"] = 4, ["name"] = "cloud_items:cloud"}, {["x"] = 8, ["y"] = 3, ["z"] = 5, ["name"] = "cloud_items:cloud"}, {["x"] = 8, ["y"] = 3, ["z"] = 11, ["name"] = "cloud_items:cloud"}, {["x"] = 8, ["y"] = 3, ["z"] = 12, ["name"] = "cloud_items:cloud"}, {["x"] = 8, ["y"] = 4, ["z"] = 4, ["name"] = "cloud_items:cloud"}, {["x"] = 8, ["y"] = 4, ["z"] = 5, ["name"] = "cloud_items:cloud"}, {["x"] = 8, ["y"] = 4, ["z"] = 6, ["name"] = "cloud_items:cloud"}, {["x"] = 8, ["y"] = 4, ["z"] = 7, ["name"] = "cloud_items:cloud"}, {["x"] = 8, ["y"] = 4, ["z"] = 8, ["name"] = "cloud_items:cloud"}, {["x"] = 8, ["y"] = 4, ["z"] = 9, ["name"] = "cloud_items:cloud"}, {["x"] = 8, ["y"] = 4, ["z"] = 10, ["name"] = "cloud_items:cloud"}, {["x"] = 8, ["y"] = 4, ["z"] = 11, ["name"] = "cloud_items:cloud"}, {["x"] = 8, ["y"] = 5, ["z"] = 6, ["name"] = "cloud_items:cloud"}, {["x"] = 8, ["y"] = 5, ["z"] = 7, ["name"] = "cloud_items:cloud"}, {["x"] = 8, ["y"] = 5, ["z"] = 8, ["name"] = "cloud_items:cloud"}, {["x"] = 8, ["y"] = 5, ["z"] = 9, ["name"] = "cloud_items:cloud"}, {["x"] = 8, ["y"] = 5, ["z"] = 10, ["name"] = "cloud_items:cloud"}, {["x"] = 8, ["y"] = 6, ["z"] = 7, ["name"] = "cloud_items:cloud"}, {["x"] = 8, ["y"] = 6, ["z"] = 8, ["name"] = "cloud_items:cloud"}, {["x"] = 8, ["y"] = 6, ["z"] = 9, ["name"] = "cloud_items:cloud"}, {["x"] = 9, ["y"] = 1, ["z"] = 2, ["name"] = "cloud_items:cloud"}, {["x"] = 9, ["y"] = 1, ["z"] = 3, ["name"] = "cloud_items:cloud"}, {["x"] = 9, ["y"] = 1, ["z"] = 4, ["name"] = "cloud_items:cloud"}, {["x"] = 9, ["y"] = 1, ["z"] = 5, ["name"] = "cloud_items:cloud"}, {["x"] = 9, ["y"] = 1, ["z"] = 6, ["name"] = "cloud_items:cloud"}, {["x"] = 9, ["y"] = 1, ["z"] = 7, ["name"] = "cloud_items:cloud"}, {["x"] = 9, ["y"] = 1, ["z"] = 8, ["name"] = "cloud_items:cloud"}, {["x"] = 9, ["y"] = 1, ["z"] = 9, ["name"] = "cloud_items:cloud"}, {["x"] = 9, ["y"] = 1, ["z"] = 10, ["name"] = "cloud_items:cloud"}, {["x"] = 9, ["y"] = 1, ["z"] = 11, ["name"] = "cloud_items:cloud"}, {["x"] = 9, ["y"] = 1, ["z"] = 12, ["name"] = "cloud_items:cloud"}, {["x"] = 9, ["y"] = 1, ["z"] = 13, ["name"] = "cloud_items:cloud"}, {["x"] = 9, ["y"] = 1, ["z"] = 14, ["name"] = "cloud_items:cloud"}, {["x"] = 9, ["y"] = 2, ["z"] = 3, ["name"] = "cloud_items:cloud"}, {["x"] = 9, ["y"] = 2, ["z"] = 4, ["name"] = "cloud_items:cloud"}, {["x"] = 9, ["y"] = 2, ["z"] = 5, ["name"] = "cloud_items:cloud"}, {["x"] = 9, ["y"] = 2, ["z"] = 6, ["name"] = "cloud_items:cloud"}, {["x"] = 9, ["y"] = 2, ["z"] = 7, ["name"] = "cloud_items:cloud"}, {["x"] = 9, ["y"] = 2, ["z"] = 8, ["name"] = "cloud_items:cloud"}, {["x"] = 9, ["y"] = 2, ["z"] = 9, ["name"] = "cloud_items:cloud"}, {["x"] = 9, ["y"] = 2, ["z"] = 10, ["name"] = "cloud_items:cloud"}, {["x"] = 9, ["y"] = 2, ["z"] = 11, ["name"] = "cloud_items:cloud"}, {["x"] = 9, ["y"] = 2, ["z"] = 12, ["name"] = "cloud_items:cloud"}, {["x"] = 9, ["y"] = 2, ["z"] = 13, ["name"] = "cloud_items:cloud"}, {["x"] = 9, ["y"] = 3, ["z"] = 4, ["name"] = "cloud_items:cloud"}, {["x"] = 9, ["y"] = 3, ["z"] = 5, ["name"] = "cloud_items:cloud"}, {["x"] = 9, ["y"] = 3, ["z"] = 6, ["name"] = "cloud_items:cloud"}, {["x"] = 9, ["y"] = 3, ["z"] = 7, ["name"] = "cloud_items:cloud"}, {["x"] = 9, ["y"] = 3, ["z"] = 8, ["name"] = "cloud_items:cloud"}, {["x"] = 9, ["y"] = 3, ["z"] = 9, ["name"] = "cloud_items:cloud"}, {["x"] = 9, ["y"] = 3, ["z"] = 10, ["name"] = "cloud_items:cloud"}, {["x"] = 9, ["y"] = 3, ["z"] = 11, ["name"] = "cloud_items:cloud"}, {["x"] = 9, ["y"] = 3, ["z"] = 12, ["name"] = "cloud_items:cloud"}, {["x"] = 9, ["y"] = 4, ["z"] = 5, ["name"] = "cloud_items:cloud"}, {["x"] = 9, ["y"] = 4, ["z"] = 6, ["name"] = "cloud_items:cloud"}, {["x"] = 9, ["y"] = 4, ["z"] = 7, ["name"] = "cloud_items:cloud"}, {["x"] = 9, ["y"] = 4, ["z"] = 8, ["name"] = "cloud_items:cloud"}, {["x"] = 9, ["y"] = 4, ["z"] = 9, ["name"] = "cloud_items:cloud"}, {["x"] = 9, ["y"] = 4, ["z"] = 10, ["name"] = "cloud_items:cloud"}, {["x"] = 9, ["y"] = 4, ["z"] = 11, ["name"] = "cloud_items:cloud"}, {["x"] = 9, ["y"] = 5, ["z"] = 7, ["name"] = "cloud_items:cloud"}, {["x"] = 9, ["y"] = 5, ["z"] = 8, ["name"] = "cloud_items:cloud"}, {["x"] = 9, ["y"] = 5, ["z"] = 9, ["name"] = "cloud_items:cloud"}, {["x"] = 10, ["y"] = 1, ["z"] = 3, ["name"] = "cloud_items:cloud"}, {["x"] = 10, ["y"] = 1, ["z"] = 4, ["name"] = "cloud_items:cloud"}, {["x"] = 10, ["y"] = 1, ["z"] = 5, ["name"] = "cloud_items:cloud"}, {["x"] = 10, ["y"] = 1, ["z"] = 6, ["name"] = "cloud_items:cloud"}, {["x"] = 10, ["y"] = 1, ["z"] = 7, ["name"] = "cloud_items:cloud"}, {["x"] = 10, ["y"] = 1, ["z"] = 8, ["name"] = "cloud_items:cloud"}, {["x"] = 10, ["y"] = 1, ["z"] = 9, ["name"] = "cloud_items:cloud"}, {["x"] = 10, ["y"] = 1, ["z"] = 10, ["name"] = "cloud_items:cloud"}, {["x"] = 10, ["y"] = 1, ["z"] = 11, ["name"] = "cloud_items:cloud"}, {["x"] = 10, ["y"] = 1, ["z"] = 12, ["name"] = "cloud_items:cloud"}, {["x"] = 10, ["y"] = 1, ["z"] = 13, ["name"] = "cloud_items:cloud"}, {["x"] = 10, ["y"] = 2, ["z"] = 4, ["name"] = "cloud_items:cloud"}, {["x"] = 10, ["y"] = 2, ["z"] = 5, ["name"] = "cloud_items:cloud"}, {["x"] = 10, ["y"] = 2, ["z"] = 6, ["name"] = "cloud_items:cloud"}, {["x"] = 10, ["y"] = 2, ["z"] = 7, ["name"] = "cloud_items:cloud"}, {["x"] = 10, ["y"] = 2, ["z"] = 8, ["name"] = "cloud_items:cloud"}, {["x"] = 10, ["y"] = 2, ["z"] = 9, ["name"] = "cloud_items:cloud"}, {["x"] = 10, ["y"] = 2, ["z"] = 10, ["name"] = "cloud_items:cloud"}, {["x"] = 10, ["y"] = 2, ["z"] = 11, ["name"] = "cloud_items:cloud"}, {["x"] = 10, ["y"] = 2, ["z"] = 12, ["name"] = "cloud_items:cloud"}, {["x"] = 10, ["y"] = 3, ["z"] = 4, ["name"] = "cloud_items:cloud"}, {["x"] = 10, ["y"] = 3, ["z"] = 5, ["name"] = "cloud_items:cloud"}, {["x"] = 10, ["y"] = 3, ["z"] = 6, ["name"] = "cloud_items:cloud"}, {["x"] = 10, ["y"] = 3, ["z"] = 7, ["name"] = "cloud_items:cloud"}, {["x"] = 10, ["y"] = 3, ["z"] = 8, ["name"] = "cloud_items:cloud"}, {["x"] = 10, ["y"] = 3, ["z"] = 9, ["name"] = "cloud_items:cloud"}, {["x"] = 10, ["y"] = 3, ["z"] = 10, ["name"] = "cloud_items:cloud"}, {["x"] = 10, ["y"] = 3, ["z"] = 11, ["name"] = "cloud_items:cloud"}, {["x"] = 10, ["y"] = 3, ["z"] = 12, ["name"] = "cloud_items:cloud"}, {["x"] = 10, ["y"] = 4, ["z"] = 6, ["name"] = "cloud_items:cloud"}, {["x"] = 10, ["y"] = 4, ["z"] = 7, ["name"] = "cloud_items:cloud"}, {["x"] = 10, ["y"] = 4, ["z"] = 8, ["name"] = "cloud_items:cloud"}, {["x"] = 10, ["y"] = 4, ["z"] = 9, ["name"] = "cloud_items:cloud"}, {["x"] = 10, ["y"] = 4, ["z"] = 10, ["name"] = "cloud_items:cloud"}, {["x"] = 11, ["y"] = 1, ["z"] = 4, ["name"] = "cloud_items:cloud"}, {["x"] = 11, ["y"] = 1, ["z"] = 5, ["name"] = "cloud_items:cloud"}, {["x"] = 11, ["y"] = 1, ["z"] = 6, ["name"] = "cloud_items:cloud"}, {["x"] = 11, ["y"] = 1, ["z"] = 7, ["name"] = "cloud_items:cloud"}, {["x"] = 11, ["y"] = 1, ["z"] = 8, ["name"] = "cloud_items:cloud"}, {["x"] = 11, ["y"] = 1, ["z"] = 9, ["name"] = "cloud_items:cloud"}, {["x"] = 11, ["y"] = 1, ["z"] = 10, ["name"] = "cloud_items:cloud"}, {["x"] = 11, ["y"] = 1, ["z"] = 11, ["name"] = "cloud_items:cloud"}, {["x"] = 11, ["y"] = 1, ["z"] = 12, ["name"] = "cloud_items:cloud"}, {["x"] = 11, ["y"] = 2, ["z"] = 4, ["name"] = "cloud_items:cloud"}, {["x"] = 11, ["y"] = 2, ["z"] = 5, ["name"] = "cloud_items:cloud"}, {["x"] = 11, ["y"] = 2, ["z"] = 6, ["name"] = "cloud_items:cloud"}, {["x"] = 11, ["y"] = 2, ["z"] = 7, ["name"] = "cloud_items:cloud"}, {["x"] = 11, ["y"] = 2, ["z"] = 8, ["name"] = "cloud_items:cloud"}, {["x"] = 11, ["y"] = 2, ["z"] = 9, ["name"] = "cloud_items:cloud"}, {["x"] = 11, ["y"] = 2, ["z"] = 10, ["name"] = "cloud_items:cloud"}, {["x"] = 11, ["y"] = 2, ["z"] = 11, ["name"] = "cloud_items:cloud"}, {["x"] = 11, ["y"] = 2, ["z"] = 12, ["name"] = "cloud_items:cloud"}, {["x"] = 11, ["y"] = 3, ["z"] = 6, ["name"] = "cloud_items:cloud"}, {["x"] = 11, ["y"] = 3, ["z"] = 7, ["name"] = "cloud_items:cloud"}, {["x"] = 11, ["y"] = 3, ["z"] = 8, ["name"] = "cloud_items:cloud"}, {["x"] = 11, ["y"] = 3, ["z"] = 9, ["name"] = "cloud_items:cloud"}, {["x"] = 11, ["y"] = 3, ["z"] = 10, ["name"] = "cloud_items:cloud"}, {["x"] = 12, ["y"] = 1, ["z"] = 6, ["name"] = "cloud_items:cloud"}, {["x"] = 12, ["y"] = 1, ["z"] = 7, ["name"] = "cloud_items:cloud"}, {["x"] = 12, ["y"] = 1, ["z"] = 8, ["name"] = "cloud_items:cloud"}, {["x"] = 12, ["y"] = 1, ["z"] = 9, ["name"] = "cloud_items:cloud"}, {["x"] = 12, ["y"] = 1, ["z"] = 10, ["name"] = "cloud_items:cloud"}, {["x"] = 12, ["y"] = 2, ["z"] = 7, ["name"] = "cloud_items:cloud"}, {["x"] = 12, ["y"] = 2, ["z"] = 8, ["name"] = "cloud_items:cloud"}, {["x"] = 12, ["y"] = 2, ["z"] = 9, ["name"] = "cloud_items:cloud"}}