5:return {{["x"] = 0, ["y"] = 0, ["z"] = 0, ["name"] = "cloud_items:decorative_cloud"}, {["x"] = 0, ["y"] = 0, ["z"] = 1, ["name"] = "cloud_items:decorative_cloud"}, {["x"] = 0, ["y"] = 0, ["z"] = 2, ["name"] = "cloud_items:decorative_cloud"}, {["x"] = 0, ["y"] = 0, ["z"] = 3, ["name"] = "cloud_items:decorative_cloud"}, {["x"] = 0, ["y"] = 0, ["z"] = 4, ["name"] = "cloud_items:decorative_cloud"}, {["x"] = 0, ["y"] = 0, ["z"] = 5, ["name"] = "cloud_items:decorative_cloud"}, {["x"] = 0, ["y"] = 0, ["z"] = 6, ["name"] = "cloud_items:decorative_cloud"}, {["x"] = 0, ["y"] = 0, ["z"] = 7, ["name"] = "cloud_items:decorative_cloud"}, {["x"] = 0, ["y"] = 0, ["z"] = 8, ["name"] = "cloud_items:decorative_cloud"}, {["x"] = 0, ["y"] = 0, ["z"] = 9, ["name"] = "cloud_items:decorative_cloud"}, {["x"] = 0, ["y"] = 0, ["z"] = 10, ["name"] = "cloud_items:decorative_cloud"}, {["x"] = 0, ["y"] = 0, ["z"] = 11, ["name"] = "cloud_items:decorative_cloud"}, {["x"] = 0, ["y"] = 0, ["z"] = 12, ["name"] = "cloud_items:decorative_cloud"}, {["x"] = 0, ["y"] = 0, ["z"] = 13, ["name"] = "cloud_items:decorative_cloud"}, {["x"] = 0, ["y"] = 0, ["z"] = 14, ["name"] = "cloud_items:decorative_cloud"}, {["x"] = 0, ["y"] = 0, ["z"] = 15, ["name"] = "cloud_items:decorative_cloud"}, {["x"] = 1, ["y"] = 0, ["z"] = 0, ["name"] = "cloud_items:decorative_cloud"}, {["x"] = 1, ["y"] = 0, ["z"] = 1, ["name"] = "cloud_items:decorative_cloud"}, {["x"] = 1, ["y"] = 0, ["z"] = 2, ["name"] = "cloud_items:decorative_cloud"}, {["x"] = 1, ["y"] = 0, ["z"] = 3, ["name"] = "cloud_items:decorative_cloud"}, {["x"] = 1, ["y"] = 0, ["z"] = 4, ["name"] = "cloud_items:decorative_cloud"}, {["x"] = 1, ["y"] = 0, ["z"] = 5, ["name"] = "cloud_items:decorative_cloud"}, {["x"] = 1, ["y"] = 0, ["z"] = 6, ["name"] = "cloud_items:decorative_cloud"}, {["x"] = 1, ["y"] = 0, ["z"] = 7, ["name"] = "cloud_items:decorative_cloud"}, {["x"] = 1, ["y"] = 0, ["z"] = 8, ["name"] = "cloud_items:decorative_cloud"}, {["x"] = 1, ["y"] = 0, ["z"] = 9, ["name"] = "cloud_items:decorative_cloud"}, {["x"] = 1, ["y"] = 0, ["z"] = 10, ["name"] = "cloud_items:decorative_cloud"}, {["x"] = 1, ["y"] = 0, ["z"] = 11, ["name"] = "cloud_items:decorative_cloud"}, {["x"] = 1, ["y"] = 0, ["z"] = 12, ["name"] = "cloud_items:decorative_cloud"}, {["x"] = 1, ["y"] = 0, ["z"] = 13, ["name"] = "cloud_items:decorative_cloud"}, {["x"] = 1, ["y"] = 0, ["z"] = 14, ["name"] = "cloud_items:decorative_cloud"}, {["x"] = 1, ["y"] = 0, ["z"] = 15, ["name"] = "cloud_items:decorative_cloud"}, {["x"] = 1, ["y"] = 4, ["z"] = 12, ["name"] = "cloud_items:decorative_cloud"}, {["x"] = 1, ["y"] = 4, ["z"] = 13, ["name"] = "cloud_items:decorative_cloud"}, {["x"] = 1, ["y"] = 4, ["z"] = 14, ["name"] = "cloud_items:decorative_cloud"}, {["x"] = 1, ["param2"] = 2, ["y"] = 5, ["param1"] = 94, ["z"] = 11, ["name"] = "stairs:stair_decorative_cloud"}, {["x"] = 1, ["param2"] = 2, ["y"] = 6, ["param1"] = 62, ["z"] = 10, ["name"] = "stairs:stair_decorative_cloud"}, {["x"] = 1, ["y"] = 7, ["z"] = 8, ["name"] = "cloud_items:decorative_cloud"}, {["x"] = 1, ["param2"] = 2, ["y"] = 7, ["param1"] = 78, ["z"] = 9, ["name"] = "stairs:stair_decorative_cloud"}, {["x"] = 2, ["y"] = 0, ["z"] = 0, ["name"] = "cloud_items:decorative_cloud"}, {["x"] = 2, ["y"] = 0, ["z"] = 1, ["name"] = "cloud_items:decorative_cloud"}, {["x"] = 2, ["y"] = 0, ["z"] = 2, ["name"] = "cloud_items:decorative_cloud"}, {["x"] = 2, ["y"] = 0, ["z"] = 3, ["name"] = "cloud_items:decorative_cloud"}, {["x"] = 2, ["y"] = 0, ["z"] = 4, ["name"] = "cloud_items:decorative_cloud"}, {["x"] = 2, ["y"] = 0, ["z"] = 5, ["name"] = "cloud_items:decorative_cloud"}, {["x"] = 2, ["y"] = 0, ["z"] = 6, ["name"] = "cloud_items:decorative_cloud"}, {["x"] = 2, ["y"] = 0, ["z"] = 7, ["name"] = "cloud_items:decorative_cloud"}, {["x"] = 2, ["y"] = 0, ["z"] = 8, ["name"] = "cloud_items:decorative_cloud"}, {["x"] = 2, ["y"] = 0, ["z"] = 9, ["name"] = "cloud_items:decorative_cloud"}, {["x"] = 2, ["y"] = 0, ["z"] = 10, ["name"] = "cloud_items:decorative_cloud"}, {["x"] = 2, ["y"] = 0, ["z"] = 11, ["name"] = "cloud_items:decorative_cloud"}, {["x"] = 2, ["y"] = 0, ["z"] = 12, ["name"] = "cloud_items:decorative_cloud"}, {["x"] = 2, ["y"] = 0, ["z"] = 13, ["name"] = "cloud_items:decorative_cloud"}, {["x"] = 2, ["y"] = 0, ["z"] = 14, ["name"] = "cloud_items:decorative_cloud"}, {["x"] = 2, ["y"] = 0, ["z"] = 15, ["name"] = "cloud_items:decorative_cloud"}, {["x"] = 2, ["y"] = 1, ["param1"] = 239, ["z"] = 2, ["name"] = "default:mese_post_light"}, {["x"] = 2, ["y"] = 1, ["param1"] = 239, ["z"] = 15, ["name"] = "default:mese_post_light"}, {["x"] = 2, ["y"] = 4, ["z"] = 12, ["name"] = "cloud_items:decorative_cloud"}, {["x"] = 2, ["param2"] = 3, ["y"] = 4, ["param1"] = 158, ["z"] = 13, ["name"] = "stairs:stair_decorative_cloud"}, {["x"] = 2, ["param2"] = 3, ["y"] = 4, ["param1"] = 174, ["z"] = 14, ["name"] = "stairs:stair_decorative_cloud"}, {["x"] = 2, ["param2"] = 2, ["y"] = 5, ["param1"] = 110, ["z"] = 11, ["name"] = "stairs:stair_decorative_cloud"}, {["x"] = 2, ["param2"] = 2, ["y"] = 6, ["param1"] = 78, ["z"] = 10, ["name"] = "stairs:stair_decorative_cloud"}, {["x"] = 2, ["y"] = 7, ["z"] = 8, ["name"] = "cloud_items:decorative_cloud"}, {["x"] = 2, ["param2"] = 2, ["y"] = 7, ["param1"] = 94, ["z"] = 9, ["name"] = "stairs:stair_decorative_cloud"}, {["x"] = 3, ["y"] = 0, ["z"] = 0, ["name"] = "cloud_items:decorative_cloud"}, {["x"] = 3, ["y"] = 0, ["z"] = 1, ["name"] = "cloud_items:decorative_cloud"}, {["x"] = 3, ["y"] = 0, ["z"] = 2, ["name"] = "cloud_items:decorative_cloud"}, {["x"] = 3, ["y"] = 0, ["z"] = 3, ["name"] = "cloud_items:decorative_cloud"}, {["x"] = 3, ["y"] = 0, ["z"] = 4, ["name"] = "cloud_items:decorative_cloud"}, {["x"] = 3, ["y"] = 0, ["z"] = 5, ["name"] = "cloud_items:decorative_cloud"}, {["x"] = 3, ["y"] = 0, ["z"] = 6, ["name"] = "cloud_items:decorative_cloud"}, {["x"] = 3, ["y"] = 0, ["z"] = 7, ["name"] = "cloud_items:decorative_cloud"}, {["x"] = 3, ["y"] = 0, ["z"] = 8, ["name"] = "cloud_items:decorative_cloud"}, {["x"] = 3, ["y"] = 0, ["z"] = 9, ["name"] = "cloud_items:decorative_cloud"}, {["x"] = 3, ["y"] = 0, ["z"] = 10, ["name"] = "cloud_items:decorative_cloud"}, {["x"] = 3, ["y"] = 0, ["z"] = 11, ["name"] = "cloud_items:decorative_cloud"}, {["x"] = 3, ["y"] = 0, ["z"] = 12, ["name"] = "cloud_items:decorative_cloud"}, {["x"] = 3, ["y"] = 0, ["z"] = 13, ["name"] = "cloud_items:decorative_cloud"}, {["x"] = 3, ["y"] = 0, ["z"] = 14, ["name"] = "cloud_items:decorative_cloud"}, {["x"] = 3, ["y"] = 0, ["z"] = 15, ["name"] = "cloud_items:decorative_cloud"}, {["x"] = 3, ["y"] = 1, ["z"] = 3, ["name"] = "cloud_items:decorative_cloud"}, {["x"] = 3, ["y"] = 1, ["z"] = 4, ["name"] = "cloud_items:decorative_cloud"}, {["x"] = 3, ["y"] = 1, ["z"] = 5, ["name"] = "cloud_items:decorative_cloud"}, {["x"] = 3, ["y"] = 1, ["z"] = 6, ["name"] = "cloud_items:decorative_cloud"}, {["x"] = 3, ["y"] = 1, ["z"] = 7, ["name"] = "cloud_items:decorative_cloud"}, {["x"] = 3, ["y"] = 1, ["z"] = 8, ["name"] = "cloud_items:decorative_cloud"}, {["x"] = 3, ["y"] = 1, ["z"] = 9, ["name"] = "cloud_items:decorative_cloud"}, {["x"] = 3, ["y"] = 1, ["z"] = 10, ["name"] = "cloud_items:decorative_cloud"}, {["x"] = 3, ["y"] = 1, ["z"] = 11, ["name"] = "cloud_items:decorative_cloud"}, {["x"] = 3, ["y"] = 1, ["z"] = 12, ["name"] = "cloud_items:decorative_cloud"}, {["x"] = 3, ["y"] = 2, ["z"] = 3, ["name"] = "cloud_items:decorative_cloud"}, {["x"] = 3, ["y"] = 2, ["z"] = 4, ["name"] = "cloud_items:decorative_cloud"}, {["x"] = 3, ["y"] = 2, ["z"] = 5, ["name"] = "cloud_items:decorative_cloud"}, {["x"] = 3, ["y"] = 2, ["z"] = 6, ["name"] = "cloud_items:decorative_cloud"}, {["x"] = 3, ["y"] = 2, ["z"] = 7, ["name"] = "cloud_items:decorative_cloud"}, {["x"] = 3, ["y"] = 2, ["z"] = 8, ["name"] = "cloud_items:decorative_cloud"}, {["x"] = 3, ["y"] = 2, ["z"] = 9, ["name"] = "cloud_items:decorative_cloud"}, {["x"] = 3, ["y"] = 2, ["z"] = 10, ["name"] = "cloud_items:decorative_cloud"}, {["x"] = 3, ["y"] = 2, ["z"] = 11, ["name"] = "cloud_items:decorative_cloud"}, {["x"] = 3, ["y"] = 2, ["z"] = 12, ["name"] = "cloud_items:decorative_cloud"}, {["x"] = 3, ["y"] = 3, ["z"] = 3, ["name"] = "cloud_items:decorative_cloud"}, {["x"] = 3, ["y"] = 3, ["z"] = 4, ["name"] = "cloud_items:decorative_cloud"}, {["x"] = 3, ["y"] = 3, ["z"] = 5, ["name"] = "cloud_items:decorative_cloud"}, {["x"] = 3, ["y"] = 3, ["z"] = 6, ["name"] = "cloud_items:decorative_cloud"}, {["x"] = 3, ["y"] = 3, ["z"] = 7, ["name"] = "cloud_items:decorative_cloud"}, {["x"] = 3, ["y"] = 3, ["z"] = 8, ["name"] = "cloud_items:decorative_cloud"}, {["x"] = 3, ["y"] = 3, ["z"] = 9, ["name"] = "cloud_items:decorative_cloud"}, {["x"] = 3, ["y"] = 3, ["z"] = 10, ["name"] = "cloud_items:decorative_cloud"}, {["x"] = 3, ["y"] = 3, ["z"] = 11, ["name"] = "cloud_items:decorative_cloud"}, {["x"] = 3, ["y"] = 3, ["z"] = 12, ["name"] = "cloud_items:decorative_cloud"}, {["x"] = 3, ["param2"] = 3, ["y"] = 3, ["param1"] = 158, ["z"] = 13, ["name"] = "stairs:stair_decorative_cloud"}, {["x"] = 3, ["param2"] = 3, ["y"] = 3, ["param1"] = 174, ["z"] = 14, ["name"] = "stairs:stair_decorative_cloud"}, {["x"] = 3, ["y"] = 4, ["z"] = 3, ["name"] = "cloud_items:decorative_cloud"}, {["x"] = 3, ["y"] = 4, ["z"] = 4, ["name"] = "cloud_items:decorative_cloud"}, {["x"] = 3, ["y"] = 4, ["z"] = 5, ["name"] = "cloud_items:decorative_cloud"}, {["x"] = 3, ["y"] = 4, ["z"] = 6, ["name"] = "cloud_items:decorative_cloud"}, {["x"] = 3, ["y"] = 4, ["z"] = 7, ["name"] = "cloud_items:decorative_cloud"}, {["x"] = 3, ["y"] = 4, ["z"] = 8, ["name"] = "cloud_items:decorative_cloud"}, {["x"] = 3, ["y"] = 4, ["z"] = 9, ["name"] = "cloud_items:decorative_cloud"}, {["x"] = 3, ["y"] = 4, ["z"] = 10, ["name"] = "cloud_items:decorative_cloud"}, {["x"] = 3, ["y"] = 4, ["z"] = 11, ["name"] = "cloud_items:decorative_cloud"}, {["x"] = 3, ["y"] = 4, ["z"] = 12, ["name"] = "cloud_items:decorative_cloud"}, {["x"] = 3, ["y"] = 5, ["z"] = 3, ["name"] = "cloud_items:decorative_cloud"}, {["x"] = 3, ["y"] = 5, ["z"] = 4, ["name"] = "cloud_items:decorative_cloud"}, {["x"] = 3, ["y"] = 5, ["z"] = 5, ["name"] = "cloud_items:decorative_cloud"}, {["x"] = 3, ["y"] = 5, ["z"] = 6, ["name"] = "cloud_items:decorative_cloud"}, {["x"] = 3, ["y"] = 5, ["z"] = 7, ["name"] = "cloud_items:decorative_cloud"}, {["x"] = 3, ["y"] = 5, ["z"] = 8, ["name"] = "cloud_items:decorative_cloud"}, {["x"] = 3, ["y"] = 5, ["z"] = 9, ["name"] = "cloud_items:decorative_cloud"}, {["x"] = 3, ["y"] = 5, ["z"] = 10, ["name"] = "cloud_items:decorative_cloud"}, {["x"] = 3, ["y"] = 5, ["z"] = 11, ["name"] = "cloud_items:decorative_cloud"}, {["x"] = 3, ["y"] = 5, ["z"] = 12, ["name"] = "cloud_items:decorative_cloud"}, {["x"] = 3, ["y"] = 6, ["z"] = 3, ["name"] = "cloud_items:decorative_cloud"}, {["x"] = 3, ["y"] = 6, ["z"] = 4, ["name"] = "cloud_items:decorative_cloud"}, {["x"] = 3, ["y"] = 6, ["z"] = 5, ["name"] = "cloud_items:decorative_cloud"}, {["x"] = 3, ["y"] = 6, ["z"] = 6, ["name"] = "cloud_items:decorative_cloud"}, {["x"] = 3, ["y"] = 6, ["z"] = 7, ["name"] = "cloud_items:decorative_cloud"}, {["x"] = 3, ["y"] = 6, ["z"] = 8, ["name"] = "cloud_items:decorative_cloud"}, {["x"] = 3, ["y"] = 6, ["z"] = 9, ["name"] = "cloud_items:decorative_cloud"}, {["x"] = 3, ["y"] = 6, ["z"] = 10, ["name"] = "cloud_items:decorative_cloud"}, {["x"] = 3, ["y"] = 6, ["z"] = 11, ["name"] = "cloud_items:decorative_cloud"}, {["x"] = 3, ["y"] = 6, ["z"] = 12, ["name"] = "cloud_items:decorative_cloud"}, {["x"] = 3, ["y"] = 7, ["z"] = 3, ["name"] = "cloud_items:decorative_cloud"}, {["x"] = 3, ["y"] = 7, ["z"] = 4, ["name"] = "cloud_items:decorative_cloud"}, {["x"] = 3, ["y"] = 7, ["z"] = 5, ["name"] = "cloud_items:decorative_cloud"}, {["x"] = 3, ["y"] = 7, ["z"] = 6, ["name"] = "cloud_items:decorative_cloud"}, {["x"] = 3, ["y"] = 7, ["z"] = 7, ["name"] = "cloud_items:decorative_cloud"}, {["x"] = 3, ["y"] = 7, ["z"] = 8, ["name"] = "cloud_items:decorative_cloud"}, {["x"] = 3, ["y"] = 7, ["z"] = 9, ["name"] = "cloud_items:decorative_cloud"}, {["x"] = 3, ["y"] = 7, ["z"] = 10, ["name"] = "cloud_items:decorative_cloud"}, {["x"] = 3, ["y"] = 7, ["z"] = 11, ["name"] = "cloud_items:decorative_cloud"}, {["x"] = 3, ["y"] = 7, ["z"] = 12, ["name"] = "cloud_items:decorative_cloud"}, {["x"] = 3, ["y"] = 8, ["z"] = 3, ["name"] = "cloud_items:decorative_cloud"}, {["x"] = 3, ["y"] = 8, ["z"] = 4, ["name"] = "cloud_items:decorative_cloud"}, {["x"] = 3, ["y"] = 8, ["z"] = 5, ["name"] = "cloud_items:decorative_cloud"}, {["x"] = 3, ["y"] = 8, ["z"] = 6, ["name"] = "cloud_items:decorative_cloud"}, {["x"] = 3, ["y"] = 8, ["z"] = 7, ["name"] = "cloud_items:decorative_cloud"}, {["x"] = 3, ["meta"] = {["fields"] = {["state"] = "2"}, ["inventory"] = {}}, ["param2"] = 1, ["y"] = 8, ["param1"] = 110, ["z"] = 8, ["name"] = "doors:door_glass_b"}, {["x"] = 3, ["meta"] = {["fields"] = {["state"] = "0"}, ["inventory"] = {}}, ["param2"] = 1, ["y"] = 8, ["param1"] = 126, ["z"] = 9, ["name"] = "doors:door_glass_a"}, {["x"] = 3, ["y"] = 8, ["z"] = 10, ["name"] = "cloud_items:decorative_cloud"}, {["x"] = 3, ["y"] = 8, ["z"] = 11, ["name"] = "cloud_items:decorative_cloud"}, {["x"] = 3, ["y"] = 8, ["z"] = 12, ["name"] = "cloud_items:decorative_cloud"}, {["x"] = 3, ["y"] = 9, ["z"] = 3, ["name"] = "cloud_items:decorative_cloud"}, {["x"] = 3, ["y"] = 9, ["z"] = 4, ["name"] = "cloud_items:decorative_cloud"}, {["x"] = 3, ["y"] = 9, ["z"] = 5, ["name"] = "cloud_items:decorative_cloud"}, {["x"] = 3, ["y"] = 9, ["z"] = 6, ["name"] = "cloud_items:decorative_cloud"}, {["x"] = 3, ["y"] = 9, ["z"] = 7, ["name"] = "cloud_items:decorative_cloud"}, {["x"] = 3, ["y"] = 9, ["param1"] = 126, ["z"] = 8, ["name"] = "doors:hidden"}, {["x"] = 3, ["param2"] = 1, ["y"] = 9, ["param1"] = 142, ["z"] = 9, ["name"] = "doors:hidden"}, {["x"] = 3, ["y"] = 9, ["z"] = 10, ["name"] = "cloud_items:decorative_cloud"}, {["x"] = 3, ["y"] = 9, ["z"] = 11, ["name"] = "cloud_items:decorative_cloud"}, {["x"] = 3, ["y"] = 9, ["z"] = 12, ["name"] = "cloud_items:decorative_cloud"}, {["x"] = 3, ["y"] = 10, ["z"] = 3, ["name"] = "cloud_items:decorative_cloud"}, {["x"] = 3, ["y"] = 10, ["z"] = 4, ["name"] = "cloud_items:decorative_cloud"}, {["x"] = 3, ["y"] = 10, ["z"] = 5, ["name"] = "cloud_items:decorative_cloud"}, {["x"] = 3, ["y"] = 10, ["z"] = 6, ["name"] = "cloud_items:decorative_cloud"}, {["x"] = 3, ["y"] = 10, ["z"] = 7, ["name"] = "cloud_items:decorative_cloud"}, {["x"] = 3, ["y"] = 10, ["z"] = 8, ["name"] = "cloud_items:decorative_cloud"}, {["x"] = 3, ["y"] = 10, ["z"] = 9, ["name"] = "cloud_items:decorative_cloud"}, {["x"] = 3, ["y"] = 10, ["z"] = 10, ["name"] = "cloud_items:decorative_cloud"}, {["x"] = 3, ["y"] = 10, ["z"] = 11, ["name"] = "cloud_items:decorative_cloud"}, {["x"] = 3, ["y"] = 10, ["z"] = 12, ["name"] = "cloud_items:decorative_cloud"}, {["x"] = 3, ["y"] = 11, ["z"] = 3, ["name"] = "cloud_items:decorative_cloud"}, {["x"] = 3, ["y"] = 11, ["z"] = 4, ["name"] = "cloud_items:decorative_cloud"}, {["x"] = 3, ["y"] = 11, ["z"] = 5, ["name"] = "cloud_items:decorative_cloud"}, {["x"] = 3, ["y"] = 11, ["z"] = 6, ["name"] = "cloud_items:decorative_cloud"}, {["x"] = 3, ["y"] = 11, ["z"] = 7, ["name"] = "cloud_items:decorative_cloud"}, {["x"] = 3, ["y"] = 11, ["z"] = 8, ["name"] = "cloud_items:decorative_cloud"}, {["x"] = 3, ["y"] = 11, ["z"] = 9, ["name"] = "cloud_items:decorative_cloud"}, {["x"] = 3, ["y"] = 11, ["z"] = 10, ["name"] = "cloud_items:decorative_cloud"}, {["x"] = 3, ["y"] = 11, ["z"] = 11, ["name"] = "cloud_items:decorative_cloud"}, {["x"] = 3, ["y"] = 11, ["z"] = 12, ["name"] = "cloud_items:decorative_cloud"}, {["x"] = 3, ["y"] = 12, ["z"] = 3, ["name"] = "cloud_items:decorative_cloud"}, {["x"] = 3, ["y"] = 12, ["z"] = 4, ["name"] = "cloud_items:decorative_cloud"}, {["x"] = 3, ["y"] = 12, ["z"] = 5, ["name"] = "cloud_items:decorative_cloud"}, {["x"] = 3, ["y"] = 12, ["z"] = 6, ["name"] = "cloud_items:decorative_cloud"}, {["x"] = 3, ["y"] = 12, ["z"] = 7, ["name"] = "cloud_items:decorative_cloud"}, {["x"] = 3, ["y"] = 12, ["z"] = 8, ["name"] = "cloud_items:decorative_cloud"}, {["x"] = 3, ["y"] = 12, ["z"] = 9, ["name"] = "cloud_items:decorative_cloud"}, {["x"] = 3, ["y"] = 12, ["z"] = 10, ["name"] = "cloud_items:decorative_cloud"}, {["x"] = 3, ["y"] = 12, ["z"] = 11, ["name"] = "cloud_items:decorative_cloud"}, {["x"] = 3, ["y"] = 12, ["z"] = 12, ["name"] = "cloud_items:decorative_cloud"}, {["x"] = 4, ["y"] = 0, ["z"] = 0, ["name"] = "cloud_items:decorative_cloud"}, {["x"] = 4, ["y"] = 0, ["z"] = 1, ["name"] = "cloud_items:decorative_cloud"}, {["x"] = 4, ["y"] = 0, ["z"] = 2, ["name"] = "cloud_items:decorative_cloud"}, {["x"] = 4, ["y"] = 0, ["z"] = 3, ["name"] = "cloud_items:decorative_cloud"}, {["x"] = 4, ["y"] = 0, ["z"] = 4, ["name"] = "cloud_items:decorative_cloud"}, {["x"] = 4, ["y"] = 0, ["z"] = 5, ["name"] = "cloud_items:decorative_cloud"}, {["x"] = 4, ["y"] = 0, ["z"] = 6, ["name"] = "cloud_items:decorative_cloud"}, {["x"] = 4, ["y"] = 0, ["z"] = 7, ["name"] = "cloud_items:decorative_cloud"}, {["x"] = 4, ["y"] = 0, ["z"] = 8, ["name"] = "cloud_items:decorative_cloud"}, {["x"] = 4, ["y"] = 0, ["z"] = 9, ["name"] = "cloud_items:decorative_cloud"}, {["x"] = 4, ["y"] = 0, ["z"] = 10, ["name"] = "cloud_items:decorative_cloud"}, {["x"] = 4, ["y"] = 0, ["z"] = 11, ["name"] = "cloud_items:decorative_cloud"}, {["x"] = 4, ["y"] = 0, ["z"] = 12, ["name"] = "cloud_items:decorative_cloud"}, {["x"] = 4, ["y"] = 0, ["z"] = 13, ["name"] = "cloud_items:decorative_cloud"}, {["x"] = 4, ["y"] = 0, ["z"] = 14, ["name"] = "cloud_items:decorative_cloud"}, {["x"] = 4, ["y"] = 0, ["z"] = 15, ["name"] = "cloud_items:decorative_cloud"}, {["x"] = 4, ["y"] = 1, ["z"] = 3, ["name"] = "cloud_items:decorative_cloud"}, {["x"] = 4, ["y"] = 1, ["param1"] = 238, ["z"] = 4, ["name"] = "default:mese_post_light"}, {["x"] = 4, ["param2"] = 3, ["y"] = 1, ["param1"] = 187, ["z"] = 7, ["name"] = "stairs:stair_goldblock"}, {["x"] = 4, ["param2"] = 3, ["y"] = 1, ["param1"] = 170, ["z"] = 8, ["name"] = "stairs:stair_goldblock"}, {["x"] = 4, ["param2"] = 3, ["y"] = 1, ["param1"] = 153, ["z"] = 9, ["name"] = "stairs:stair_goldblock"}, {["x"] = 4, ["param2"] = 4, ["y"] = 1, ["param1"] = 122, ["z"] = 11, ["name"] = "default:ladder_steel"}, {["x"] = 4, ["y"] = 1, ["z"] = 12, ["name"] = "cloud_items:decorative_cloud"}, {["x"] = 4, ["y"] = 2, ["z"] = 3, ["name"] = "cloud_items:decorative_cloud"}, {["x"] = 4, ["param2"] = 4, ["y"] = 2, ["param1"] = 106, ["z"] = 11, ["name"] = "default:ladder_steel"}, {["x"] = 4, ["y"] = 2, ["z"] = 12, ["name"] = "cloud_items:decorative_cloud"}, {["x"] = 4, ["param2"] = 3, ["y"] = 2, ["param1"] = 158, ["z"] = 13, ["name"] = "stairs:stair_decorative_cloud"}, {["x"] = 4, ["param2"] = 3, ["y"] = 2, ["param1"] = 174, ["z"] = 14, ["name"] = "stairs:stair_decorative_cloud"}, {["x"] = 4, ["y"] = 3, ["z"] = 3, ["name"] = "cloud_items:decorative_cloud"}, {["x"] = 4, ["param2"] = 4, ["y"] = 3, ["param1"] = 90, ["z"] = 11, ["name"] = "default:ladder_steel"}, {["x"] = 4, ["y"] = 3, ["z"] = 12, ["name"] = "cloud_items:decorative_cloud"}, {["x"] = 4, ["y"] = 4, ["z"] = 3, ["name"] = "cloud_items:decorative_cloud"}, {["x"] = 4, ["param2"] = 4, ["y"] = 4, ["param1"] = 105, ["z"] = 11, ["name"] = "default:ladder_steel"}, {["x"] = 4, ["y"] = 4, ["z"] = 12, ["name"] = "cloud_items:decorative_cloud"}, {["x"] = 4, ["y"] = 5, ["z"] = 3, ["name"] = "cloud_items:decorative_cloud"}, {["x"] = 4, ["param2"] = 4, ["y"] = 5, ["param1"] = 120, ["z"] = 11, ["name"] = "default:ladder_steel"}, {["x"] = 4, ["y"] = 5, ["z"] = 12, ["name"] = "cloud_items:decorative_cloud"}, {["x"] = 4, ["y"] = 6, ["z"] = 3, ["name"] = "cloud_items:decorative_cloud"}, {["x"] = 4, ["y"] = 6, ["z"] = 4, ["name"] = "cloud_items:decorative_cloud"}, {["x"] = 4, ["y"] = 6, ["z"] = 5, ["name"] = "cloud_items:decorative_cloud"}, {["x"] = 4, ["y"] = 6, ["z"] = 6, ["name"] = "cloud_items:decorative_cloud"}, {["x"] = 4, ["y"] = 6, ["z"] = 7, ["name"] = "cloud_items:decorative_cloud"}, {["x"] = 4, ["y"] = 6, ["z"] = 8, ["name"] = "cloud_items:decorative_cloud"}, {["x"] = 4, ["y"] = 6, ["z"] = 9, ["name"] = "cloud_items:decorative_cloud"}, {["x"] = 4, ["y"] = 6, ["z"] = 10, ["name"] = "cloud_items:decorative_cloud"}, {["x"] = 4, ["param2"] = 4, ["y"] = 6, ["param1"] = 137, ["z"] = 11, ["name"] = "default:ladder_steel"}, {["x"] = 4, ["y"] = 6, ["z"] = 12, ["name"] = "cloud_items:decorative_cloud"}, {["x"] = 4, ["y"] = 7, ["z"] = 3, ["name"] = "cloud_items:decorative_cloud"}, {["x"] = 4, ["meta"] = {["fields"] = {["infotext"] = "\27(T@default)Empty Bookshelf\27E", ["formspec"] = "size[8,7;]list[context;books;0,0.3;8,2;]list[current_player;main;0,2.85;8,1;]list[current_player;main;0,4.08;8,3;8]listring[context;books]listring[current_player;main]image[0,2.85;1,1;gui_hb_bg.png]image[1,2.85;1,1;gui_hb_bg.png]image[2,2.85;1,1;gui_hb_bg.png]image[3,2.85;1,1;gui_hb_bg.png]image[4,2.85;1,1;gui_hb_bg.png]image[5,2.85;1,1;gui_hb_bg.png]image[6,2.85;1,1;gui_hb_bg.png]image[7,2.85;1,1;gui_hb_bg.png]image[0,0.3;1,1;default_bookshelf_slot.png]image[1,0.3;1,1;default_bookshelf_slot.png]image[2,0.3;1,1;default_bookshelf_slot.png]image[3,0.3;1,1;default_bookshelf_slot.png]image[4,0.3;1,1;default_bookshelf_slot.png]image[5,0.3;1,1;default_bookshelf_slot.png]image[6,0.3;1,1;default_bookshelf_slot.png]image[7,0.3;1,1;default_bookshelf_slot.png]image[0,1.3;1,1;default_bookshelf_slot.png]image[1,1.3;1,1;default_bookshelf_slot.png]image[2,1.3;1,1;default_bookshelf_slot.png]image[3,1.3;1,1;default_bookshelf_slot.png]image[4,1.3;1,1;default_bookshelf_slot.png]image[5,1.3;1,1;default_bookshelf_slot.png]image[6,1.3;1,1;default_bookshelf_slot.png]image[7,1.3;1,1;default_bookshelf_slot.png]"}, ["inventory"] = {["books"] = {"", "", "", "", "", "", "", "", "", "", "", "", "", "", "", ""}}}, ["param2"] = 2, ["y"] = 7, ["z"] = 4, ["name"] = "default:bookshelf"}, {["x"] = 4, ["param2"] = 3, ["y"] = 7, ["param1"] = 108, ["z"] = 8, ["name"] = "stairs:stair_decorative_cloud"}, {["x"] = 4, ["param2"] = 3, ["y"] = 7, ["param1"] = 124, ["z"] = 9, ["name"] = "stairs:stair_decorative_cloud"}, {["x"] = 4, ["y"] = 7, ["z"] = 12, ["name"] = "cloud_items:decorative_cloud"}, {["x"] = 4, ["y"] = 8, ["z"] = 3, ["name"] = "cloud_items:decorative_cloud"}, {["x"] = 4, ["meta"] = {["fields"] = {["infotext"] = "\27(T@default)Empty Bookshelf\27E", ["formspec"] = "size[8,7;]list[context;books;0,0.3;8,2;]list[current_player;main;0,2.85;8,1;]list[current_player;main;0,4.08;8,3;8]listring[context;books]listring[current_player;main]image[0,2.85;1,1;gui_hb_bg.png]image[1,2.85;1,1;gui_hb_bg.png]image[2,2.85;1,1;gui_hb_bg.png]image[3,2.85;1,1;gui_hb_bg.png]image[4,2.85;1,1;gui_hb_bg.png]image[5,2.85;1,1;gui_hb_bg.png]image[6,2.85;1,1;gui_hb_bg.png]image[7,2.85;1,1;gui_hb_bg.png]image[0,0.3;1,1;default_bookshelf_slot.png]image[1,0.3;1,1;default_bookshelf_slot.png]image[2,0.3;1,1;default_bookshelf_slot.png]image[3,0.3;1,1;default_bookshelf_slot.png]image[4,0.3;1,1;default_bookshelf_slot.png]image[5,0.3;1,1;default_bookshelf_slot.png]image[6,0.3;1,1;default_bookshelf_slot.png]image[7,0.3;1,1;default_bookshelf_slot.png]image[0,1.3;1,1;default_bookshelf_slot.png]image[1,1.3;1,1;default_bookshelf_slot.png]image[2,1.3;1,1;default_bookshelf_slot.png]image[3,1.3;1,1;default_bookshelf_slot.png]image[4,1.3;1,1;default_bookshelf_slot.png]image[5,1.3;1,1;default_bookshelf_slot.png]image[6,1.3;1,1;default_bookshelf_slot.png]image[7,1.3;1,1;default_bookshelf_slot.png]"}, ["inventory"] = {["books"] = {"", "", "", "", "", "", "", "", "", "", "", "", "", "", "", ""}}}, ["param2"] = 2, ["y"] = 8, ["z"] = 4, ["name"] = "default:bookshelf"}, {["x"] = 4, ["y"] = 8, ["z"] = 12, ["name"] = "cloud_items:decorative_cloud"}, {["x"] = 4, ["y"] = 9, ["z"] = 3, ["name"] = "cloud_items:decorative_cloud"}, {["x"] = 4, ["meta"] = {["fields"] = {["infotext"] = "\27(T@default)Empty Bookshelf\27E", ["formspec"] = "size[8,7;]list[context;books;0,0.3;8,2;]list[current_player;main;0,2.85;8,1;]list[current_player;main;0,4.08;8,3;8]listring[context;books]listring[current_player;main]image[0,2.85;1,1;gui_hb_bg.png]image[1,2.85;1,1;gui_hb_bg.png]image[2,2.85;1,1;gui_hb_bg.png]image[3,2.85;1,1;gui_hb_bg.png]image[4,2.85;1,1;gui_hb_bg.png]image[5,2.85;1,1;gui_hb_bg.png]image[6,2.85;1,1;gui_hb_bg.png]image[7,2.85;1,1;gui_hb_bg.png]image[0,0.3;1,1;default_bookshelf_slot.png]image[1,0.3;1,1;default_bookshelf_slot.png]image[2,0.3;1,1;default_bookshelf_slot.png]image[3,0.3;1,1;default_bookshelf_slot.png]image[4,0.3;1,1;default_bookshelf_slot.png]image[5,0.3;1,1;default_bookshelf_slot.png]image[6,0.3;1,1;default_bookshelf_slot.png]image[7,0.3;1,1;default_bookshelf_slot.png]image[0,1.3;1,1;default_bookshelf_slot.png]image[1,1.3;1,1;default_bookshelf_slot.png]image[2,1.3;1,1;default_bookshelf_slot.png]image[3,1.3;1,1;default_bookshelf_slot.png]image[4,1.3;1,1;default_bookshelf_slot.png]image[5,1.3;1,1;default_bookshelf_slot.png]image[6,1.3;1,1;default_bookshelf_slot.png]image[7,1.3;1,1;default_bookshelf_slot.png]"}, ["inventory"] = {["books"] = {"", "", "", "", "", "", "", "", "", "", "", "", "", "", "", ""}}}, ["param2"] = 2, ["y"] = 9, ["z"] = 4, ["name"] = "default:bookshelf"}, {["x"] = 4, ["y"] = 9, ["z"] = 12, ["name"] = "cloud_items:decorative_cloud"}, {["x"] = 4, ["y"] = 10, ["z"] = 3, ["name"] = "cloud_items:decorative_cloud"}, {["x"] = 4, ["y"] = 10, ["z"] = 12, ["name"] = "cloud_items:decorative_cloud"}, {["x"] = 4, ["y"] = 11, ["param1"] = 238, ["z"] = 3, ["name"] = "default:meselamp"}, {["x"] = 4, ["y"] = 11, ["param1"] = 238, ["z"] = 12, ["name"] = "default:meselamp"}, {["x"] = 4, ["y"] = 12, ["z"] = 3, ["name"] = "cloud_items:decorative_cloud"}, {["x"] = 4, ["y"] = 12, ["z"] = 4, ["name"] = "cloud_items:decorative_cloud"}, {["x"] = 4, ["y"] = 12, ["z"] = 5, ["name"] = "cloud_items:decorative_cloud"}, {["x"] = 4, ["y"] = 12, ["z"] = 6, ["name"] = "cloud_items:decorative_cloud"}, {["x"] = 4, ["y"] = 12, ["z"] = 7, ["name"] = "cloud_items:decorative_cloud"}, {["x"] = 4, ["y"] = 12, ["z"] = 8, ["name"] = "cloud_items:decorative_cloud"}, {["x"] = 4, ["y"] = 12, ["z"] = 9, ["name"] = "cloud_items:decorative_cloud"}, {["x"] = 4, ["y"] = 12, ["z"] = 10, ["name"] = "cloud_items:decorative_cloud"}, {["x"] = 4, ["y"] = 12, ["z"] = 11, ["name"] = "cloud_items:decorative_cloud"}, {["x"] = 4, ["y"] = 12, ["z"] = 12, ["name"] = "cloud_items:decorative_cloud"}, {["x"] = 5, ["y"] = 0, ["z"] = 0, ["name"] = "cloud_items:decorative_cloud"}, {["x"] = 5, ["y"] = 0, ["z"] = 1, ["name"] = "cloud_items:decorative_cloud"}, {["x"] = 5, ["y"] = 0, ["z"] = 2, ["name"] = "cloud_items:decorative_cloud"}, {["x"] = 5, ["y"] = 0, ["z"] = 3, ["name"] = "cloud_items:decorative_cloud"}, {["x"] = 5, ["y"] = 0, ["z"] = 4, ["name"] = "cloud_items:decorative_cloud"}, {["x"] = 5, ["y"] = 0, ["z"] = 5, ["name"] = "cloud_items:decorative_cloud"}, {["x"] = 5, ["y"] = 0, ["z"] = 6, ["name"] = "cloud_items:decorative_cloud"}, {["x"] = 5, ["y"] = 0, ["z"] = 7, ["name"] = "cloud_items:decorative_cloud"}, {["x"] = 5, ["y"] = 0, ["z"] = 8, ["name"] = "cloud_items:decorative_cloud"}, {["x"] = 5, ["y"] = 0, ["z"] = 9, ["name"] = "cloud_items:decorative_cloud"}, {["x"] = 5, ["y"] = 0, ["z"] = 10, ["name"] = "cloud_items:decorative_cloud"}, {["x"] = 5, ["y"] = 0, ["z"] = 11, ["name"] = "cloud_items:decorative_cloud"}, {["x"] = 5, ["y"] = 0, ["z"] = 12, ["name"] = "cloud_items:decorative_cloud"}, {["x"] = 5, ["y"] = 0, ["z"] = 13, ["name"] = "cloud_items:decorative_cloud"}, {["x"] = 5, ["y"] = 0, ["z"] = 14, ["name"] = "cloud_items:decorative_cloud"}, {["x"] = 5, ["y"] = 0, ["z"] = 15, ["name"] = "cloud_items:decorative_cloud"}, {["x"] = 5, ["y"] = 1, ["z"] = 3, ["name"] = "cloud_items:decorative_cloud"}, {["x"] = 5, ["y"] = 1, ["z"] = 12, ["name"] = "cloud_items:decorative_cloud"}, {["x"] = 5, ["param2"] = 3, ["y"] = 1, ["param1"] = 158, ["z"] = 13, ["name"] = "stairs:stair_decorative_cloud"}, {["x"] = 5, ["param2"] = 3, ["y"] = 1, ["param1"] = 174, ["z"] = 14, ["name"] = "stairs:stair_decorative_cloud"}, {["x"] = 5, ["y"] = 2, ["z"] = 3, ["name"] = "cloud_items:decorative_cloud"}, {["x"] = 5, ["y"] = 2, ["z"] = 12, ["name"] = "cloud_items:decorative_cloud"}, {["x"] = 5, ["y"] = 3, ["z"] = 3, ["name"] = "cloud_items:decorative_cloud"}, {["x"] = 5, ["y"] = 3, ["z"] = 12, ["name"] = "cloud_items:decorative_cloud"}, {["x"] = 5, ["y"] = 4, ["z"] = 3, ["name"] = "cloud_items:decorative_cloud"}, {["x"] = 5, ["y"] = 4, ["z"] = 12, ["name"] = "cloud_items:decorative_cloud"}, {["x"] = 5, ["y"] = 5, ["z"] = 3, ["name"] = "cloud_items:decorative_cloud"}, {["x"] = 5, ["y"] = 5, ["z"] = 12, ["name"] = "cloud_items:decorative_cloud"}, {["x"] = 5, ["y"] = 6, ["z"] = 3, ["name"] = "cloud_items:decorative_cloud"}, {["x"] = 5, ["y"] = 6, ["z"] = 4, ["name"] = "cloud_items:decorative_cloud"}, {["x"] = 5, ["y"] = 6, ["z"] = 5, ["name"] = "cloud_items:decorative_cloud"}, {["x"] = 5, ["y"] = 6, ["z"] = 6, ["name"] = "cloud_items:decorative_cloud"}, {["x"] = 5, ["y"] = 6, ["z"] = 7, ["name"] = "cloud_items:decorative_cloud"}, {["x"] = 5, ["y"] = 6, ["z"] = 8, ["name"] = "cloud_items:decorative_cloud"}, {["x"] = 5, ["y"] = 6, ["z"] = 9, ["name"] = "cloud_items:decorative_cloud"}, {["x"] = 5, ["y"] = 6, ["z"] = 10, ["name"] = "cloud_items:decorative_cloud"}, {["x"] = 5, ["y"] = 6, ["z"] = 11, ["name"] = "cloud_items:decorative_cloud"}, {["x"] = 5, ["y"] = 6, ["z"] = 12, ["name"] = "cloud_items:decorative_cloud"}, {["x"] = 5, ["y"] = 7, ["z"] = 3, ["name"] = "cloud_items:decorative_cloud"}, {["x"] = 5, ["meta"] = {["fields"] = {["infotext"] = "\27(T@default)Empty Bookshelf\27E", ["formspec"] = "size[8,7;]list[context;books;0,0.3;8,2;]list[current_player;main;0,2.85;8,1;]list[current_player;main;0,4.08;8,3;8]listring[context;books]listring[current_player;main]image[0,2.85;1,1;gui_hb_bg.png]image[1,2.85;1,1;gui_hb_bg.png]image[2,2.85;1,1;gui_hb_bg.png]image[3,2.85;1,1;gui_hb_bg.png]image[4,2.85;1,1;gui_hb_bg.png]image[5,2.85;1,1;gui_hb_bg.png]image[6,2.85;1,1;gui_hb_bg.png]image[7,2.85;1,1;gui_hb_bg.png]image[0,0.3;1,1;default_bookshelf_slot.png]image[1,0.3;1,1;default_bookshelf_slot.png]image[2,0.3;1,1;default_bookshelf_slot.png]image[3,0.3;1,1;default_bookshelf_slot.png]image[4,0.3;1,1;default_bookshelf_slot.png]image[5,0.3;1,1;default_bookshelf_slot.png]image[6,0.3;1,1;default_bookshelf_slot.png]image[7,0.3;1,1;default_bookshelf_slot.png]image[0,1.3;1,1;default_bookshelf_slot.png]image[1,1.3;1,1;default_bookshelf_slot.png]image[2,1.3;1,1;default_bookshelf_slot.png]image[3,1.3;1,1;default_bookshelf_slot.png]image[4,1.3;1,1;default_bookshelf_slot.png]image[5,1.3;1,1;default_bookshelf_slot.png]image[6,1.3;1,1;default_bookshelf_slot.png]image[7,1.3;1,1;default_bookshelf_slot.png]"}, ["inventory"] = {["books"] = {"", "", "", "", "", "", "", "", "", "", "", "", "", "", "", ""}}}, ["param2"] = 2, ["y"] = 7, ["z"] = 4, ["name"] = "default:bookshelf"}, {["x"] = 5, ["y"] = 7, ["z"] = 12, ["name"] = "cloud_items:decorative_cloud"}, {["x"] = 5, ["y"] = 8, ["z"] = 3, ["name"] = "cloud_items:decorative_cloud"}, {["x"] = 5, ["meta"] = {["fields"] = {["infotext"] = "\27(T@default)Empty Bookshelf\27E", ["formspec"] = "size[8,7;]list[context;books;0,0.3;8,2;]list[current_player;main;0,2.85;8,1;]list[current_player;main;0,4.08;8,3;8]listring[context;books]listring[current_player;main]image[0,2.85;1,1;gui_hb_bg.png]image[1,2.85;1,1;gui_hb_bg.png]image[2,2.85;1,1;gui_hb_bg.png]image[3,2.85;1,1;gui_hb_bg.png]image[4,2.85;1,1;gui_hb_bg.png]image[5,2.85;1,1;gui_hb_bg.png]image[6,2.85;1,1;gui_hb_bg.png]image[7,2.85;1,1;gui_hb_bg.png]image[0,0.3;1,1;default_bookshelf_slot.png]image[1,0.3;1,1;default_bookshelf_slot.png]image[2,0.3;1,1;default_bookshelf_slot.png]image[3,0.3;1,1;default_bookshelf_slot.png]image[4,0.3;1,1;default_bookshelf_slot.png]image[5,0.3;1,1;default_bookshelf_slot.png]image[6,0.3;1,1;default_bookshelf_slot.png]image[7,0.3;1,1;default_bookshelf_slot.png]image[0,1.3;1,1;default_bookshelf_slot.png]image[1,1.3;1,1;default_bookshelf_slot.png]image[2,1.3;1,1;default_bookshelf_slot.png]image[3,1.3;1,1;default_bookshelf_slot.png]image[4,1.3;1,1;default_bookshelf_slot.png]image[5,1.3;1,1;default_bookshelf_slot.png]image[6,1.3;1,1;default_bookshelf_slot.png]image[7,1.3;1,1;default_bookshelf_slot.png]"}, ["inventory"] = {["books"] = {"", "", "", "", "", "", "", "", "", "", "", "", "", "", "", ""}}}, ["param2"] = 2, ["y"] = 8, ["z"] = 4, ["name"] = "default:bookshelf"}, {["x"] = 5, ["y"] = 8, ["z"] = 12, ["name"] = "cloud_items:decorative_cloud"}, {["x"] = 5, ["y"] = 9, ["z"] = 3, ["name"] = "cloud_items:decorative_cloud"}, {["x"] = 5, ["meta"] = {["fields"] = {["infotext"] = "\27(T@default)Empty Bookshelf\27E", ["formspec"] = "size[8,7;]list[context;books;0,0.3;8,2;]list[current_player;main;0,2.85;8,1;]list[current_player;main;0,4.08;8,3;8]listring[context;books]listring[current_player;main]image[0,2.85;1,1;gui_hb_bg.png]image[1,2.85;1,1;gui_hb_bg.png]image[2,2.85;1,1;gui_hb_bg.png]image[3,2.85;1,1;gui_hb_bg.png]image[4,2.85;1,1;gui_hb_bg.png]image[5,2.85;1,1;gui_hb_bg.png]image[6,2.85;1,1;gui_hb_bg.png]image[7,2.85;1,1;gui_hb_bg.png]image[0,0.3;1,1;default_bookshelf_slot.png]image[1,0.3;1,1;default_bookshelf_slot.png]image[2,0.3;1,1;default_bookshelf_slot.png]image[3,0.3;1,1;default_bookshelf_slot.png]image[4,0.3;1,1;default_bookshelf_slot.png]image[5,0.3;1,1;default_bookshelf_slot.png]image[6,0.3;1,1;default_bookshelf_slot.png]image[7,0.3;1,1;default_bookshelf_slot.png]image[0,1.3;1,1;default_bookshelf_slot.png]image[1,1.3;1,1;default_bookshelf_slot.png]image[2,1.3;1,1;default_bookshelf_slot.png]image[3,1.3;1,1;default_bookshelf_slot.png]image[4,1.3;1,1;default_bookshelf_slot.png]image[5,1.3;1,1;default_bookshelf_slot.png]image[6,1.3;1,1;default_bookshelf_slot.png]image[7,1.3;1,1;default_bookshelf_slot.png]"}, ["inventory"] = {["books"] = {"", "", "", "", "", "", "", "", "", "", "", "", "", "", "", ""}}}, ["param2"] = 2, ["y"] = 9, ["z"] = 4, ["name"] = "default:bookshelf"}, {["x"] = 5, ["y"] = 9, ["z"] = 12, ["name"] = "cloud_items:decorative_cloud"}, {["x"] = 5, ["y"] = 10, ["z"] = 3, ["name"] = "cloud_items:decorative_cloud"}, {["x"] = 5, ["y"] = 10, ["z"] = 12, ["name"] = "cloud_items:decorative_cloud"}, {["x"] = 5, ["y"] = 11, ["z"] = 3, ["name"] = "cloud_items:decorative_cloud"}, {["x"] = 5, ["y"] = 11, ["z"] = 12, ["name"] = "cloud_items:decorative_cloud"}, {["x"] = 5, ["y"] = 12, ["z"] = 3, ["name"] = "cloud_items:decorative_cloud"}, {["x"] = 5, ["y"] = 12, ["z"] = 4, ["name"] = "cloud_items:decorative_cloud"}, {["x"] = 5, ["y"] = 12, ["z"] = 5, ["name"] = "cloud_items:decorative_cloud"}, {["x"] = 5, ["y"] = 12, ["z"] = 6, ["name"] = "cloud_items:decorative_cloud"}, {["x"] = 5, ["y"] = 12, ["z"] = 7, ["name"] = "cloud_items:decorative_cloud"}, {["x"] = 5, ["y"] = 12, ["z"] = 8, ["name"] = "cloud_items:decorative_cloud"}, {["x"] = 5, ["y"] = 12, ["z"] = 9, ["name"] = "cloud_items:decorative_cloud"}, {["x"] = 5, ["y"] = 12, ["z"] = 10, ["name"] = "cloud_items:decorative_cloud"}, {["x"] = 5, ["y"] = 12, ["z"] = 11, ["name"] = "cloud_items:decorative_cloud"}, {["x"] = 5, ["y"] = 12, ["z"] = 12, ["name"] = "cloud_items:decorative_cloud"}, {["x"] = 6, ["y"] = 0, ["z"] = 0, ["name"] = "cloud_items:decorative_cloud"}, {["x"] = 6, ["y"] = 0, ["z"] = 1, ["name"] = "cloud_items:decorative_cloud"}, {["x"] = 6, ["y"] = 0, ["z"] = 2, ["name"] = "cloud_items:decorative_cloud"}, {["x"] = 6, ["y"] = 0, ["z"] = 3, ["name"] = "cloud_items:decorative_cloud"}, {["x"] = 6, ["y"] = 0, ["z"] = 4, ["name"] = "cloud_items:decorative_cloud"}, {["x"] = 6, ["y"] = 0, ["z"] = 5, ["name"] = "cloud_items:decorative_cloud"}, {["x"] = 6, ["y"] = 0, ["z"] = 6, ["name"] = "cloud_items:decorative_cloud"}, {["x"] = 6, ["y"] = 0, ["z"] = 7, ["name"] = "cloud_items:decorative_cloud"}, {["x"] = 6, ["y"] = 0, ["z"] = 8, ["name"] = "cloud_items:decorative_cloud"}, {["x"] = 6, ["y"] = 0, ["z"] = 9, ["name"] = "cloud_items:decorative_cloud"}, {["x"] = 6, ["y"] = 0, ["z"] = 10, ["name"] = "cloud_items:decorative_cloud"}, {["x"] = 6, ["y"] = 0, ["z"] = 11, ["name"] = "cloud_items:decorative_cloud"}, {["x"] = 6, ["y"] = 0, ["z"] = 12, ["name"] = "cloud_items:decorative_cloud"}, {["x"] = 6, ["y"] = 0, ["z"] = 13, ["name"] = "cloud_items:decorative_cloud"}, {["x"] = 6, ["y"] = 0, ["z"] = 14, ["name"] = "cloud_items:decorative_cloud"}, {["x"] = 6, ["y"] = 0, ["z"] = 15, ["name"] = "cloud_items:decorative_cloud"}, {["x"] = 6, ["y"] = 1, ["z"] = 3, ["name"] = "cloud_items:decorative_cloud"}, {["x"] = 6, ["y"] = 1, ["z"] = 12, ["name"] = "cloud_items:decorative_cloud"}, {["x"] = 6, ["y"] = 2, ["z"] = 3, ["name"] = "cloud_items:decorative_cloud"}, {["x"] = 6, ["y"] = 2, ["z"] = 12, ["name"] = "cloud_items:decorative_cloud"}, {["x"] = 6, ["y"] = 3, ["z"] = 3, ["name"] = "cloud_items:decorative_cloud"}, {["x"] = 6, ["y"] = 3, ["z"] = 12, ["name"] = "cloud_items:decorative_cloud"}, {["x"] = 6, ["y"] = 4, ["z"] = 3, ["name"] = "cloud_items:decorative_cloud"}, {["x"] = 6, ["y"] = 4, ["z"] = 12, ["name"] = "cloud_items:decorative_cloud"}, {["x"] = 6, ["y"] = 5, ["z"] = 3, ["name"] = "cloud_items:decorative_cloud"}, {["x"] = 6, ["y"] = 5, ["z"] = 12, ["name"] = "cloud_items:decorative_cloud"}, {["x"] = 6, ["y"] = 6, ["z"] = 3, ["name"] = "cloud_items:decorative_cloud"}, {["x"] = 6, ["y"] = 6, ["z"] = 4, ["name"] = "cloud_items:decorative_cloud"}, {["x"] = 6, ["y"] = 6, ["z"] = 5, ["name"] = "cloud_items:decorative_cloud"}, {["x"] = 6, ["y"] = 6, ["z"] = 6, ["name"] = "cloud_items:decorative_cloud"}, {["x"] = 6, ["y"] = 6, ["z"] = 7, ["name"] = "cloud_items:decorative_cloud"}, {["x"] = 6, ["y"] = 6, ["z"] = 8, ["name"] = "cloud_items:decorative_cloud"}, {["x"] = 6, ["y"] = 6, ["z"] = 9, ["name"] = "cloud_items:decorative_cloud"}, {["x"] = 6, ["y"] = 6, ["z"] = 10, ["name"] = "cloud_items:decorative_cloud"}, {["x"] = 6, ["y"] = 6, ["z"] = 11, ["name"] = "cloud_items:decorative_cloud"}, {["x"] = 6, ["y"] = 6, ["z"] = 12, ["name"] = "cloud_items:decorative_cloud"}, {["x"] = 6, ["y"] = 7, ["z"] = 3, ["name"] = "cloud_items:decorative_cloud"}, {["x"] = 6, ["meta"] = {["fields"] = {["infotext"] = "\27(T@default)Chest\27E"}, ["inventory"] = {["main"] = {"default:mese 2", "default:mese_crystal 50", "default:diamond 50", "default:chest_locked 25", "default:apple 50", "default:blueberries 50", "flowers:mushroom_brown 99", "farming:bread 50", "default:sign_wall_steel 6", "doors:door_steel 6", "default:ladder_steel 25", "carts:brakerail 25", "carts:cart 25", "default:book 12", "default:glass 25", "boats:boat 6", "", "", "", "", "", "", "", "", "", "", "", "", "", "", "", ""}}}, ["param2"] = 2, ["y"] = 7, ["param1"] = 119, ["z"] = 4, ["name"] = "default:chest"}, {["x"] = 6, ["y"] = 7, ["z"] = 12, ["name"] = "cloud_items:decorative_cloud"}, {["x"] = 6, ["y"] = 8, ["z"] = 3, ["name"] = "cloud_items:decorative_cloud"}, {["x"] = 6, ["param2"] = 2, ["y"] = 8, ["param1"] = 126, ["z"] = 12, ["name"] = "xpanes:pane_flat"}, {["x"] = 6, ["y"] = 9, ["z"] = 3, ["name"] = "cloud_items:decorative_cloud"}, {["x"] = 6, ["param2"] = 2, ["y"] = 9, ["param1"] = 142, ["z"] = 12, ["name"] = "xpanes:pane_flat"}, {["x"] = 6, ["y"] = 10, ["z"] = 3, ["name"] = "cloud_items:decorative_cloud"}, {["x"] = 6, ["y"] = 10, ["z"] = 12, ["name"] = "cloud_items:decorative_cloud"}, {["x"] = 6, ["y"] = 11, ["z"] = 3, ["name"] = "cloud_items:decorative_cloud"}, {["x"] = 6, ["y"] = 11, ["z"] = 12, ["name"] = "cloud_items:decorative_cloud"}, {["x"] = 6, ["y"] = 12, ["z"] = 3, ["name"] = "cloud_items:decorative_cloud"}, {["x"] = 6, ["y"] = 12, ["z"] = 4, ["name"] = "cloud_items:decorative_cloud"}, {["x"] = 6, ["y"] = 12, ["z"] = 5, ["name"] = "cloud_items:decorative_cloud"}, {["x"] = 6, ["y"] = 12, ["z"] = 6, ["name"] = "cloud_items:decorative_cloud"}, {["x"] = 6, ["y"] = 12, ["z"] = 7, ["name"] = "cloud_items:decorative_cloud"}, {["x"] = 6, ["y"] = 12, ["z"] = 8, ["name"] = "cloud_items:decorative_cloud"}, {["x"] = 6, ["y"] = 12, ["z"] = 9, ["name"] = "cloud_items:decorative_cloud"}, {["x"] = 6, ["y"] = 12, ["z"] = 10, ["name"] = "cloud_items:decorative_cloud"}, {["x"] = 6, ["y"] = 12, ["z"] = 11, ["name"] = "cloud_items:decorative_cloud"}, {["x"] = 6, ["y"] = 12, ["z"] = 12, ["name"] = "cloud_items:decorative_cloud"}, {["x"] = 7, ["y"] = 0, ["z"] = 0, ["name"] = "cloud_items:decorative_cloud"}, {["x"] = 7, ["y"] = 0, ["z"] = 1, ["name"] = "cloud_items:decorative_cloud"}, {["x"] = 7, ["y"] = 0, ["z"] = 2, ["name"] = "cloud_items:decorative_cloud"}, {["x"] = 7, ["y"] = 0, ["z"] = 3, ["name"] = "cloud_items:decorative_cloud"}, {["x"] = 7, ["y"] = 0, ["z"] = 4, ["name"] = "cloud_items:decorative_cloud"}, {["x"] = 7, ["y"] = 0, ["z"] = 5, ["name"] = "cloud_items:decorative_cloud"}, {["x"] = 7, ["y"] = 0, ["z"] = 6, ["name"] = "cloud_items:decorative_cloud"}, {["x"] = 7, ["y"] = 0, ["z"] = 7, ["name"] = "cloud_items:decorative_cloud"}, {["x"] = 7, ["y"] = 0, ["z"] = 8, ["name"] = "cloud_items:decorative_cloud"}, {["x"] = 7, ["y"] = 0, ["z"] = 9, ["name"] = "cloud_items:decorative_cloud"}, {["x"] = 7, ["y"] = 0, ["z"] = 10, ["name"] = "cloud_items:decorative_cloud"}, {["x"] = 7, ["y"] = 0, ["z"] = 11, ["name"] = "cloud_items:decorative_cloud"}, {["x"] = 7, ["y"] = 0, ["z"] = 12, ["name"] = "cloud_items:decorative_cloud"}, {["x"] = 7, ["y"] = 0, ["z"] = 13, ["name"] = "cloud_items:decorative_cloud"}, {["x"] = 7, ["y"] = 0, ["z"] = 14, ["name"] = "cloud_items:decorative_cloud"}, {["x"] = 7, ["y"] = 0, ["z"] = 15, ["name"] = "cloud_items:decorative_cloud"}, {["x"] = 7, ["y"] = 1, ["z"] = 3, ["name"] = "cloud_items:decorative_cloud"}, {["x"] = 7, ["param2"] = 2, ["y"] = 1, ["param1"] = 188, ["z"] = 4, ["name"] = "stairs:stair_goldblock"}, {["x"] = 7, ["param2"] = 2, ["y"] = 2, ["param1"] = 158, ["z"] = 3, ["name"] = "xpanes:pane_flat"}, {["x"] = 7, ["param2"] = 2, ["y"] = 3, ["param1"] = 142, ["z"] = 3, ["name"] = "xpanes:pane_flat"}, {["x"] = 7, ["param2"] = 2, ["y"] = 4, ["param1"] = 126, ["z"] = 3, ["name"] = "xpanes:pane_flat"}, {["x"] = 7, ["y"] = 4, ["z"] = 12, ["name"] = "cloud_items:decorative_cloud"}, {["x"] = 7, ["y"] = 5, ["z"] = 3, ["name"] = "cloud_items:decorative_cloud"}, {["x"] = 7, ["y"] = 5, ["z"] = 12, ["name"] = "cloud_items:decorative_cloud"}, {["x"] = 7, ["y"] = 6, ["z"] = 3, ["name"] = "cloud_items:decorative_cloud"}, {["x"] = 7, ["y"] = 6, ["z"] = 4, ["name"] = "cloud_items:decorative_cloud"}, {["x"] = 7, ["y"] = 6, ["z"] = 5, ["name"] = "cloud_items:decorative_cloud"}, {["x"] = 7, ["y"] = 6, ["z"] = 6, ["name"] = "cloud_items:decorative_cloud"}, {["x"] = 7, ["y"] = 6, ["z"] = 7, ["name"] = "cloud_items:decorative_cloud"}, {["x"] = 7, ["y"] = 6, ["z"] = 8, ["name"] = "cloud_items:decorative_cloud"}, {["x"] = 7, ["y"] = 6, ["z"] = 9, ["name"] = "cloud_items:decorative_cloud"}, {["x"] = 7, ["y"] = 6, ["z"] = 10, ["name"] = "cloud_items:decorative_cloud"}, {["x"] = 7, ["y"] = 6, ["z"] = 11, ["name"] = "cloud_items:decorative_cloud"}, {["x"] = 7, ["y"] = 6, ["z"] = 12, ["name"] = "cloud_items:decorative_cloud"}, {["x"] = 7, ["y"] = 7, ["z"] = 3, ["name"] = "cloud_items:decorative_cloud"}, {["x"] = 7, ["y"] = 7, ["z"] = 12, ["name"] = "cloud_items:decorative_cloud"}, {["x"] = 7, ["y"] = 8, ["z"] = 3, ["name"] = "cloud_items:decorative_cloud"}, {["x"] = 7, ["y"] = 8, ["param1"] = 110, ["z"] = 12, ["name"] = "xpanes:pane_flat"}, {["x"] = 7, ["y"] = 9, ["z"] = 3, ["name"] = "cloud_items:decorative_cloud"}, {["x"] = 7, ["y"] = 9, ["param1"] = 126, ["z"] = 12, ["name"] = "xpanes:pane_flat"}, {["x"] = 7, ["y"] = 10, ["z"] = 3, ["name"] = "cloud_items:decorative_cloud"}, {["x"] = 7, ["param2"] = 2, ["y"] = 10, ["param1"] = 142, ["z"] = 12, ["name"] = "xpanes:pane_flat"}, {["x"] = 7, ["y"] = 11, ["z"] = 3, ["name"] = "cloud_items:decorative_cloud"}, {["x"] = 7, ["y"] = 11, ["z"] = 12, ["name"] = "cloud_items:decorative_cloud"}, {["x"] = 7, ["y"] = 12, ["z"] = 3, ["name"] = "cloud_items:decorative_cloud"}, {["x"] = 7, ["y"] = 12, ["z"] = 4, ["name"] = "cloud_items:decorative_cloud"}, {["x"] = 7, ["y"] = 12, ["z"] = 5, ["name"] = "cloud_items:decorative_cloud"}, {["x"] = 7, ["y"] = 12, ["z"] = 6, ["name"] = "cloud_items:decorative_cloud"}, {["x"] = 7, ["y"] = 12, ["z"] = 7, ["name"] = "cloud_items:decorative_cloud"}, {["x"] = 7, ["y"] = 12, ["z"] = 8, ["name"] = "cloud_items:decorative_cloud"}, {["x"] = 7, ["y"] = 12, ["z"] = 9, ["name"] = "cloud_items:decorative_cloud"}, {["x"] = 7, ["y"] = 12, ["z"] = 10, ["name"] = "cloud_items:decorative_cloud"}, {["x"] = 7, ["y"] = 12, ["z"] = 11, ["name"] = "cloud_items:decorative_cloud"}, {["x"] = 7, ["y"] = 12, ["z"] = 12, ["name"] = "cloud_items:decorative_cloud"}, {["x"] = 8, ["y"] = 0, ["z"] = 0, ["name"] = "cloud_items:decorative_cloud"}, {["x"] = 8, ["y"] = 0, ["z"] = 1, ["name"] = "cloud_items:decorative_cloud"}, {["x"] = 8, ["y"] = 0, ["z"] = 2, ["name"] = "cloud_items:decorative_cloud"}, {["x"] = 8, ["y"] = 0, ["z"] = 3, ["name"] = "cloud_items:decorative_cloud"}, {["x"] = 8, ["y"] = 0, ["z"] = 4, ["name"] = "cloud_items:decorative_cloud"}, {["x"] = 8, ["y"] = 0, ["z"] = 5, ["name"] = "cloud_items:decorative_cloud"}, {["x"] = 8, ["y"] = 0, ["z"] = 6, ["name"] = "cloud_items:decorative_cloud"}, {["x"] = 8, ["y"] = 0, ["z"] = 7, ["name"] = "cloud_items:decorative_cloud"}, {["x"] = 8, ["y"] = 0, ["z"] = 8, ["name"] = "cloud_items:decorative_cloud"}, {["x"] = 8, ["y"] = 0, ["z"] = 9, ["name"] = "cloud_items:decorative_cloud"}, {["x"] = 8, ["y"] = 0, ["z"] = 10, ["name"] = "cloud_items:decorative_cloud"}, {["x"] = 8, ["y"] = 0, ["z"] = 11, ["name"] = "cloud_items:decorative_cloud"}, {["x"] = 8, ["y"] = 0, ["z"] = 12, ["name"] = "cloud_items:decorative_cloud"}, {["x"] = 8, ["y"] = 0, ["z"] = 13, ["name"] = "cloud_items:decorative_cloud"}, {["x"] = 8, ["y"] = 0, ["z"] = 14, ["name"] = "cloud_items:decorative_cloud"}, {["x"] = 8, ["y"] = 0, ["z"] = 15, ["name"] = "cloud_items:decorative_cloud"}, {["x"] = 8, ["y"] = 1, ["z"] = 3, ["name"] = "cloud_items:decorative_cloud"}, {["x"] = 8, ["param2"] = 2, ["y"] = 1, ["param1"] = 172, ["z"] = 4, ["name"] = "stairs:stair_goldblock"}, {["x"] = 8, ["y"] = 2, ["param1"] = 142, ["z"] = 3, ["name"] = "xpanes:pane_flat"}, {["x"] = 8, ["y"] = 3, ["param1"] = 126, ["z"] = 3, ["name"] = "xpanes:pane_flat"}, {["x"] = 8, ["y"] = 4, ["param1"] = 110, ["z"] = 3, ["name"] = "xpanes:pane_flat"}, {["x"] = 8, ["y"] = 5, ["z"] = 3, ["name"] = "cloud_items:decorative_cloud"}, {["x"] = 8, ["y"] = 5, ["z"] = 12, ["name"] = "cloud_items:decorative_cloud"}, {["x"] = 8, ["y"] = 6, ["z"] = 3, ["name"] = "cloud_items:decorative_cloud"}, {["x"] = 8, ["y"] = 6, ["z"] = 4, ["name"] = "cloud_items:decorative_cloud"}, {["x"] = 8, ["y"] = 6, ["z"] = 5, ["name"] = "cloud_items:decorative_cloud"}, {["x"] = 8, ["y"] = 6, ["z"] = 6, ["name"] = "cloud_items:decorative_cloud"}, {["x"] = 8, ["y"] = 6, ["z"] = 7, ["name"] = "cloud_items:decorative_cloud"}, {["x"] = 8, ["y"] = 6, ["z"] = 8, ["name"] = "cloud_items:decorative_cloud"}, {["x"] = 8, ["y"] = 6, ["z"] = 9, ["name"] = "cloud_items:decorative_cloud"}, {["x"] = 8, ["y"] = 6, ["z"] = 10, ["name"] = "cloud_items:decorative_cloud"}, {["x"] = 8, ["y"] = 6, ["z"] = 11, ["name"] = "cloud_items:decorative_cloud"}, {["x"] = 8, ["y"] = 6, ["z"] = 12, ["name"] = "cloud_items:decorative_cloud"}, {["x"] = 8, ["y"] = 7, ["z"] = 3, ["name"] = "cloud_items:decorative_cloud"}, {["x"] = 8, ["param2"] = 2, ["y"] = 7, ["param1"] = 70, ["z"] = 5, ["name"] = "beds:fancy_bed_top"}, {["x"] = 8, ["param2"] = 2, ["y"] = 7, ["param1"] = 71, ["z"] = 6, ["name"] = "beds:fancy_bed_bottom"}, {["x"] = 8, ["meta"] = {["fields"] = {["infotext"] = "\27(T@default)Chest\27E"}, ["inventory"] = {["main"] = {"cloud_items:cloudblock", "cloud_items:decoration_block", "", "", "", "", "", "", "", "", "", "", "", "", "", "", "", "", "", "", "", "", "", "", "", "", "", "", "", "", "", ""}}}, ["y"] = 7, ["param1"] = 156, ["z"] = 11, ["name"] = "default:chest"}, {["x"] = 8, ["y"] = 7, ["z"] = 12, ["name"] = "cloud_items:decorative_cloud"}, {["x"] = 8, ["y"] = 8, ["z"] = 3, ["name"] = "cloud_items:decorative_cloud"}, {["x"] = 8, ["y"] = 8, ["param1"] = 126, ["z"] = 12, ["name"] = "xpanes:pane_flat"}, {["x"] = 8, ["y"] = 9, ["z"] = 3, ["name"] = "cloud_items:decorative_cloud"}, {["x"] = 8, ["y"] = 9, ["param1"] = 110, ["z"] = 12, ["name"] = "xpanes:pane_flat"}, {["x"] = 8, ["y"] = 10, ["z"] = 3, ["name"] = "cloud_items:decorative_cloud"}, {["x"] = 8, ["y"] = 10, ["param1"] = 126, ["z"] = 12, ["name"] = "xpanes:pane_flat"}, {["x"] = 8, ["y"] = 11, ["z"] = 3, ["name"] = "cloud_items:decorative_cloud"}, {["x"] = 8, ["y"] = 11, ["z"] = 12, ["name"] = "cloud_items:decorative_cloud"}, {["x"] = 8, ["y"] = 12, ["z"] = 3, ["name"] = "cloud_items:decorative_cloud"}, {["x"] = 8, ["y"] = 12, ["z"] = 4, ["name"] = "cloud_items:decorative_cloud"}, {["x"] = 8, ["y"] = 12, ["z"] = 5, ["name"] = "cloud_items:decorative_cloud"}, {["x"] = 8, ["y"] = 12, ["z"] = 6, ["name"] = "cloud_items:decorative_cloud"}, {["x"] = 8, ["y"] = 12, ["z"] = 7, ["name"] = "cloud_items:decorative_cloud"}, {["x"] = 8, ["y"] = 12, ["z"] = 8, ["name"] = "cloud_items:decorative_cloud"}, {["x"] = 8, ["y"] = 12, ["z"] = 9, ["name"] = "cloud_items:decorative_cloud"}, {["x"] = 8, ["y"] = 12, ["z"] = 10, ["name"] = "cloud_items:decorative_cloud"}, {["x"] = 8, ["y"] = 12, ["z"] = 11, ["name"] = "cloud_items:decorative_cloud"}, {["x"] = 8, ["y"] = 12, ["z"] = 12, ["name"] = "cloud_items:decorative_cloud"}, {["x"] = 9, ["y"] = 0, ["z"] = 0, ["name"] = "cloud_items:decorative_cloud"}, {["x"] = 9, ["y"] = 0, ["z"] = 1, ["name"] = "cloud_items:decorative_cloud"}, {["x"] = 9, ["y"] = 0, ["z"] = 2, ["name"] = "cloud_items:decorative_cloud"}, {["x"] = 9, ["y"] = 0, ["z"] = 3, ["name"] = "cloud_items:decorative_cloud"}, {["x"] = 9, ["y"] = 0, ["z"] = 4, ["name"] = "cloud_items:decorative_cloud"}, {["x"] = 9, ["y"] = 0, ["z"] = 5, ["name"] = "cloud_items:decorative_cloud"}, {["x"] = 9, ["y"] = 0, ["z"] = 6, ["name"] = "cloud_items:decorative_cloud"}, {["x"] = 9, ["y"] = 0, ["z"] = 7, ["name"] = "cloud_items:decorative_cloud"}, {["x"] = 9, ["y"] = 0, ["z"] = 8, ["name"] = "cloud_items:decorative_cloud"}, {["x"] = 9, ["y"] = 0, ["z"] = 9, ["name"] = "cloud_items:decorative_cloud"}, {["x"] = 9, ["y"] = 0, ["z"] = 10, ["name"] = "cloud_items:decorative_cloud"}, {["x"] = 9, ["y"] = 0, ["z"] = 11, ["name"] = "cloud_items:decorative_cloud"}, {["x"] = 9, ["y"] = 0, ["z"] = 12, ["name"] = "cloud_items:decorative_cloud"}, {["x"] = 9, ["y"] = 0, ["z"] = 13, ["name"] = "cloud_items:decorative_cloud"}, {["x"] = 9, ["y"] = 0, ["z"] = 14, ["name"] = "cloud_items:decorative_cloud"}, {["x"] = 9, ["y"] = 0, ["z"] = 15, ["name"] = "cloud_items:decorative_cloud"}, {["x"] = 9, ["y"] = 1, ["z"] = 3, ["name"] = "cloud_items:decorative_cloud"}, {["x"] = 9, ["param2"] = 2, ["y"] = 1, ["param1"] = 172, ["z"] = 4, ["name"] = "stairs:stair_goldblock"}, {["x"] = 9, ["y"] = 2, ["param1"] = 142, ["z"] = 3, ["name"] = "xpanes:pane_flat"}, {["x"] = 9, ["y"] = 3, ["param1"] = 126, ["z"] = 3, ["name"] = "xpanes:pane_flat"}, {["x"] = 9, ["y"] = 4, ["param1"] = 110, ["z"] = 3, ["name"] = "xpanes:pane_flat"}, {["x"] = 9, ["y"] = 5, ["z"] = 3, ["name"] = "cloud_items:decorative_cloud"}, {["x"] = 9, ["y"] = 5, ["z"] = 12, ["name"] = "cloud_items:decorative_cloud"}, {["x"] = 9, ["y"] = 6, ["z"] = 3, ["name"] = "cloud_items:decorative_cloud"}, {["x"] = 9, ["y"] = 6, ["z"] = 4, ["name"] = "cloud_items:decorative_cloud"}, {["x"] = 9, ["y"] = 6, ["z"] = 5, ["name"] = "cloud_items:decorative_cloud"}, {["x"] = 9, ["y"] = 6, ["z"] = 6, ["name"] = "cloud_items:decorative_cloud"}, {["x"] = 9, ["y"] = 6, ["z"] = 7, ["name"] = "cloud_items:decorative_cloud"}, {["x"] = 9, ["y"] = 6, ["z"] = 8, ["name"] = "cloud_items:decorative_cloud"}, {["x"] = 9, ["y"] = 6, ["z"] = 9, ["name"] = "cloud_items:decorative_cloud"}, {["x"] = 9, ["y"] = 6, ["z"] = 10, ["name"] = "cloud_items:decorative_cloud"}, {["x"] = 9, ["y"] = 6, ["z"] = 11, ["name"] = "cloud_items:decorative_cloud"}, {["x"] = 9, ["y"] = 6, ["z"] = 12, ["name"] = "cloud_items:decorative_cloud"}, {["x"] = 9, ["y"] = 7, ["z"] = 3, ["name"] = "cloud_items:decorative_cloud"}, {["x"] = 9, ["param2"] = 2, ["y"] = 7, ["param1"] = 70, ["z"] = 5, ["name"] = "beds:fancy_bed_top"}, {["x"] = 9, ["param2"] = 2, ["y"] = 7, ["param1"] = 87, ["z"] = 6, ["name"] = "beds:fancy_bed_bottom"}, {["x"] = 9, ["meta"] = {["fields"] = {["infotext"] = "\27(T@default)Chest\27E"}, ["inventory"] = {["main"] = {"cloud_items:cloud_lump 25", "", "", "", "", "", "", "", "", "", "", "", "", "", "", "", "", "", "", "", "", "", "", "", "", "", "", "", "", "", "", ""}}}, ["y"] = 7, ["param1"] = 172, ["z"] = 11, ["name"] = "default:chest"}, {["x"] = 9, ["y"] = 7, ["z"] = 12, ["name"] = "cloud_items:decorative_cloud"}, {["x"] = 9, ["y"] = 8, ["z"] = 3, ["name"] = "cloud_items:decorative_cloud"}, {["x"] = 9, ["y"] = 8, ["param1"] = 142, ["z"] = 12, ["name"] = "xpanes:pane_flat"}, {["x"] = 9, ["y"] = 9, ["z"] = 3, ["name"] = "cloud_items:decorative_cloud"}, {["x"] = 9, ["y"] = 9, ["param1"] = 126, ["z"] = 12, ["name"] = "xpanes:pane_flat"}, {["x"] = 9, ["y"] = 10, ["z"] = 3, ["name"] = "cloud_items:decorative_cloud"}, {["x"] = 9, ["y"] = 10, ["param1"] = 126, ["z"] = 12, ["name"] = "xpanes:pane_flat"}, {["x"] = 9, ["y"] = 11, ["z"] = 3, ["name"] = "cloud_items:decorative_cloud"}, {["x"] = 9, ["y"] = 11, ["z"] = 12, ["name"] = "cloud_items:decorative_cloud"}, {["x"] = 9, ["y"] = 12, ["z"] = 3, ["name"] = "cloud_items:decorative_cloud"}, {["x"] = 9, ["y"] = 12, ["z"] = 4, ["name"] = "cloud_items:decorative_cloud"}, {["x"] = 9, ["y"] = 12, ["z"] = 5, ["name"] = "cloud_items:decorative_cloud"}, {["x"] = 9, ["y"] = 12, ["z"] = 6, ["name"] = "cloud_items:decorative_cloud"}, {["x"] = 9, ["y"] = 12, ["z"] = 7, ["name"] = "cloud_items:decorative_cloud"}, {["x"] = 9, ["y"] = 12, ["z"] = 8, ["name"] = "cloud_items:decorative_cloud"}, {["x"] = 9, ["y"] = 12, ["z"] = 9, ["name"] = "cloud_items:decorative_cloud"}, {["x"] = 9, ["y"] = 12, ["z"] = 10, ["name"] = "cloud_items:decorative_cloud"}, {["x"] = 9, ["y"] = 12, ["z"] = 11, ["name"] = "cloud_items:decorative_cloud"}, {["x"] = 9, ["y"] = 12, ["z"] = 12, ["name"] = "cloud_items:decorative_cloud"}, {["x"] = 10, ["y"] = 0, ["z"] = 0, ["name"] = "cloud_items:decorative_cloud"}, {["x"] = 10, ["y"] = 0, ["z"] = 1, ["name"] = "cloud_items:decorative_cloud"}, {["x"] = 10, ["y"] = 0, ["z"] = 2, ["name"] = "cloud_items:decorative_cloud"}, {["x"] = 10, ["y"] = 0, ["z"] = 3, ["name"] = "cloud_items:decorative_cloud"}, {["x"] = 10, ["y"] = 0, ["z"] = 4, ["name"] = "cloud_items:decorative_cloud"}, {["x"] = 10, ["y"] = 0, ["z"] = 5, ["name"] = "cloud_items:decorative_cloud"}, {["x"] = 10, ["y"] = 0, ["z"] = 6, ["name"] = "cloud_items:decorative_cloud"}, {["x"] = 10, ["y"] = 0, ["z"] = 7, ["name"] = "cloud_items:decorative_cloud"}, {["x"] = 10, ["y"] = 0, ["z"] = 8, ["name"] = "cloud_items:decorative_cloud"}, {["x"] = 10, ["y"] = 0, ["z"] = 9, ["name"] = "cloud_items:decorative_cloud"}, {["x"] = 10, ["y"] = 0, ["z"] = 10, ["name"] = "cloud_items:decorative_cloud"}, {["x"] = 10, ["y"] = 0, ["z"] = 11, ["name"] = "cloud_items:decorative_cloud"}, {["x"] = 10, ["y"] = 0, ["z"] = 12, ["name"] = "cloud_items:decorative_cloud"}, {["x"] = 10, ["y"] = 0, ["z"] = 13, ["name"] = "cloud_items:decorative_cloud"}, {["x"] = 10, ["y"] = 0, ["z"] = 14, ["name"] = "cloud_items:decorative_cloud"}, {["x"] = 10, ["y"] = 0, ["z"] = 15, ["name"] = "cloud_items:decorative_cloud"}, {["x"] = 10, ["y"] = 1, ["z"] = 3, ["name"] = "cloud_items:decorative_cloud"}, {["x"] = 10, ["param2"] = 2, ["y"] = 1, ["param1"] = 188, ["z"] = 4, ["name"] = "stairs:stair_goldblock"}, {["x"] = 10, ["y"] = 2, ["param1"] = 158, ["z"] = 3, ["name"] = "xpanes:pane_flat"}, {["x"] = 10, ["y"] = 3, ["param1"] = 142, ["z"] = 3, ["name"] = "xpanes:pane_flat"}, {["x"] = 10, ["y"] = 4, ["param1"] = 126, ["z"] = 3, ["name"] = "xpanes:pane_flat"}, {["x"] = 10, ["y"] = 4, ["z"] = 12, ["name"] = "cloud_items:decorative_cloud"}, {["x"] = 10, ["y"] = 5, ["z"] = 3, ["name"] = "cloud_items:decorative_cloud"}, {["x"] = 10, ["y"] = 5, ["z"] = 12, ["name"] = "cloud_items:decorative_cloud"}, {["x"] = 10, ["y"] = 6, ["z"] = 3, ["name"] = "cloud_items:decorative_cloud"}, {["x"] = 10, ["y"] = 6, ["z"] = 4, ["name"] = "cloud_items:decorative_cloud"}, {["x"] = 10, ["y"] = 6, ["z"] = 5, ["name"] = "cloud_items:decorative_cloud"}, {["x"] = 10, ["y"] = 6, ["z"] = 6, ["name"] = "cloud_items:decorative_cloud"}, {["x"] = 10, ["y"] = 6, ["z"] = 7, ["name"] = "cloud_items:decorative_cloud"}, {["x"] = 10, ["y"] = 6, ["z"] = 8, ["name"] = "cloud_items:decorative_cloud"}, {["x"] = 10, ["y"] = 6, ["z"] = 9, ["name"] = "cloud_items:decorative_cloud"}, {["x"] = 10, ["y"] = 6, ["z"] = 10, ["name"] = "cloud_items:decorative_cloud"}, {["x"] = 10, ["y"] = 6, ["z"] = 11, ["name"] = "cloud_items:decorative_cloud"}, {["x"] = 10, ["y"] = 6, ["z"] = 12, ["name"] = "cloud_items:decorative_cloud"}, {["x"] = 10, ["y"] = 7, ["z"] = 3, ["name"] = "cloud_items:decorative_cloud"}, {["x"] = 10, ["y"] = 7, ["z"] = 12, ["name"] = "cloud_items:decorative_cloud"}, {["x"] = 10, ["y"] = 8, ["z"] = 3, ["name"] = "cloud_items:decorative_cloud"}, {["x"] = 10, ["y"] = 8, ["param1"] = 158, ["z"] = 12, ["name"] = "xpanes:pane_flat"}, {["x"] = 10, ["y"] = 9, ["z"] = 3, ["name"] = "cloud_items:decorative_cloud"}, {["x"] = 10, ["y"] = 9, ["param1"] = 142, ["z"] = 12, ["name"] = "xpanes:pane_flat"}, {["x"] = 10, ["y"] = 10, ["z"] = 3, ["name"] = "cloud_items:decorative_cloud"}, {["x"] = 10, ["y"] = 10, ["param1"] = 142, ["z"] = 12, ["name"] = "xpanes:pane_flat"}, {["x"] = 10, ["y"] = 11, ["z"] = 3, ["name"] = "cloud_items:decorative_cloud"}, {["x"] = 10, ["y"] = 11, ["z"] = 12, ["name"] = "cloud_items:decorative_cloud"}, {["x"] = 10, ["y"] = 12, ["z"] = 3, ["name"] = "cloud_items:decorative_cloud"}, {["x"] = 10, ["y"] = 12, ["z"] = 4, ["name"] = "cloud_items:decorative_cloud"}, {["x"] = 10, ["y"] = 12, ["z"] = 5, ["name"] = "cloud_items:decorative_cloud"}, {["x"] = 10, ["y"] = 12, ["z"] = 6, ["name"] = "cloud_items:decorative_cloud"}, {["x"] = 10, ["y"] = 12, ["z"] = 7, ["name"] = "cloud_items:decorative_cloud"}, {["x"] = 10, ["y"] = 12, ["z"] = 8, ["name"] = "cloud_items:decorative_cloud"}, {["x"] = 10, ["y"] = 12, ["z"] = 9, ["name"] = "cloud_items:decorative_cloud"}, {["x"] = 10, ["y"] = 12, ["z"] = 10, ["name"] = "cloud_items:decorative_cloud"}, {["x"] = 10, ["y"] = 12, ["z"] = 11, ["name"] = "cloud_items:decorative_cloud"}, {["x"] = 10, ["y"] = 12, ["z"] = 12, ["name"] = "cloud_items:decorative_cloud"}, {["x"] = 11, ["y"] = 0, ["z"] = 0, ["name"] = "cloud_items:decorative_cloud"}, {["x"] = 11, ["y"] = 0, ["z"] = 1, ["name"] = "cloud_items:decorative_cloud"}, {["x"] = 11, ["y"] = 0, ["z"] = 2, ["name"] = "cloud_items:decorative_cloud"}, {["x"] = 11, ["y"] = 0, ["z"] = 3, ["name"] = "cloud_items:decorative_cloud"}, {["x"] = 11, ["y"] = 0, ["z"] = 4, ["name"] = "cloud_items:decorative_cloud"}, {["x"] = 11, ["y"] = 0, ["z"] = 5, ["name"] = "cloud_items:decorative_cloud"}, {["x"] = 11, ["y"] = 0, ["z"] = 6, ["name"] = "cloud_items:decorative_cloud"}, {["x"] = 11, ["y"] = 0, ["z"] = 7, ["name"] = "cloud_items:decorative_cloud"}, {["x"] = 11, ["y"] = 0, ["z"] = 8, ["name"] = "cloud_items:decorative_cloud"}, {["x"] = 11, ["y"] = 0, ["z"] = 9, ["name"] = "cloud_items:decorative_cloud"}, {["x"] = 11, ["y"] = 0, ["z"] = 10, ["name"] = "cloud_items:decorative_cloud"}, {["x"] = 11, ["y"] = 0, ["z"] = 11, ["name"] = "cloud_items:decorative_cloud"}, {["x"] = 11, ["y"] = 0, ["z"] = 12, ["name"] = "cloud_items:decorative_cloud"}, {["x"] = 11, ["y"] = 0, ["z"] = 13, ["name"] = "cloud_items:decorative_cloud"}, {["x"] = 11, ["y"] = 0, ["z"] = 14, ["name"] = "cloud_items:decorative_cloud"}, {["x"] = 11, ["y"] = 0, ["z"] = 15, ["name"] = "cloud_items:decorative_cloud"}, {["x"] = 11, ["y"] = 1, ["z"] = 3, ["name"] = "cloud_items:decorative_cloud"}, {["x"] = 11, ["y"] = 1, ["z"] = 12, ["name"] = "cloud_items:decorative_cloud"}, {["x"] = 11, ["y"] = 2, ["z"] = 3, ["name"] = "cloud_items:decorative_cloud"}, {["x"] = 11, ["y"] = 2, ["z"] = 12, ["name"] = "cloud_items:decorative_cloud"}, {["x"] = 11, ["y"] = 3, ["z"] = 3, ["name"] = "cloud_items:decorative_cloud"}, {["x"] = 11, ["y"] = 3, ["z"] = 12, ["name"] = "cloud_items:decorative_cloud"}, {["x"] = 11, ["y"] = 4, ["z"] = 3, ["name"] = "cloud_items:decorative_cloud"}, {["x"] = 11, ["y"] = 4, ["z"] = 12, ["name"] = "cloud_items:decorative_cloud"}, {["x"] = 11, ["y"] = 5, ["z"] = 3, ["name"] = "cloud_items:decorative_cloud"}, {["x"] = 11, ["y"] = 5, ["z"] = 12, ["name"] = "cloud_items:decorative_cloud"}, {["x"] = 11, ["y"] = 6, ["z"] = 3, ["name"] = "cloud_items:decorative_cloud"}, {["x"] = 11, ["y"] = 6, ["z"] = 4, ["name"] = "cloud_items:decorative_cloud"}, {["x"] = 11, ["y"] = 6, ["z"] = 5, ["name"] = "cloud_items:decorative_cloud"}, {["x"] = 11, ["y"] = 6, ["z"] = 6, ["name"] = "cloud_items:decorative_cloud"}, {["x"] = 11, ["y"] = 6, ["z"] = 7, ["name"] = "cloud_items:decorative_cloud"}, {["x"] = 11, ["y"] = 6, ["z"] = 8, ["name"] = "cloud_items:decorative_cloud"}, {["x"] = 11, ["y"] = 6, ["z"] = 9, ["name"] = "cloud_items:decorative_cloud"}, {["x"] = 11, ["y"] = 6, ["z"] = 10, ["name"] = "cloud_items:decorative_cloud"}, {["x"] = 11, ["y"] = 6, ["z"] = 11, ["name"] = "cloud_items:decorative_cloud"}, {["x"] = 11, ["y"] = 6, ["z"] = 12, ["name"] = "cloud_items:decorative_cloud"}, {["x"] = 11, ["y"] = 7, ["z"] = 3, ["name"] = "cloud_items:decorative_cloud"}, {["x"] = 11, ["meta"] = {["fields"] = {["infotext"] = "\27(T@default)Chest\27E"}, ["inventory"] = {["main"] = {"cloud_items:cloud_shovel", "cloud_items:cloud_axe", "default:axe_mese", "default:pick_mese", "default:shovel_mese", "default:sword_mese", "farming:hoe_mese", "", "", "", "", "", "", "", "", "", "", "", "", "", "", "", "", "", "", "", "", "", "", "", "", ""}}}, ["param2"] = 2, ["y"] = 7, ["param1"] = 119, ["z"] = 4, ["name"] = "default:chest"}, {["x"] = 11, ["y"] = 7, ["z"] = 12, ["name"] = "cloud_items:decorative_cloud"}, {["x"] = 11, ["y"] = 8, ["z"] = 3, ["name"] = "cloud_items:decorative_cloud"}, {["x"] = 11, ["y"] = 8, ["param1"] = 174, ["z"] = 12, ["name"] = "xpanes:pane_flat"}, {["x"] = 11, ["y"] = 9, ["z"] = 3, ["name"] = "cloud_items:decorative_cloud"}, {["x"] = 11, ["y"] = 9, ["param1"] = 158, ["z"] = 12, ["name"] = "xpanes:pane_flat"}, {["x"] = 11, ["y"] = 10, ["z"] = 3, ["name"] = "cloud_items:decorative_cloud"}, {["x"] = 11, ["y"] = 10, ["z"] = 12, ["name"] = "cloud_items:decorative_cloud"}, {["x"] = 11, ["y"] = 11, ["z"] = 3, ["name"] = "cloud_items:decorative_cloud"}, {["x"] = 11, ["y"] = 11, ["z"] = 12, ["name"] = "cloud_items:decorative_cloud"}, {["x"] = 11, ["y"] = 12, ["z"] = 3, ["name"] = "cloud_items:decorative_cloud"}, {["x"] = 11, ["y"] = 12, ["z"] = 4, ["name"] = "cloud_items:decorative_cloud"}, {["x"] = 11, ["y"] = 12, ["z"] = 5, ["name"] = "cloud_items:decorative_cloud"}, {["x"] = 11, ["y"] = 12, ["z"] = 6, ["name"] = "cloud_items:decorative_cloud"}, {["x"] = 11, ["y"] = 12, ["z"] = 7, ["name"] = "cloud_items:decorative_cloud"}, {["x"] = 11, ["y"] = 12, ["z"] = 8, ["name"] = "cloud_items:decorative_cloud"}, {["x"] = 11, ["y"] = 12, ["z"] = 9, ["name"] = "cloud_items:decorative_cloud"}, {["x"] = 11, ["y"] = 12, ["z"] = 10, ["name"] = "cloud_items:decorative_cloud"}, {["x"] = 11, ["y"] = 12, ["z"] = 11, ["name"] = "cloud_items:decorative_cloud"}, {["x"] = 11, ["y"] = 12, ["z"] = 12, ["name"] = "cloud_items:decorative_cloud"}, {["x"] = 12, ["y"] = 0, ["z"] = 0, ["name"] = "cloud_items:decorative_cloud"}, {["x"] = 12, ["y"] = 0, ["z"] = 1, ["name"] = "cloud_items:decorative_cloud"}, {["x"] = 12, ["y"] = 0, ["z"] = 2, ["name"] = "cloud_items:decorative_cloud"}, {["x"] = 12, ["y"] = 0, ["z"] = 3, ["name"] = "cloud_items:decorative_cloud"}, {["x"] = 12, ["y"] = 0, ["z"] = 4, ["name"] = "cloud_items:decorative_cloud"}, {["x"] = 12, ["y"] = 0, ["z"] = 5, ["name"] = "cloud_items:decorative_cloud"}, {["x"] = 12, ["y"] = 0, ["z"] = 6, ["name"] = "cloud_items:decorative_cloud"}, {["x"] = 12, ["y"] = 0, ["z"] = 7, ["name"] = "cloud_items:decorative_cloud"}, {["x"] = 12, ["y"] = 0, ["z"] = 8, ["name"] = "cloud_items:decorative_cloud"}, {["x"] = 12, ["y"] = 0, ["z"] = 9, ["name"] = "cloud_items:decorative_cloud"}, {["x"] = 12, ["y"] = 0, ["z"] = 10, ["name"] = "cloud_items:decorative_cloud"}, {["x"] = 12, ["y"] = 0, ["z"] = 11, ["name"] = "cloud_items:decorative_cloud"}, {["x"] = 12, ["y"] = 0, ["z"] = 12, ["name"] = "cloud_items:decorative_cloud"}, {["x"] = 12, ["y"] = 0, ["z"] = 13, ["name"] = "cloud_items:decorative_cloud"}, {["x"] = 12, ["y"] = 0, ["z"] = 14, ["name"] = "cloud_items:decorative_cloud"}, {["x"] = 12, ["y"] = 0, ["z"] = 15, ["name"] = "cloud_items:decorative_cloud"}, {["x"] = 12, ["y"] = 1, ["z"] = 3, ["name"] = "cloud_items:decorative_cloud"}, {["x"] = 12, ["meta"] = {["fields"] = {["infotext"] = "\27(T@default)Bookshelf (\27F1\27E written, \27F0\27E empty books)\27E", ["formspec"] = "size[8,7;]list[context;books;0,0.3;8,2;]list[current_player;main;0,2.85;8,1;]list[current_player;main;0,4.08;8,3;8]listring[context;books]listring[current_player;main]image[0,2.85;1,1;gui_hb_bg.png]image[1,2.85;1,1;gui_hb_bg.png]image[2,2.85;1,1;gui_hb_bg.png]image[3,2.85;1,1;gui_hb_bg.png]image[4,2.85;1,1;gui_hb_bg.png]image[5,2.85;1,1;gui_hb_bg.png]image[6,2.85;1,1;gui_hb_bg.png]image[7,2.85;1,1;gui_hb_bg.png]image[1,0.3;1,1;default_bookshelf_slot.png]image[2,0.3;1,1;default_bookshelf_slot.png]image[3,0.3;1,1;default_bookshelf_slot.png]image[4,0.3;1,1;default_bookshelf_slot.png]image[5,0.3;1,1;default_bookshelf_slot.png]image[6,0.3;1,1;default_bookshelf_slot.png]image[7,0.3;1,1;default_bookshelf_slot.png]image[0,1.3;1,1;default_bookshelf_slot.png]image[1,1.3;1,1;default_bookshelf_slot.png]image[2,1.3;1,1;default_bookshelf_slot.png]image[3,1.3;1,1;default_bookshelf_slot.png]image[4,1.3;1,1;default_bookshelf_slot.png]image[5,1.3;1,1;default_bookshelf_slot.png]image[6,1.3;1,1;default_bookshelf_slot.png]image[7,1.3;1,1;default_bookshelf_slot.png]"}, ["inventory"] = {["books"] = {"default:book_written 1 0 \"\\u0001title\\u0002Para ti \\u0003owner\\u0002singleplayer\\u0003page_max\\u00021\\u0003page\\u00021\\u0003text\\u0002\\u00c2\\u00a1Hola amig@! :)\\u0003description\\u0002\\u001b(T@default)\\\"\\u001bFPara ti \\u001bE\\\" by \\u001bFsingleplayer\\u001bE\\u001bE\\u0003\"", "", "", "", "", "", "", "", "", "", "", "", "", "", "", ""}}}, ["y"] = 1, ["z"] = 11, ["name"] = "default:bookshelf"}, {["x"] = 12, ["y"] = 1, ["z"] = 12, ["name"] = "cloud_items:decorative_cloud"}, {["x"] = 12, ["param2"] = 1, ["y"] = 1, ["param1"] = 158, ["z"] = 13, ["name"] = "stairs:stair_decorative_cloud"}, {["x"] = 12, ["param2"] = 1, ["y"] = 1, ["param1"] = 174, ["z"] = 14, ["name"] = "stairs:stair_decorative_cloud"}, {["x"] = 12, ["y"] = 2, ["z"] = 3, ["name"] = "cloud_items:decorative_cloud"}, {["x"] = 12, ["meta"] = {["fields"] = {["infotext"] = "\27(T@default)Empty Bookshelf\27E", ["formspec"] = "size[8,7;]list[context;books;0,0.3;8,2;]list[current_player;main;0,2.85;8,1;]list[current_player;main;0,4.08;8,3;8]listring[context;books]listring[current_player;main]image[0,2.85;1,1;gui_hb_bg.png]image[1,2.85;1,1;gui_hb_bg.png]image[2,2.85;1,1;gui_hb_bg.png]image[3,2.85;1,1;gui_hb_bg.png]image[4,2.85;1,1;gui_hb_bg.png]image[5,2.85;1,1;gui_hb_bg.png]image[6,2.85;1,1;gui_hb_bg.png]image[7,2.85;1,1;gui_hb_bg.png]image[0,0.3;1,1;default_bookshelf_slot.png]image[1,0.3;1,1;default_bookshelf_slot.png]image[2,0.3;1,1;default_bookshelf_slot.png]image[3,0.3;1,1;default_bookshelf_slot.png]image[4,0.3;1,1;default_bookshelf_slot.png]image[5,0.3;1,1;default_bookshelf_slot.png]image[6,0.3;1,1;default_bookshelf_slot.png]image[7,0.3;1,1;default_bookshelf_slot.png]image[0,1.3;1,1;default_bookshelf_slot.png]image[1,1.3;1,1;default_bookshelf_slot.png]image[2,1.3;1,1;default_bookshelf_slot.png]image[3,1.3;1,1;default_bookshelf_slot.png]image[4,1.3;1,1;default_bookshelf_slot.png]image[5,1.3;1,1;default_bookshelf_slot.png]image[6,1.3;1,1;default_bookshelf_slot.png]image[7,1.3;1,1;default_bookshelf_slot.png]"}, ["inventory"] = {["books"] = {"", "", "", "", "", "", "", "", "", "", "", "", "", "", "", ""}}}, ["y"] = 2, ["z"] = 11, ["name"] = "default:bookshelf"}, {["x"] = 12, ["y"] = 2, ["z"] = 12, ["name"] = "cloud_items:decorative_cloud"}, {["x"] = 12, ["y"] = 3, ["z"] = 3, ["name"] = "cloud_items:decorative_cloud"}, {["x"] = 12, ["meta"] = {["fields"] = {["infotext"] = "\27(T@default)Empty Bookshelf\27E", ["formspec"] = "size[8,7;]list[context;books;0,0.3;8,2;]list[current_player;main;0,2.85;8,1;]list[current_player;main;0,4.08;8,3;8]listring[context;books]listring[current_player;main]image[0,2.85;1,1;gui_hb_bg.png]image[1,2.85;1,1;gui_hb_bg.png]image[2,2.85;1,1;gui_hb_bg.png]image[3,2.85;1,1;gui_hb_bg.png]image[4,2.85;1,1;gui_hb_bg.png]image[5,2.85;1,1;gui_hb_bg.png]image[6,2.85;1,1;gui_hb_bg.png]image[7,2.85;1,1;gui_hb_bg.png]image[0,0.3;1,1;default_bookshelf_slot.png]image[1,0.3;1,1;default_bookshelf_slot.png]image[2,0.3;1,1;default_bookshelf_slot.png]image[3,0.3;1,1;default_bookshelf_slot.png]image[4,0.3;1,1;default_bookshelf_slot.png]image[5,0.3;1,1;default_bookshelf_slot.png]image[6,0.3;1,1;default_bookshelf_slot.png]image[7,0.3;1,1;default_bookshelf_slot.png]image[0,1.3;1,1;default_bookshelf_slot.png]image[1,1.3;1,1;default_bookshelf_slot.png]image[2,1.3;1,1;default_bookshelf_slot.png]image[3,1.3;1,1;default_bookshelf_slot.png]image[4,1.3;1,1;default_bookshelf_slot.png]image[5,1.3;1,1;default_bookshelf_slot.png]image[6,1.3;1,1;default_bookshelf_slot.png]image[7,1.3;1,1;default_bookshelf_slot.png]"}, ["inventory"] = {["books"] = {"", "", "", "", "", "", "", "", "", "", "", "", "", "", "", ""}}}, ["y"] = 3, ["z"] = 11, ["name"] = "default:bookshelf"}, {["x"] = 12, ["y"] = 3, ["z"] = 12, ["name"] = "cloud_items:decorative_cloud"}, {["x"] = 12, ["y"] = 4, ["z"] = 3, ["name"] = "cloud_items:decorative_cloud"}, {["x"] = 12, ["y"] = 4, ["z"] = 12, ["name"] = "cloud_items:decorative_cloud"}, {["x"] = 12, ["y"] = 5, ["z"] = 3, ["name"] = "cloud_items:decorative_cloud"}, {["x"] = 12, ["y"] = 5, ["z"] = 12, ["name"] = "cloud_items:decorative_cloud"}, {["x"] = 12, ["y"] = 6, ["z"] = 3, ["name"] = "cloud_items:decorative_cloud"}, {["x"] = 12, ["y"] = 6, ["z"] = 4, ["name"] = "cloud_items:decorative_cloud"}, {["x"] = 12, ["y"] = 6, ["z"] = 5, ["name"] = "cloud_items:decorative_cloud"}, {["x"] = 12, ["y"] = 6, ["z"] = 6, ["name"] = "cloud_items:decorative_cloud"}, {["x"] = 12, ["y"] = 6, ["z"] = 7, ["name"] = "cloud_items:decorative_cloud"}, {["x"] = 12, ["y"] = 6, ["z"] = 8, ["name"] = "cloud_items:decorative_cloud"}, {["x"] = 12, ["y"] = 6, ["z"] = 9, ["name"] = "cloud_items:decorative_cloud"}, {["x"] = 12, ["y"] = 6, ["z"] = 10, ["name"] = "cloud_items:decorative_cloud"}, {["x"] = 12, ["y"] = 6, ["z"] = 11, ["name"] = "cloud_items:decorative_cloud"}, {["x"] = 12, ["y"] = 6, ["z"] = 12, ["name"] = "cloud_items:decorative_cloud"}, {["x"] = 12, ["y"] = 7, ["z"] = 3, ["name"] = "cloud_items:decorative_cloud"}, {["x"] = 12, ["meta"] = {["fields"] = {["infotext"] = "\27(T@default)Empty Bookshelf\27E", ["formspec"] = "size[8,7;]list[context;books;0,0.3;8,2;]list[current_player;main;0,2.85;8,1;]list[current_player;main;0,4.08;8,3;8]listring[context;books]listring[current_player;main]image[0,2.85;1,1;gui_hb_bg.png]image[1,2.85;1,1;gui_hb_bg.png]image[2,2.85;1,1;gui_hb_bg.png]image[3,2.85;1,1;gui_hb_bg.png]image[4,2.85;1,1;gui_hb_bg.png]image[5,2.85;1,1;gui_hb_bg.png]image[6,2.85;1,1;gui_hb_bg.png]image[7,2.85;1,1;gui_hb_bg.png]image[0,0.3;1,1;default_bookshelf_slot.png]image[1,0.3;1,1;default_bookshelf_slot.png]image[2,0.3;1,1;default_bookshelf_slot.png]image[3,0.3;1,1;default_bookshelf_slot.png]image[4,0.3;1,1;default_bookshelf_slot.png]image[5,0.3;1,1;default_bookshelf_slot.png]image[6,0.3;1,1;default_bookshelf_slot.png]image[7,0.3;1,1;default_bookshelf_slot.png]image[0,1.3;1,1;default_bookshelf_slot.png]image[1,1.3;1,1;default_bookshelf_slot.png]image[2,1.3;1,1;default_bookshelf_slot.png]image[3,1.3;1,1;default_bookshelf_slot.png]image[4,1.3;1,1;default_bookshelf_slot.png]image[5,1.3;1,1;default_bookshelf_slot.png]image[6,1.3;1,1;default_bookshelf_slot.png]image[7,1.3;1,1;default_bookshelf_slot.png]"}, ["inventory"] = {["books"] = {"", "", "", "", "", "", "", "", "", "", "", "", "", "", "", ""}}}, ["param2"] = 2, ["y"] = 7, ["z"] = 4, ["name"] = "default:bookshelf"}, {["x"] = 12, ["y"] = 7, ["z"] = 12, ["name"] = "cloud_items:decorative_cloud"}, {["x"] = 12, ["y"] = 8, ["z"] = 3, ["name"] = "cloud_items:decorative_cloud"}, {["x"] = 12, ["meta"] = {["fields"] = {["infotext"] = "\27(T@default)Empty Bookshelf\27E", ["formspec"] = "size[8,7;]list[context;books;0,0.3;8,2;]list[current_player;main;0,2.85;8,1;]list[current_player;main;0,4.08;8,3;8]listring[context;books]listring[current_player;main]image[0,2.85;1,1;gui_hb_bg.png]image[1,2.85;1,1;gui_hb_bg.png]image[2,2.85;1,1;gui_hb_bg.png]image[3,2.85;1,1;gui_hb_bg.png]image[4,2.85;1,1;gui_hb_bg.png]image[5,2.85;1,1;gui_hb_bg.png]image[6,2.85;1,1;gui_hb_bg.png]image[7,2.85;1,1;gui_hb_bg.png]image[0,0.3;1,1;default_bookshelf_slot.png]image[1,0.3;1,1;default_bookshelf_slot.png]image[2,0.3;1,1;default_bookshelf_slot.png]image[3,0.3;1,1;default_bookshelf_slot.png]image[4,0.3;1,1;default_bookshelf_slot.png]image[5,0.3;1,1;default_bookshelf_slot.png]image[6,0.3;1,1;default_bookshelf_slot.png]image[7,0.3;1,1;default_bookshelf_slot.png]image[0,1.3;1,1;default_bookshelf_slot.png]image[1,1.3;1,1;default_bookshelf_slot.png]image[2,1.3;1,1;default_bookshelf_slot.png]image[3,1.3;1,1;default_bookshelf_slot.png]image[4,1.3;1,1;default_bookshelf_slot.png]image[5,1.3;1,1;default_bookshelf_slot.png]image[6,1.3;1,1;default_bookshelf_slot.png]image[7,1.3;1,1;default_bookshelf_slot.png]"}, ["inventory"] = {["books"] = {"", "", "", "", "", "", "", "", "", "", "", "", "", "", "", ""}}}, ["param2"] = 2, ["y"] = 8, ["z"] = 4, ["name"] = "default:bookshelf"}, {["x"] = 12, ["y"] = 8, ["z"] = 12, ["name"] = "cloud_items:decorative_cloud"}, {["x"] = 12, ["y"] = 9, ["z"] = 3, ["name"] = "cloud_items:decorative_cloud"}, {["x"] = 12, ["meta"] = {["fields"] = {["infotext"] = "\27(T@default)Empty Bookshelf\27E", ["formspec"] = "size[8,7;]list[context;books;0,0.3;8,2;]list[current_player;main;0,2.85;8,1;]list[current_player;main;0,4.08;8,3;8]listring[context;books]listring[current_player;main]image[0,2.85;1,1;gui_hb_bg.png]image[1,2.85;1,1;gui_hb_bg.png]image[2,2.85;1,1;gui_hb_bg.png]image[3,2.85;1,1;gui_hb_bg.png]image[4,2.85;1,1;gui_hb_bg.png]image[5,2.85;1,1;gui_hb_bg.png]image[6,2.85;1,1;gui_hb_bg.png]image[7,2.85;1,1;gui_hb_bg.png]image[0,0.3;1,1;default_bookshelf_slot.png]image[1,0.3;1,1;default_bookshelf_slot.png]image[2,0.3;1,1;default_bookshelf_slot.png]image[3,0.3;1,1;default_bookshelf_slot.png]image[4,0.3;1,1;default_bookshelf_slot.png]image[5,0.3;1,1;default_bookshelf_slot.png]image[6,0.3;1,1;default_bookshelf_slot.png]image[7,0.3;1,1;default_bookshelf_slot.png]image[0,1.3;1,1;default_bookshelf_slot.png]image[1,1.3;1,1;default_bookshelf_slot.png]image[2,1.3;1,1;default_bookshelf_slot.png]image[3,1.3;1,1;default_bookshelf_slot.png]image[4,1.3;1,1;default_bookshelf_slot.png]image[5,1.3;1,1;default_bookshelf_slot.png]image[6,1.3;1,1;default_bookshelf_slot.png]image[7,1.3;1,1;default_bookshelf_slot.png]"}, ["inventory"] = {["books"] = {"", "", "", "", "", "", "", "", "", "", "", "", "", "", "", ""}}}, ["param2"] = 2, ["y"] = 9, ["z"] = 4, ["name"] = "default:bookshelf"}, {["x"] = 12, ["y"] = 9, ["z"] = 12, ["name"] = "cloud_items:decorative_cloud"}, {["x"] = 12, ["y"] = 10, ["z"] = 3, ["name"] = "cloud_items:decorative_cloud"}, {["x"] = 12, ["y"] = 10, ["z"] = 12, ["name"] = "cloud_items:decorative_cloud"}, {["x"] = 12, ["y"] = 11, ["z"] = 3, ["name"] = "cloud_items:decorative_cloud"}, {["x"] = 12, ["y"] = 11, ["z"] = 12, ["name"] = "cloud_items:decorative_cloud"}, {["x"] = 12, ["y"] = 12, ["z"] = 3, ["name"] = "cloud_items:decorative_cloud"}, {["x"] = 12, ["y"] = 12, ["z"] = 4, ["name"] = "cloud_items:decorative_cloud"}, {["x"] = 12, ["y"] = 12, ["z"] = 5, ["name"] = "cloud_items:decorative_cloud"}, {["x"] = 12, ["y"] = 12, ["z"] = 6, ["name"] = "cloud_items:decorative_cloud"}, {["x"] = 12, ["y"] = 12, ["z"] = 7, ["name"] = "cloud_items:decorative_cloud"}, {["x"] = 12, ["y"] = 12, ["z"] = 8, ["name"] = "cloud_items:decorative_cloud"}, {["x"] = 12, ["y"] = 12, ["z"] = 9, ["name"] = "cloud_items:decorative_cloud"}, {["x"] = 12, ["y"] = 12, ["z"] = 10, ["name"] = "cloud_items:decorative_cloud"}, {["x"] = 12, ["y"] = 12, ["z"] = 11, ["name"] = "cloud_items:decorative_cloud"}, {["x"] = 12, ["y"] = 12, ["z"] = 12, ["name"] = "cloud_items:decorative_cloud"}, {["x"] = 13, ["y"] = 0, ["z"] = 0, ["name"] = "cloud_items:decorative_cloud"}, {["x"] = 13, ["y"] = 0, ["z"] = 1, ["name"] = "cloud_items:decorative_cloud"}, {["x"] = 13, ["y"] = 0, ["z"] = 2, ["name"] = "cloud_items:decorative_cloud"}, {["x"] = 13, ["y"] = 0, ["z"] = 3, ["name"] = "cloud_items:decorative_cloud"}, {["x"] = 13, ["y"] = 0, ["z"] = 4, ["name"] = "cloud_items:decorative_cloud"}, {["x"] = 13, ["y"] = 0, ["z"] = 5, ["name"] = "cloud_items:decorative_cloud"}, {["x"] = 13, ["y"] = 0, ["z"] = 6, ["name"] = "cloud_items:decorative_cloud"}, {["x"] = 13, ["y"] = 0, ["z"] = 7, ["name"] = "cloud_items:decorative_cloud"}, {["x"] = 13, ["y"] = 0, ["z"] = 8, ["name"] = "cloud_items:decorative_cloud"}, {["x"] = 13, ["y"] = 0, ["z"] = 9, ["name"] = "cloud_items:decorative_cloud"}, {["x"] = 13, ["y"] = 0, ["z"] = 10, ["name"] = "cloud_items:decorative_cloud"}, {["x"] = 13, ["y"] = 0, ["z"] = 11, ["name"] = "cloud_items:decorative_cloud"}, {["x"] = 13, ["y"] = 0, ["z"] = 12, ["name"] = "cloud_items:decorative_cloud"}, {["x"] = 13, ["y"] = 0, ["z"] = 13, ["name"] = "cloud_items:decorative_cloud"}, {["x"] = 13, ["y"] = 0, ["z"] = 14, ["name"] = "cloud_items:decorative_cloud"}, {["x"] = 13, ["y"] = 0, ["z"] = 15, ["name"] = "cloud_items:decorative_cloud"}, {["x"] = 13, ["y"] = 1, ["z"] = 3, ["name"] = "cloud_items:decorative_cloud"}, {["x"] = 13, ["y"] = 1, ["param1"] = 238, ["z"] = 4, ["name"] = "default:mese_post_light"}, {["x"] = 13, ["param2"] = 1, ["y"] = 1, ["param1"] = 187, ["z"] = 7, ["name"] = "stairs:stair_goldblock"}, {["x"] = 13, ["param2"] = 1, ["y"] = 1, ["param1"] = 170, ["z"] = 8, ["name"] = "stairs:stair_goldblock"}, {["x"] = 13, ["param2"] = 1, ["y"] = 1, ["param1"] = 153, ["z"] = 9, ["name"] = "stairs:stair_goldblock"}, {["x"] = 13, ["meta"] = {["fields"] = {["formspec"] = "size[8,8.5]list[context;src;2.75,0.5;1,1;]list[context;fuel;2.75,2.5;1,1;]image[2.75,1.5;1,1;default_furnace_fire_bg.png]image[3.75,1.5;1,1;gui_furnace_arrow_bg.png^[transformR270]list[context;dst;4.75,0.96;2,2;]list[current_player;main;0,4.25;8,1;]list[current_player;main;0,5.5;8,3;8]listring[context;dst]listring[current_player;main]listring[context;src]listring[current_player;main]listring[context;fuel]listring[current_player;main]image[0,4.25;1,1;gui_hb_bg.png]image[1,4.25;1,1;gui_hb_bg.png]image[2,4.25;1,1;gui_hb_bg.png]image[3,4.25;1,1;gui_hb_bg.png]image[4,4.25;1,1;gui_hb_bg.png]image[5,4.25;1,1;gui_hb_bg.png]image[6,4.25;1,1;gui_hb_bg.png]image[7,4.25;1,1;gui_hb_bg.png]", ["infotext"] = "\27(T@default)Furnace inactive\27E\
\27(T@default)(Item: \27F\27(T@default)Empty\27E\27E; Fuel: \27F\27(T@default)Empty\27E\27E)\27E", ["fuel_totaltime"] = "0", ["src_time"] = "0", ["fuel_time"] = "0"}, ["inventory"] = {["fuel"] = {""}, ["dst"] = {"", "", "", ""}, ["src"] = {""}}}, ["y"] = 1, ["z"] = 11, ["name"] = "default:furnace"}, {["x"] = 13, ["y"] = 1, ["z"] = 12, ["name"] = "cloud_items:decorative_cloud"}, {["x"] = 13, ["y"] = 2, ["z"] = 3, ["name"] = "cloud_items:decorative_cloud"}, {["x"] = 13, ["meta"] = {["fields"] = {["infotext"] = "\27(T@default)Empty Bookshelf\27E", ["formspec"] = "size[8,7;]list[context;books;0,0.3;8,2;]list[current_player;main;0,2.85;8,1;]list[current_player;main;0,4.08;8,3;8]listring[context;books]listring[current_player;main]image[0,2.85;1,1;gui_hb_bg.png]image[1,2.85;1,1;gui_hb_bg.png]image[2,2.85;1,1;gui_hb_bg.png]image[3,2.85;1,1;gui_hb_bg.png]image[4,2.85;1,1;gui_hb_bg.png]image[5,2.85;1,1;gui_hb_bg.png]image[6,2.85;1,1;gui_hb_bg.png]image[7,2.85;1,1;gui_hb_bg.png]image[0,0.3;1,1;default_bookshelf_slot.png]image[1,0.3;1,1;default_bookshelf_slot.png]image[2,0.3;1,1;default_bookshelf_slot.png]image[3,0.3;1,1;default_bookshelf_slot.png]image[4,0.3;1,1;default_bookshelf_slot.png]image[5,0.3;1,1;default_bookshelf_slot.png]image[6,0.3;1,1;default_bookshelf_slot.png]image[7,0.3;1,1;default_bookshelf_slot.png]image[0,1.3;1,1;default_bookshelf_slot.png]image[1,1.3;1,1;default_bookshelf_slot.png]image[2,1.3;1,1;default_bookshelf_slot.png]image[3,1.3;1,1;default_bookshelf_slot.png]image[4,1.3;1,1;default_bookshelf_slot.png]image[5,1.3;1,1;default_bookshelf_slot.png]image[6,1.3;1,1;default_bookshelf_slot.png]image[7,1.3;1,1;default_bookshelf_slot.png]"}, ["inventory"] = {["books"] = {"", "", "", "", "", "", "", "", "", "", "", "", "", "", "", ""}}}, ["y"] = 2, ["z"] = 11, ["name"] = "default:bookshelf"}, {["x"] = 13, ["y"] = 2, ["z"] = 12, ["name"] = "cloud_items:decorative_cloud"}, {["x"] = 13, ["param2"] = 1, ["y"] = 2, ["param1"] = 158, ["z"] = 13, ["name"] = "stairs:stair_decorative_cloud"}, {["x"] = 13, ["param2"] = 1, ["y"] = 2, ["param1"] = 174, ["z"] = 14, ["name"] = "stairs:stair_decorative_cloud"}, {["x"] = 13, ["y"] = 3, ["z"] = 3, ["name"] = "cloud_items:decorative_cloud"}, {["x"] = 13, ["meta"] = {["fields"] = {["infotext"] = "\27(T@default)Empty Bookshelf\27E", ["formspec"] = "size[8,7;]list[context;books;0,0.3;8,2;]list[current_player;main;0,2.85;8,1;]list[current_player;main;0,4.08;8,3;8]listring[context;books]listring[current_player;main]image[0,2.85;1,1;gui_hb_bg.png]image[1,2.85;1,1;gui_hb_bg.png]image[2,2.85;1,1;gui_hb_bg.png]image[3,2.85;1,1;gui_hb_bg.png]image[4,2.85;1,1;gui_hb_bg.png]image[5,2.85;1,1;gui_hb_bg.png]image[6,2.85;1,1;gui_hb_bg.png]image[7,2.85;1,1;gui_hb_bg.png]image[0,0.3;1,1;default_bookshelf_slot.png]image[1,0.3;1,1;default_bookshelf_slot.png]image[2,0.3;1,1;default_bookshelf_slot.png]image[3,0.3;1,1;default_bookshelf_slot.png]image[4,0.3;1,1;default_bookshelf_slot.png]image[5,0.3;1,1;default_bookshelf_slot.png]image[6,0.3;1,1;default_bookshelf_slot.png]image[7,0.3;1,1;default_bookshelf_slot.png]image[0,1.3;1,1;default_bookshelf_slot.png]image[1,1.3;1,1;default_bookshelf_slot.png]image[2,1.3;1,1;default_bookshelf_slot.png]image[3,1.3;1,1;default_bookshelf_slot.png]image[4,1.3;1,1;default_bookshelf_slot.png]image[5,1.3;1,1;default_bookshelf_slot.png]image[6,1.3;1,1;default_bookshelf_slot.png]image[7,1.3;1,1;default_bookshelf_slot.png]"}, ["inventory"] = {["books"] = {"", "", "", "", "", "", "", "", "", "", "", "", "", "", "", ""}}}, ["y"] = 3, ["z"] = 11, ["name"] = "default:bookshelf"}, {["x"] = 13, ["y"] = 3, ["z"] = 12, ["name"] = "cloud_items:decorative_cloud"}, {["x"] = 13, ["y"] = 4, ["z"] = 3, ["name"] = "cloud_items:decorative_cloud"}, {["x"] = 13, ["y"] = 4, ["z"] = 12, ["name"] = "cloud_items:decorative_cloud"}, {["x"] = 13, ["y"] = 5, ["z"] = 3, ["name"] = "cloud_items:decorative_cloud"}, {["x"] = 13, ["y"] = 5, ["z"] = 12, ["name"] = "cloud_items:decorative_cloud"}, {["x"] = 13, ["y"] = 6, ["z"] = 3, ["name"] = "cloud_items:decorative_cloud"}, {["x"] = 13, ["y"] = 6, ["z"] = 4, ["name"] = "cloud_items:decorative_cloud"}, {["x"] = 13, ["y"] = 6, ["z"] = 5, ["name"] = "cloud_items:decorative_cloud"}, {["x"] = 13, ["y"] = 6, ["z"] = 6, ["name"] = "cloud_items:decorative_cloud"}, {["x"] = 13, ["y"] = 6, ["z"] = 7, ["name"] = "cloud_items:decorative_cloud"}, {["x"] = 13, ["y"] = 6, ["z"] = 8, ["name"] = "cloud_items:decorative_cloud"}, {["x"] = 13, ["y"] = 6, ["z"] = 9, ["name"] = "cloud_items:decorative_cloud"}, {["x"] = 13, ["y"] = 6, ["z"] = 10, ["name"] = "cloud_items:decorative_cloud"}, {["x"] = 13, ["y"] = 6, ["z"] = 11, ["name"] = "cloud_items:decorative_cloud"}, {["x"] = 13, ["y"] = 6, ["z"] = 12, ["name"] = "cloud_items:decorative_cloud"}, {["x"] = 13, ["y"] = 7, ["z"] = 3, ["name"] = "cloud_items:decorative_cloud"}, {["x"] = 13, ["meta"] = {["fields"] = {["infotext"] = "\27(T@default)Empty Bookshelf\27E", ["formspec"] = "size[8,7;]list[context;books;0,0.3;8,2;]list[current_player;main;0,2.85;8,1;]list[current_player;main;0,4.08;8,3;8]listring[context;books]listring[current_player;main]image[0,2.85;1,1;gui_hb_bg.png]image[1,2.85;1,1;gui_hb_bg.png]image[2,2.85;1,1;gui_hb_bg.png]image[3,2.85;1,1;gui_hb_bg.png]image[4,2.85;1,1;gui_hb_bg.png]image[5,2.85;1,1;gui_hb_bg.png]image[6,2.85;1,1;gui_hb_bg.png]image[7,2.85;1,1;gui_hb_bg.png]image[0,0.3;1,1;default_bookshelf_slot.png]image[1,0.3;1,1;default_bookshelf_slot.png]image[2,0.3;1,1;default_bookshelf_slot.png]image[3,0.3;1,1;default_bookshelf_slot.png]image[4,0.3;1,1;default_bookshelf_slot.png]image[5,0.3;1,1;default_bookshelf_slot.png]image[6,0.3;1,1;default_bookshelf_slot.png]image[7,0.3;1,1;default_bookshelf_slot.png]image[0,1.3;1,1;default_bookshelf_slot.png]image[1,1.3;1,1;default_bookshelf_slot.png]image[2,1.3;1,1;default_bookshelf_slot.png]image[3,1.3;1,1;default_bookshelf_slot.png]image[4,1.3;1,1;default_bookshelf_slot.png]image[5,1.3;1,1;default_bookshelf_slot.png]image[6,1.3;1,1;default_bookshelf_slot.png]image[7,1.3;1,1;default_bookshelf_slot.png]"}, ["inventory"] = {["books"] = {"", "", "", "", "", "", "", "", "", "", "", "", "", "", "", ""}}}, ["param2"] = 2, ["y"] = 7, ["z"] = 4, ["name"] = "default:bookshelf"}, {["x"] = 13, ["param2"] = 1, ["y"] = 7, ["param1"] = 188, ["z"] = 8, ["name"] = "stairs:stair_decorative_cloud"}, {["x"] = 13, ["param2"] = 1, ["y"] = 7, ["param1"] = 204, ["z"] = 9, ["name"] = "stairs:stair_decorative_cloud"}, {["x"] = 13, ["y"] = 7, ["param1"] = 238, ["z"] = 11, ["name"] = "default:mese_post_light"}, {["x"] = 13, ["y"] = 7, ["z"] = 12, ["name"] = "cloud_items:decorative_cloud"}, {["x"] = 13, ["y"] = 8, ["z"] = 3, ["name"] = "cloud_items:decorative_cloud"}, {["x"] = 13, ["meta"] = {["fields"] = {["infotext"] = "\27(T@default)Empty Bookshelf\27E", ["formspec"] = "size[8,7;]list[context;books;0,0.3;8,2;]list[current_player;main;0,2.85;8,1;]list[current_player;main;0,4.08;8,3;8]listring[context;books]listring[current_player;main]image[0,2.85;1,1;gui_hb_bg.png]image[1,2.85;1,1;gui_hb_bg.png]image[2,2.85;1,1;gui_hb_bg.png]image[3,2.85;1,1;gui_hb_bg.png]image[4,2.85;1,1;gui_hb_bg.png]image[5,2.85;1,1;gui_hb_bg.png]image[6,2.85;1,1;gui_hb_bg.png]image[7,2.85;1,1;gui_hb_bg.png]image[0,0.3;1,1;default_bookshelf_slot.png]image[1,0.3;1,1;default_bookshelf_slot.png]image[2,0.3;1,1;default_bookshelf_slot.png]image[3,0.3;1,1;default_bookshelf_slot.png]image[4,0.3;1,1;default_bookshelf_slot.png]image[5,0.3;1,1;default_bookshelf_slot.png]image[6,0.3;1,1;default_bookshelf_slot.png]image[7,0.3;1,1;default_bookshelf_slot.png]image[0,1.3;1,1;default_bookshelf_slot.png]image[1,1.3;1,1;default_bookshelf_slot.png]image[2,1.3;1,1;default_bookshelf_slot.png]image[3,1.3;1,1;default_bookshelf_slot.png]image[4,1.3;1,1;default_bookshelf_slot.png]image[5,1.3;1,1;default_bookshelf_slot.png]image[6,1.3;1,1;default_bookshelf_slot.png]image[7,1.3;1,1;default_bookshelf_slot.png]"}, ["inventory"] = {["books"] = {"", "", "", "", "", "", "", "", "", "", "", "", "", "", "", ""}}}, ["param2"] = 2, ["y"] = 8, ["z"] = 4, ["name"] = "default:bookshelf"}, {["x"] = 13, ["y"] = 8, ["z"] = 12, ["name"] = "cloud_items:decorative_cloud"}, {["x"] = 13, ["y"] = 9, ["z"] = 3, ["name"] = "cloud_items:decorative_cloud"}, {["x"] = 13, ["meta"] = {["fields"] = {["infotext"] = "\27(T@default)Empty Bookshelf\27E", ["formspec"] = "size[8,7;]list[context;books;0,0.3;8,2;]list[current_player;main;0,2.85;8,1;]list[current_player;main;0,4.08;8,3;8]listring[context;books]listring[current_player;main]image[0,2.85;1,1;gui_hb_bg.png]image[1,2.85;1,1;gui_hb_bg.png]image[2,2.85;1,1;gui_hb_bg.png]image[3,2.85;1,1;gui_hb_bg.png]image[4,2.85;1,1;gui_hb_bg.png]image[5,2.85;1,1;gui_hb_bg.png]image[6,2.85;1,1;gui_hb_bg.png]image[7,2.85;1,1;gui_hb_bg.png]image[0,0.3;1,1;default_bookshelf_slot.png]image[1,0.3;1,1;default_bookshelf_slot.png]image[2,0.3;1,1;default_bookshelf_slot.png]image[3,0.3;1,1;default_bookshelf_slot.png]image[4,0.3;1,1;default_bookshelf_slot.png]image[5,0.3;1,1;default_bookshelf_slot.png]image[6,0.3;1,1;default_bookshelf_slot.png]image[7,0.3;1,1;default_bookshelf_slot.png]image[0,1.3;1,1;default_bookshelf_slot.png]image[1,1.3;1,1;default_bookshelf_slot.png]image[2,1.3;1,1;default_bookshelf_slot.png]image[3,1.3;1,1;default_bookshelf_slot.png]image[4,1.3;1,1;default_bookshelf_slot.png]image[5,1.3;1,1;default_bookshelf_slot.png]image[6,1.3;1,1;default_bookshelf_slot.png]image[7,1.3;1,1;default_bookshelf_slot.png]"}, ["inventory"] = {["books"] = {"", "", "", "", "", "", "", "", "", "", "", "", "", "", "", ""}}}, ["param2"] = 2, ["y"] = 9, ["z"] = 4, ["name"] = "default:bookshelf"}, {["x"] = 13, ["y"] = 9, ["z"] = 12, ["name"] = "cloud_items:decorative_cloud"}, {["x"] = 13, ["y"] = 10, ["z"] = 3, ["name"] = "cloud_items:decorative_cloud"}, {["x"] = 13, ["y"] = 10, ["z"] = 12, ["name"] = "cloud_items:decorative_cloud"}, {["x"] = 13, ["y"] = 11, ["param1"] = 238, ["z"] = 3, ["name"] = "default:meselamp"}, {["x"] = 13, ["y"] = 11, ["param1"] = 238, ["z"] = 12, ["name"] = "default:meselamp"}, {["x"] = 13, ["y"] = 12, ["z"] = 3, ["name"] = "cloud_items:decorative_cloud"}, {["x"] = 13, ["y"] = 12, ["z"] = 4, ["name"] = "cloud_items:decorative_cloud"}, {["x"] = 13, ["y"] = 12, ["z"] = 5, ["name"] = "cloud_items:decorative_cloud"}, {["x"] = 13, ["y"] = 12, ["z"] = 6, ["name"] = "cloud_items:decorative_cloud"}, {["x"] = 13, ["y"] = 12, ["z"] = 7, ["name"] = "cloud_items:decorative_cloud"}, {["x"] = 13, ["y"] = 12, ["z"] = 8, ["name"] = "cloud_items:decorative_cloud"}, {["x"] = 13, ["y"] = 12, ["z"] = 9, ["name"] = "cloud_items:decorative_cloud"}, {["x"] = 13, ["y"] = 12, ["z"] = 10, ["name"] = "cloud_items:decorative_cloud"}, {["x"] = 13, ["y"] = 12, ["z"] = 11, ["name"] = "cloud_items:decorative_cloud"}, {["x"] = 13, ["y"] = 12, ["z"] = 12, ["name"] = "cloud_items:decorative_cloud"}, {["x"] = 14, ["y"] = 0, ["z"] = 0, ["name"] = "cloud_items:decorative_cloud"}, {["x"] = 14, ["y"] = 0, ["z"] = 1, ["name"] = "cloud_items:decorative_cloud"}, {["x"] = 14, ["y"] = 0, ["z"] = 2, ["name"] = "cloud_items:decorative_cloud"}, {["x"] = 14, ["y"] = 0, ["z"] = 3, ["name"] = "cloud_items:decorative_cloud"}, {["x"] = 14, ["y"] = 0, ["z"] = 4, ["name"] = "cloud_items:decorative_cloud"}, {["x"] = 14, ["y"] = 0, ["z"] = 5, ["name"] = "cloud_items:decorative_cloud"}, {["x"] = 14, ["y"] = 0, ["z"] = 6, ["name"] = "cloud_items:decorative_cloud"}, {["x"] = 14, ["y"] = 0, ["z"] = 7, ["name"] = "cloud_items:decorative_cloud"}, {["x"] = 14, ["y"] = 0, ["z"] = 8, ["name"] = "cloud_items:decorative_cloud"}, {["x"] = 14, ["y"] = 0, ["z"] = 9, ["name"] = "cloud_items:decorative_cloud"}, {["x"] = 14, ["y"] = 0, ["z"] = 10, ["name"] = "cloud_items:decorative_cloud"}, {["x"] = 14, ["y"] = 0, ["z"] = 11, ["name"] = "cloud_items:decorative_cloud"}, {["x"] = 14, ["y"] = 0, ["z"] = 12, ["name"] = "cloud_items:decorative_cloud"}, {["x"] = 14, ["y"] = 0, ["z"] = 13, ["name"] = "cloud_items:decorative_cloud"}, {["x"] = 14, ["y"] = 0, ["z"] = 14, ["name"] = "cloud_items:decorative_cloud"}, {["x"] = 14, ["y"] = 0, ["z"] = 15, ["name"] = "cloud_items:decorative_cloud"}, {["x"] = 14, ["y"] = 1, ["z"] = 3, ["name"] = "cloud_items:decorative_cloud"}, {["x"] = 14, ["y"] = 1, ["z"] = 4, ["name"] = "cloud_items:decorative_cloud"}, {["x"] = 14, ["y"] = 1, ["z"] = 5, ["name"] = "cloud_items:decorative_cloud"}, {["x"] = 14, ["y"] = 1, ["z"] = 6, ["name"] = "cloud_items:decorative_cloud"}, {["x"] = 14, ["y"] = 1, ["z"] = 7, ["name"] = "cloud_items:decorative_cloud"}, {["x"] = 14, ["y"] = 1, ["z"] = 8, ["name"] = "cloud_items:decorative_cloud"}, {["x"] = 14, ["y"] = 1, ["z"] = 9, ["name"] = "cloud_items:decorative_cloud"}, {["x"] = 14, ["y"] = 1, ["z"] = 10, ["name"] = "cloud_items:decorative_cloud"}, {["x"] = 14, ["y"] = 1, ["z"] = 11, ["name"] = "cloud_items:decorative_cloud"}, {["x"] = 14, ["y"] = 1, ["z"] = 12, ["name"] = "cloud_items:decorative_cloud"}, {["x"] = 14, ["y"] = 2, ["z"] = 3, ["name"] = "cloud_items:decorative_cloud"}, {["x"] = 14, ["y"] = 2, ["z"] = 4, ["name"] = "cloud_items:decorative_cloud"}, {["x"] = 14, ["y"] = 2, ["z"] = 5, ["name"] = "cloud_items:decorative_cloud"}, {["x"] = 14, ["y"] = 2, ["z"] = 6, ["name"] = "cloud_items:decorative_cloud"}, {["x"] = 14, ["y"] = 2, ["z"] = 7, ["name"] = "cloud_items:decorative_cloud"}, {["x"] = 14, ["y"] = 2, ["z"] = 8, ["name"] = "cloud_items:decorative_cloud"}, {["x"] = 14, ["y"] = 2, ["z"] = 9, ["name"] = "cloud_items:decorative_cloud"}, {["x"] = 14, ["y"] = 2, ["z"] = 10, ["name"] = "cloud_items:decorative_cloud"}, {["x"] = 14, ["y"] = 2, ["z"] = 11, ["name"] = "cloud_items:decorative_cloud"}, {["x"] = 14, ["y"] = 2, ["z"] = 12, ["name"] = "cloud_items:decorative_cloud"}, {["x"] = 14, ["y"] = 3, ["z"] = 3, ["name"] = "cloud_items:decorative_cloud"}, {["x"] = 14, ["y"] = 3, ["z"] = 4, ["name"] = "cloud_items:decorative_cloud"}, {["x"] = 14, ["y"] = 3, ["z"] = 5, ["name"] = "cloud_items:decorative_cloud"}, {["x"] = 14, ["y"] = 3, ["z"] = 6, ["name"] = "cloud_items:decorative_cloud"}, {["x"] = 14, ["y"] = 3, ["z"] = 7, ["name"] = "cloud_items:decorative_cloud"}, {["x"] = 14, ["y"] = 3, ["z"] = 8, ["name"] = "cloud_items:decorative_cloud"}, {["x"] = 14, ["y"] = 3, ["z"] = 9, ["name"] = "cloud_items:decorative_cloud"}, {["x"] = 14, ["y"] = 3, ["z"] = 10, ["name"] = "cloud_items:decorative_cloud"}, {["x"] = 14, ["y"] = 3, ["z"] = 11, ["name"] = "cloud_items:decorative_cloud"}, {["x"] = 14, ["y"] = 3, ["z"] = 12, ["name"] = "cloud_items:decorative_cloud"}, {["x"] = 14, ["param2"] = 1, ["y"] = 3, ["param1"] = 158, ["z"] = 13, ["name"] = "stairs:stair_decorative_cloud"}, {["x"] = 14, ["param2"] = 1, ["y"] = 3, ["param1"] = 174, ["z"] = 14, ["name"] = "stairs:stair_decorative_cloud"}, {["x"] = 14, ["y"] = 4, ["z"] = 3, ["name"] = "cloud_items:decorative_cloud"}, {["x"] = 14, ["y"] = 4, ["z"] = 4, ["name"] = "cloud_items:decorative_cloud"}, {["x"] = 14, ["y"] = 4, ["z"] = 5, ["name"] = "cloud_items:decorative_cloud"}, {["x"] = 14, ["y"] = 4, ["z"] = 6, ["name"] = "cloud_items:decorative_cloud"}, {["x"] = 14, ["y"] = 4, ["z"] = 7, ["name"] = "cloud_items:decorative_cloud"}, {["x"] = 14, ["y"] = 4, ["z"] = 8, ["name"] = "cloud_items:decorative_cloud"}, {["x"] = 14, ["y"] = 4, ["z"] = 9, ["name"] = "cloud_items:decorative_cloud"}, {["x"] = 14, ["y"] = 4, ["z"] = 10, ["name"] = "cloud_items:decorative_cloud"}, {["x"] = 14, ["y"] = 4, ["z"] = 11, ["name"] = "cloud_items:decorative_cloud"}, {["x"] = 14, ["y"] = 4, ["z"] = 12, ["name"] = "cloud_items:decorative_cloud"}, {["x"] = 14, ["y"] = 5, ["z"] = 3, ["name"] = "cloud_items:decorative_cloud"}, {["x"] = 14, ["y"] = 5, ["z"] = 4, ["name"] = "cloud_items:decorative_cloud"}, {["x"] = 14, ["y"] = 5, ["z"] = 5, ["name"] = "cloud_items:decorative_cloud"}, {["x"] = 14, ["y"] = 5, ["z"] = 6, ["name"] = "cloud_items:decorative_cloud"}, {["x"] = 14, ["y"] = 5, ["z"] = 7, ["name"] = "cloud_items:decorative_cloud"}, {["x"] = 14, ["y"] = 5, ["z"] = 8, ["name"] = "cloud_items:decorative_cloud"}, {["x"] = 14, ["y"] = 5, ["z"] = 9, ["name"] = "cloud_items:decorative_cloud"}, {["x"] = 14, ["y"] = 5, ["z"] = 10, ["name"] = "cloud_items:decorative_cloud"}, {["x"] = 14, ["y"] = 5, ["z"] = 11, ["name"] = "cloud_items:decorative_cloud"}, {["x"] = 14, ["y"] = 5, ["z"] = 12, ["name"] = "cloud_items:decorative_cloud"}, {["x"] = 14, ["y"] = 6, ["z"] = 3, ["name"] = "cloud_items:decorative_cloud"}, {["x"] = 14, ["y"] = 6, ["z"] = 4, ["name"] = "cloud_items:decorative_cloud"}, {["x"] = 14, ["y"] = 6, ["z"] = 5, ["name"] = "cloud_items:decorative_cloud"}, {["x"] = 14, ["y"] = 6, ["z"] = 6, ["name"] = "cloud_items:decorative_cloud"}, {["x"] = 14, ["y"] = 6, ["z"] = 7, ["name"] = "cloud_items:decorative_cloud"}, {["x"] = 14, ["y"] = 6, ["z"] = 8, ["name"] = "cloud_items:decorative_cloud"}, {["x"] = 14, ["y"] = 6, ["z"] = 9, ["name"] = "cloud_items:decorative_cloud"}, {["x"] = 14, ["y"] = 6, ["z"] = 10, ["name"] = "cloud_items:decorative_cloud"}, {["x"] = 14, ["y"] = 6, ["z"] = 11, ["name"] = "cloud_items:decorative_cloud"}, {["x"] = 14, ["y"] = 6, ["z"] = 12, ["name"] = "cloud_items:decorative_cloud"}, {["x"] = 14, ["y"] = 7, ["z"] = 3, ["name"] = "cloud_items:decorative_cloud"}, {["x"] = 14, ["y"] = 7, ["z"] = 4, ["name"] = "cloud_items:decorative_cloud"}, {["x"] = 14, ["y"] = 7, ["z"] = 5, ["name"] = "cloud_items:decorative_cloud"}, {["x"] = 14, ["y"] = 7, ["z"] = 6, ["name"] = "cloud_items:decorative_cloud"}, {["x"] = 14, ["y"] = 7, ["z"] = 7, ["name"] = "cloud_items:decorative_cloud"}, {["x"] = 14, ["y"] = 7, ["z"] = 8, ["name"] = "cloud_items:decorative_cloud"}, {["x"] = 14, ["y"] = 7, ["z"] = 9, ["name"] = "cloud_items:decorative_cloud"}, {["x"] = 14, ["y"] = 7, ["z"] = 10, ["name"] = "cloud_items:decorative_cloud"}, {["x"] = 14, ["y"] = 7, ["z"] = 11, ["name"] = "cloud_items:decorative_cloud"}, {["x"] = 14, ["y"] = 7, ["z"] = 12, ["name"] = "cloud_items:decorative_cloud"}, {["x"] = 14, ["y"] = 8, ["z"] = 3, ["name"] = "cloud_items:decorative_cloud"}, {["x"] = 14, ["y"] = 8, ["z"] = 4, ["name"] = "cloud_items:decorative_cloud"}, {["x"] = 14, ["y"] = 8, ["z"] = 5, ["name"] = "cloud_items:decorative_cloud"}, {["x"] = 14, ["y"] = 8, ["z"] = 6, ["name"] = "cloud_items:decorative_cloud"}, {["x"] = 14, ["y"] = 8, ["z"] = 7, ["name"] = "cloud_items:decorative_cloud"}, {["x"] = 14, ["meta"] = {["fields"] = {["state"] = "0"}, ["inventory"] = {}}, ["param2"] = 3, ["y"] = 8, ["param1"] = 158, ["z"] = 8, ["name"] = "doors:door_glass_a"}, {["x"] = 14, ["meta"] = {["fields"] = {["state"] = "2"}, ["inventory"] = {}}, ["param2"] = 3, ["y"] = 8, ["param1"] = 174, ["z"] = 9, ["name"] = "doors:door_glass_b"}, {["x"] = 14, ["y"] = 8, ["z"] = 10, ["name"] = "cloud_items:decorative_cloud"}, {["x"] = 14, ["y"] = 8, ["z"] = 11, ["name"] = "cloud_items:decorative_cloud"}, {["x"] = 14, ["y"] = 8, ["z"] = 12, ["name"] = "cloud_items:decorative_cloud"}, {["x"] = 14, ["y"] = 9, ["z"] = 3, ["name"] = "cloud_items:decorative_cloud"}, {["x"] = 14, ["y"] = 9, ["z"] = 4, ["name"] = "cloud_items:decorative_cloud"}, {["x"] = 14, ["y"] = 9, ["z"] = 5, ["name"] = "cloud_items:decorative_cloud"}, {["x"] = 14, ["y"] = 9, ["z"] = 6, ["name"] = "cloud_items:decorative_cloud"}, {["x"] = 14, ["y"] = 9, ["z"] = 7, ["name"] = "cloud_items:decorative_cloud"}, {["x"] = 14, ["param2"] = 3, ["y"] = 9, ["param1"] = 142, ["z"] = 8, ["name"] = "doors:hidden"}, {["x"] = 14, ["param2"] = 2, ["y"] = 9, ["param1"] = 158, ["z"] = 9, ["name"] = "doors:hidden"}, {["x"] = 14, ["y"] = 9, ["z"] = 10, ["name"] = "cloud_items:decorative_cloud"}, {["x"] = 14, ["y"] = 9, ["z"] = 11, ["name"] = "cloud_items:decorative_cloud"}, {["x"] = 14, ["y"] = 9, ["z"] = 12, ["name"] = "cloud_items:decorative_cloud"}, {["x"] = 14, ["y"] = 10, ["z"] = 3, ["name"] = "cloud_items:decorative_cloud"}, {["x"] = 14, ["y"] = 10, ["z"] = 4, ["name"] = "cloud_items:decorative_cloud"}, {["x"] = 14, ["y"] = 10, ["z"] = 5, ["name"] = "cloud_items:decorative_cloud"}, {["x"] = 14, ["y"] = 10, ["z"] = 6, ["name"] = "cloud_items:decorative_cloud"}, {["x"] = 14, ["y"] = 10, ["z"] = 7, ["name"] = "cloud_items:decorative_cloud"}, {["x"] = 14, ["y"] = 10, ["z"] = 8, ["name"] = "cloud_items:decorative_cloud"}, {["x"] = 14, ["y"] = 10, ["z"] = 9, ["name"] = "cloud_items:decorative_cloud"}, {["x"] = 14, ["y"] = 10, ["z"] = 10, ["name"] = "cloud_items:decorative_cloud"}, {["x"] = 14, ["y"] = 10, ["z"] = 11, ["name"] = "cloud_items:decorative_cloud"}, {["x"] = 14, ["y"] = 10, ["z"] = 12, ["name"] = "cloud_items:decorative_cloud"}, {["x"] = 14, ["y"] = 11, ["z"] = 3, ["name"] = "cloud_items:decorative_cloud"}, {["x"] = 14, ["y"] = 11, ["z"] = 4, ["name"] = "cloud_items:decorative_cloud"},