return {{["x"] = 0, ["y"] = 1, ["z"] = 8, ["name"] = "cloud_items:ongen_big"}, {["x"] = 0, ["y"] = 1, ["z"] = 9, ["name"] = "cloud_items:ongen_big"}, {["x"] = 0, ["y"] = 1, ["z"] = 10, ["name"] = "cloud_items:ongen_big"}, {["x"] = 0, ["y"] = 1, ["z"] = 11, ["name"] = "cloud_items:ongen_big"}, {["x"] = 0, ["y"] = 1, ["z"] = 12, ["name"] = "cloud_items:ongen_big"}, {["x"] = 0, ["y"] = 1, ["z"] = 13, ["name"] = "cloud_items:ongen_big"}, {["x"] = 0, ["y"] = 1, ["z"] = 14, ["name"] = "cloud_items:ongen_big"}, {["x"] = 0, ["y"] = 1, ["z"] = 15, ["name"] = "cloud_items:ongen_big"}, {["x"] = 1, ["y"] = 1, ["z"] = 7, ["name"] = "cloud_items:ongen_big"}, {["x"] = 1, ["y"] = 1, ["z"] = 8, ["name"] = "cloud_items:ongen_big"}, {["x"] = 1, ["y"] = 1, ["z"] = 9, ["name"] = "cloud_items:ongen_big"}, {["x"] = 1, ["y"] = 1, ["z"] = 10, ["name"] = "cloud_items:ongen_big"}, {["x"] = 1, ["y"] = 1, ["z"] = 11, ["name"] = "cloud_items:ongen_big"}, {["x"] = 1, ["y"] = 1, ["z"] = 12, ["name"] = "cloud_items:ongen_big"}, {["x"] = 1, ["y"] = 1, ["z"] = 13, ["name"] = "cloud_items:ongen_big"}, {["x"] = 1, ["y"] = 1, ["z"] = 14, ["name"] = "cloud_items:ongen_big"}, {["x"] = 1, ["y"] = 1, ["z"] = 15, ["name"] = "cloud_items:ongen_big"}, {["x"] = 1, ["y"] = 1, ["z"] = 16, ["name"] = "cloud_items:ongen_big"}, {["x"] = 2, ["y"] = 1, ["z"] = 6, ["name"] = "cloud_items:ongen_big"}, {["x"] = 2, ["y"] = 1, ["z"] = 7, ["name"] = "cloud_items:ongen_big"}, {["x"] = 2, ["y"] = 1, ["z"] = 8, ["name"] = "cloud_items:ongen_big"}, {["x"] = 2, ["y"] = 1, ["z"] = 9, ["name"] = "cloud_items:ongen_big"}, {["x"] = 2, ["y"] = 1, ["z"] = 10, ["name"] = "cloud_items:ongen_big"}, {["x"] = 2, ["y"] = 1, ["z"] = 11, ["name"] = "cloud_items:ongen_big"}, {["x"] = 2, ["y"] = 1, ["z"] = 12, ["name"] = "cloud_items:ongen_big"}, {["x"] = 2, ["y"] = 1, ["z"] = 13, ["name"] = "cloud_items:ongen_big"}, {["x"] = 2, ["y"] = 1, ["z"] = 14, ["name"] = "cloud_items:ongen_big"}, {["x"] = 2, ["y"] = 1, ["z"] = 15, ["name"] = "cloud_items:ongen_big"}, {["x"] = 2, ["y"] = 1, ["z"] = 16, ["name"] = "cloud_items:ongen_big"}, {["x"] = 2, ["y"] = 1, ["z"] = 17, ["name"] = "cloud_items:ongen_big"}, {["x"] = 2, ["y"] = 1, ["z"] = 18, ["name"] = "cloud_items:ongen_big"}, {["x"] = 2, ["y"] = 2, ["z"] = 7, ["name"] = "cloud_items:ongen_big"}, {["x"] = 2, ["y"] = 2, ["z"] = 8, ["name"] = "cloud_items:ongen_big"}, {["x"] = 2, ["y"] = 2, ["z"] = 9, ["name"] = "cloud_items:ongen_big"}, {["x"] = 2, ["y"] = 2, ["z"] = 10, ["name"] = "cloud_items:ongen_big"}, {["x"] = 2, ["y"] = 2, ["z"] = 11, ["name"] = "cloud_items:ongen_big"}, {["x"] = 2, ["y"] = 2, ["z"] = 12, ["name"] = "cloud_items:ongen_big"}, {["x"] = 2, ["y"] = 2, ["z"] = 13, ["name"] = "cloud_items:ongen_big"}, {["x"] = 2, ["y"] = 2, ["z"] = 14, ["name"] = "cloud_items:ongen_big"}, {["x"] = 2, ["y"] = 2, ["z"] = 15, ["name"] = "cloud_items:ongen_big"}, {["x"] = 2, ["y"] = 2, ["z"] = 16, ["name"] = "cloud_items:ongen_big"}, {["x"] = 3, ["y"] = 1, ["z"] = 5, ["name"] = "cloud_items:ongen_big"}, {["x"] = 3, ["y"] = 1, ["z"] = 6, ["name"] = "cloud_items:ongen_big"}, {["x"] = 3, ["y"] = 1, ["z"] = 7, ["name"] = "cloud_items:ongen_big"}, {["x"] = 3, ["y"] = 1, ["z"] = 8, ["name"] = "cloud_items:ongen_big"}, {["x"] = 3, ["y"] = 1, ["z"] = 9, ["name"] = "cloud_items:ongen_big"}, {["x"] = 3, ["y"] = 1, ["z"] = 10, ["name"] = "cloud_items:ongen_big"}, {["x"] = 3, ["y"] = 1, ["z"] = 11, ["name"] = "cloud_items:ongen_big"}, {["x"] = 3, ["y"] = 1, ["z"] = 12, ["name"] = "cloud_items:ongen_big"}, {["x"] = 3, ["y"] = 1, ["z"] = 13, ["name"] = "cloud_items:ongen_big"}, {["x"] = 3, ["y"] = 1, ["z"] = 14, ["name"] = "cloud_items:ongen_big"}, {["x"] = 3, ["y"] = 1, ["z"] = 15, ["name"] = "cloud_items:ongen_big"}, {["x"] = 3, ["y"] = 1, ["z"] = 16, ["name"] = "cloud_items:ongen_big"}, {["x"] = 3, ["y"] = 1, ["z"] = 17, ["name"] = "cloud_items:ongen_big"}, {["x"] = 3, ["y"] = 1, ["z"] = 18, ["name"] = "cloud_items:ongen_big"}, {["x"] = 3, ["y"] = 1, ["z"] = 19, ["name"] = "cloud_items:ongen_big"}, {["x"] = 3, ["y"] = 2, ["z"] = 6, ["name"] = "cloud_items:ongen_big"}, {["x"] = 3, ["y"] = 2, ["z"] = 7, ["name"] = "cloud_items:ongen_big"}, {["x"] = 3, ["y"] = 2, ["z"] = 8, ["name"] = "cloud_items:ongen_big"}, {["x"] = 3, ["y"] = 2, ["z"] = 9, ["name"] = "cloud_items:ongen_big"}, {["x"] = 3, ["y"] = 2, ["z"] = 10, ["name"] = "cloud_items:ongen_big"}, {["x"] = 3, ["y"] = 2, ["z"] = 11, ["name"] = "cloud_items:ongen_big"}, {["x"] = 3, ["y"] = 2, ["z"] = 12, ["name"] = "cloud_items:ongen_big"}, {["x"] = 3, ["y"] = 2, ["z"] = 13, ["name"] = "cloud_items:ongen_big"}, {["x"] = 3, ["y"] = 2, ["z"] = 14, ["name"] = "cloud_items:ongen_big"}, {["x"] = 3, ["y"] = 2, ["z"] = 15, ["name"] = "cloud_items:ongen_big"}, {["x"] = 3, ["y"] = 2, ["z"] = 16, ["name"] = "cloud_items:ongen_big"}, {["x"] = 3, ["y"] = 2, ["z"] = 17, ["name"] = "cloud_items:ongen_big"}, {["x"] = 3, ["y"] = 2, ["z"] = 18, ["name"] = "cloud_items:ongen_big"}, {["x"] = 4, ["y"] = 1, ["z"] = 4, ["name"] = "cloud_items:ongen_big"}, {["x"] = 4, ["y"] = 1, ["z"] = 5, ["name"] = "cloud_items:ongen_big"}, {["x"] = 4, ["y"] = 1, ["z"] = 6, ["name"] = "cloud_items:ongen_big"}, {["x"] = 4, ["y"] = 1, ["z"] = 7, ["name"] = "cloud_items:ongen_big"}, {["x"] = 4, ["y"] = 1, ["z"] = 8, ["name"] = "cloud_items:ongen_big"}, {["x"] = 4, ["y"] = 1, ["z"] = 9, ["name"] = "cloud_items:ongen_big"}, {["x"] = 4, ["y"] = 1, ["z"] = 10, ["name"] = "cloud_items:ongen_big"}, {["x"] = 4, ["y"] = 1, ["z"] = 11, ["name"] = "cloud_items:ongen_big"}, {["x"] = 4, ["y"] = 1, ["z"] = 12, ["name"] = "cloud_items:ongen_big"}, {["x"] = 4, ["y"] = 1, ["z"] = 13, ["name"] = "cloud_items:ongen_big"}, {["x"] = 4, ["y"] = 1, ["z"] = 14, ["name"] = "cloud_items:ongen_big"}, {["x"] = 4, ["y"] = 1, ["z"] = 15, ["name"] = "cloud_items:ongen_big"}, {["x"] = 4, ["y"] = 1, ["z"] = 16, ["name"] = "cloud_items:ongen_big"}, {["x"] = 4, ["y"] = 1, ["z"] = 17, ["name"] = "cloud_items:ongen_big"}, {["x"] = 4, ["y"] = 1, ["z"] = 18, ["name"] = "cloud_items:ongen_big"}, {["x"] = 4, ["y"] = 1, ["z"] = 19, ["name"] = "cloud_items:ongen_big"}, {["x"] = 4, ["y"] = 1, ["z"] = 20, ["name"] = "cloud_items:ongen_big"}, {["x"] = 4, ["y"] = 2, ["z"] = 6, ["name"] = "cloud_items:ongen_big"}, {["x"] = 4, ["y"] = 2, ["z"] = 7, ["name"] = "cloud_items:ongen_big"}, {["x"] = 4, ["y"] = 2, ["z"] = 8, ["name"] = "cloud_items:ongen_big"}, {["x"] = 4, ["y"] = 2, ["z"] = 9, ["name"] = "cloud_items:ongen_big"}, {["x"] = 4, ["y"] = 2, ["z"] = 10, ["name"] = "cloud_items:ongen_big"}, {["x"] = 4, ["y"] = 2, ["z"] = 11, ["name"] = "cloud_items:ongen_big"}, {["x"] = 4, ["y"] = 2, ["z"] = 12, ["name"] = "cloud_items:ongen_big"}, {["x"] = 4, ["y"] = 2, ["z"] = 13, ["name"] = "cloud_items:ongen_big"}, {["x"] = 4, ["y"] = 2, ["z"] = 14, ["name"] = "cloud_items:ongen_big"}, {["x"] = 4, ["y"] = 2, ["z"] = 15, ["name"] = "cloud_items:ongen_big"}, {["x"] = 4, ["y"] = 2, ["z"] = 16, ["name"] = "cloud_items:ongen_big"}, {["x"] = 4, ["y"] = 2, ["z"] = 17, ["name"] = "cloud_items:ongen_big"}, {["x"] = 4, ["y"] = 2, ["z"] = 18, ["name"] = "cloud_items:ongen_big"}, {["x"] = 4, ["y"] = 3, ["z"] = 8, ["name"] = "cloud_items:ongen_big"}, {["x"] = 4, ["y"] = 3, ["z"] = 9, ["name"] = "cloud_items:ongen_big"}, {["x"] = 4, ["y"] = 3, ["z"] = 10, ["name"] = "cloud_items:ongen_big"}, {["x"] = 4, ["y"] = 3, ["z"] = 11, ["name"] = "cloud_items:ongen_big"}, {["x"] = 4, ["y"] = 3, ["z"] = 12, ["name"] = "cloud_items:ongen_big"}, {["x"] = 4, ["y"] = 3, ["z"] = 13, ["name"] = "cloud_items:ongen_big"}, {["x"] = 4, ["y"] = 3, ["z"] = 14, ["name"] = "cloud_items:ongen_big"}, {["x"] = 4, ["y"] = 3, ["z"] = 15, ["name"] = "cloud_items:ongen_big"}, {["x"] = 5, ["y"] = 1, ["z"] = 3, ["name"] = "cloud_items:ongen_big"}, {["x"] = 5, ["y"] = 1, ["z"] = 4, ["name"] = "cloud_items:ongen_big"}, {["x"] = 5, ["y"] = 1, ["z"] = 5, ["name"] = "cloud_items:ongen_big"}, {["x"] = 5, ["y"] = 1, ["z"] = 6, ["name"] = "cloud_items:ongen_big"}, {["x"] = 5, ["y"] = 1, ["z"] = 7, ["name"] = "cloud_items:ongen_big"}, {["x"] = 5, ["y"] = 1, ["z"] = 8, ["name"] = "cloud_items:ongen_big"}, {["x"] = 5, ["y"] = 1, ["z"] = 9, ["name"] = "cloud_items:ongen_big"}, {["x"] = 5, ["y"] = 1, ["z"] = 10, ["name"] = "cloud_items:ongen_big"}, {["x"] = 5, ["y"] = 1, ["z"] = 11, ["name"] = "cloud_items:ongen_big"}, {["x"] = 5, ["y"] = 1, ["z"] = 12, ["name"] = "cloud_items:ongen_big"}, {["x"] = 5, ["y"] = 1, ["z"] = 13, ["name"] = "cloud_items:ongen_big"}, {["x"] = 5, ["y"] = 1, ["z"] = 14, ["name"] = "cloud_items:ongen_big"}, {["x"] = 5, ["y"] = 1, ["z"] = 15, ["name"] = "cloud_items:ongen_big"}, {["x"] = 5, ["y"] = 1, ["z"] = 16, ["name"] = "cloud_items:ongen_big"}, {["x"] = 5, ["y"] = 1, ["z"] = 17, ["name"] = "cloud_items:ongen_big"}, {["x"] = 5, ["y"] = 1, ["z"] = 18, ["name"] = "cloud_items:ongen_big"}, {["x"] = 5, ["y"] = 1, ["z"] = 19, ["name"] = "cloud_items:ongen_big"}, {["x"] = 5, ["y"] = 1, ["z"] = 20, ["name"] = "cloud_items:ongen_big"}, {["x"] = 5, ["y"] = 2, ["z"] = 5, ["name"] = "cloud_items:ongen_big"}, {["x"] = 5, ["y"] = 2, ["z"] = 6, ["name"] = "cloud_items:ongen_big"}, {["x"] = 5, ["y"] = 2, ["z"] = 7, ["name"] = "cloud_items:ongen_big"}, {["x"] = 5, ["y"] = 2, ["z"] = 8, ["name"] = "cloud_items:ongen_big"}, {["x"] = 5, ["y"] = 2, ["z"] = 9, ["name"] = "cloud_items:ongen_big"}, {["x"] = 5, ["y"] = 2, ["z"] = 10, ["name"] = "cloud_items:ongen_big"}, {["x"] = 5, ["y"] = 2, ["z"] = 11, ["name"] = "cloud_items:ongen_big"}, {["x"] = 5, ["y"] = 2, ["z"] = 12, ["name"] = "cloud_items:ongen_big"}, {["x"] = 5, ["y"] = 2, ["z"] = 13, ["name"] = "cloud_items:ongen_big"}, {["x"] = 5, ["y"] = 2, ["z"] = 14, ["name"] = "cloud_items:ongen_big"}, {["x"] = 5, ["y"] = 2, ["z"] = 15, ["name"] = "cloud_items:ongen_big"}, {["x"] = 5, ["y"] = 2, ["z"] = 16, ["name"] = "cloud_items:ongen_big"}, {["x"] = 5, ["y"] = 2, ["z"] = 17, ["name"] = "cloud_items:ongen_big"}, {["x"] = 5, ["y"] = 2, ["z"] = 18, ["name"] = "cloud_items:ongen_big"}, {["x"] = 5, ["y"] = 2, ["z"] = 19, ["name"] = "cloud_items:ongen_big"}, {["x"] = 5, ["y"] = 3, ["z"] = 6, ["name"] = "cloud_items:ongen_big"}, {["x"] = 5, ["y"] = 3, ["z"] = 7, ["name"] = "cloud_items:ongen_big"}, {["x"] = 5, ["y"] = 3, ["z"] = 8, ["name"] = "cloud_items:ongen_big"}, {["x"] = 5, ["y"] = 3, ["z"] = 9, ["name"] = "cloud_items:ongen_big"}, {["x"] = 5, ["y"] = 3, ["z"] = 10, ["name"] = "cloud_items:ongen_big"}, {["x"] = 5, ["y"] = 3, ["z"] = 11, ["name"] = "cloud_items:ongen_big"}, {["x"] = 5, ["y"] = 3, ["z"] = 12, ["name"] = "cloud_items:ongen_big"}, {["x"] = 5, ["y"] = 3, ["z"] = 13, ["name"] = "cloud_items:ongen_big"}, {["x"] = 5, ["y"] = 3, ["z"] = 14, ["name"] = "cloud_items:ongen_big"}, {["x"] = 5, ["y"] = 3, ["z"] = 15, ["name"] = "cloud_items:ongen_big"}, {["x"] = 5, ["y"] = 3, ["z"] = 16, ["name"] = "cloud_items:ongen_big"}, {["x"] = 5, ["y"] = 3, ["z"] = 17, ["name"] = "cloud_items:ongen_big"}, {["x"] = 5, ["y"] = 3, ["z"] = 18, ["name"] = "cloud_items:ongen_big"}, {["x"] = 5, ["y"] = 4, ["z"] = 9, ["name"] = "cloud_items:ongen_big"}, {["x"] = 5, ["y"] = 4, ["z"] = 10, ["name"] = "cloud_items:ongen_big"}, {["x"] = 5, ["y"] = 4, ["z"] = 11, ["name"] = "cloud_items:ongen_big"}, {["x"] = 5, ["y"] = 4, ["z"] = 12, ["name"] = "cloud_items:ongen_big"}, {["x"] = 5, ["y"] = 4, ["z"] = 13, ["name"] = "cloud_items:ongen_big"}, {["x"] = 5, ["y"] = 4, ["z"] = 14, ["name"] = "cloud_items:ongen_big"}, {["x"] = 5, ["y"] = 4, ["z"] = 15, ["name"] = "cloud_items:ongen_big"}, {["x"] = 6, ["y"] = 1, ["z"] = 3, ["name"] = "cloud_items:ongen_big"}, {["x"] = 6, ["y"] = 1, ["z"] = 4, ["name"] = "cloud_items:ongen_big"}, {["x"] = 6, ["y"] = 1, ["z"] = 5, ["name"] = "cloud_items:ongen_big"}, {["x"] = 6, ["y"] = 1, ["z"] = 6, ["name"] = "cloud_items:ongen_big"}, {["x"] = 6, ["y"] = 1, ["z"] = 7, ["name"] = "cloud_items:ongen_big"}, {["x"] = 6, ["y"] = 1, ["z"] = 8, ["name"] = "cloud_items:ongen_big"}, {["x"] = 6, ["y"] = 1, ["z"] = 9, ["name"] = "cloud_items:ongen_big"}, {["x"] = 6, ["y"] = 1, ["z"] = 10, ["name"] = "cloud_items:ongen_big"}, {["x"] = 6, ["y"] = 1, ["z"] = 11, ["name"] = "cloud_items:ongen_big"}, {["x"] = 6, ["y"] = 1, ["z"] = 12, ["name"] = "cloud_items:ongen_big"}, {["x"] = 6, ["y"] = 1, ["z"] = 13, ["name"] = "cloud_items:ongen_big"}, {["x"] = 6, ["y"] = 1, ["z"] = 14, ["name"] = "cloud_items:ongen_big"}, {["x"] = 6, ["y"] = 1, ["z"] = 15, ["name"] = "cloud_items:ongen_big"}, {["x"] = 6, ["y"] = 1, ["z"] = 16, ["name"] = "cloud_items:ongen_big"}, {["x"] = 6, ["y"] = 1, ["z"] = 17, ["name"] = "cloud_items:ongen_big"}, {["x"] = 6, ["y"] = 1, ["z"] = 18, ["name"] = "cloud_items:ongen_big"}, {["x"] = 6, ["y"] = 1, ["z"] = 19, ["name"] = "cloud_items:ongen_big"}, {["x"] = 6, ["y"] = 1, ["z"] = 20, ["name"] = "cloud_items:ongen_big"}, {["x"] = 6, ["y"] = 2, ["z"] = 5, ["name"] = "cloud_items:ongen_big"}, {["x"] = 6, ["y"] = 2, ["z"] = 6, ["name"] = "cloud_items:ongen_big"}, {["x"] = 6, ["y"] = 2, ["z"] = 7, ["name"] = "cloud_items:ongen_big"}, {["x"] = 6, ["y"] = 2, ["z"] = 8, ["name"] = "cloud_items:ongen_big"}, {["x"] = 6, ["y"] = 2, ["z"] = 9, ["name"] = "cloud_items:ongen_big"}, {["x"] = 6, ["y"] = 2, ["z"] = 10, ["name"] = "cloud_items:ongen_big"}, {["x"] = 6, ["y"] = 2, ["z"] = 11, ["name"] = "cloud_items:ongen_big"}, {["x"] = 6, ["y"] = 2, ["z"] = 12, ["name"] = "cloud_items:ongen_big"}, {["x"] = 6, ["y"] = 2, ["z"] = 13, ["name"] = "cloud_items:ongen_big"}, {["x"] = 6, ["y"] = 2, ["z"] = 14, ["name"] = "cloud_items:ongen_big"}, {["x"] = 6, ["y"] = 2, ["z"] = 15, ["name"] = "cloud_items:ongen_big"}, {["x"] = 6, ["y"] = 2, ["z"] = 16, ["name"] = "cloud_items:ongen_big"}, {["x"] = 6, ["y"] = 2, ["z"] = 17, ["name"] = "cloud_items:ongen_big"}, {["x"] = 6, ["y"] = 2, ["z"] = 18, ["name"] = "cloud_items:ongen_big"}, {["x"] = 6, ["y"] = 2, ["z"] = 19, ["name"] = "cloud_items:ongen_big"}, {["x"] = 6, ["y"] = 3, ["z"] = 6, ["name"] = "cloud_items:ongen_big"}, {["x"] = 6, ["y"] = 3, ["z"] = 7, ["name"] = "cloud_items:ongen_big"}, {["x"] = 6, ["y"] = 3, ["z"] = 8, ["name"] = "cloud_items:ongen_big"}, {["x"] = 6, ["y"] = 3, ["z"] = 9, ["name"] = "cloud_items:ongen_big"}, {["x"] = 6, ["y"] = 3, ["z"] = 10, ["name"] = "cloud_items:ongen_big"}, {["x"] = 6, ["y"] = 3, ["z"] = 11, ["name"] = "cloud_items:ongen_big"}, {["x"] = 6, ["y"] = 3, ["z"] = 12, ["name"] = "cloud_items:ongen_big"}, {["x"] = 6, ["y"] = 3, ["z"] = 13, ["name"] = "cloud_items:ongen_big"}, {["x"] = 6, ["y"] = 3, ["z"] = 14, ["name"] = "cloud_items:ongen_big"}, {["x"] = 6, ["y"] = 3, ["z"] = 15, ["name"] = "cloud_items:ongen_big"}, {["x"] = 6, ["y"] = 3, ["z"] = 16, ["name"] = "cloud_items:ongen_big"}, {["x"] = 6, ["y"] = 3, ["z"] = 17, ["name"] = "cloud_items:ongen_big"}, {["x"] = 6, ["y"] = 3, ["z"] = 18, ["name"] = "cloud_items:ongen_big"}, {["x"] = 6, ["y"] = 4, ["z"] = 7, ["name"] = "cloud_items:ongen_big"}, {["x"] = 6, ["y"] = 4, ["z"] = 8, ["name"] = "cloud_items:ongen_big"}, {["x"] = 6, ["y"] = 4, ["z"] = 9, ["name"] = "cloud_items:ongen_big"}, {["x"] = 6, ["y"] = 4, ["z"] = 10, ["name"] = "cloud_items:ongen_big"}, {["x"] = 6, ["y"] = 4, ["z"] = 11, ["name"] = "cloud_items:ongen_big"}, {["x"] = 6, ["y"] = 4, ["z"] = 12, ["name"] = "cloud_items:ongen_big"}, {["x"] = 6, ["y"] = 4, ["z"] = 13, ["name"] = "cloud_items:ongen_big"}, {["x"] = 6, ["y"] = 4, ["z"] = 14, ["name"] = "cloud_items:ongen_big"}, {["x"] = 6, ["y"] = 4, ["z"] = 15, ["name"] = "cloud_items:ongen_big"}, {["x"] = 6, ["y"] = 4, ["z"] = 16, ["name"] = "cloud_items:ongen_big"}, {["x"] = 6, ["y"] = 4, ["z"] = 17, ["name"] = "cloud_items:ongen_big"}, {["x"] = 7, ["y"] = 1, ["z"] = 2, ["name"] = "cloud_items:ongen_big"}, {["x"] = 7, ["y"] = 1, ["z"] = 3, ["name"] = "cloud_items:ongen_big"}, {["x"] = 7, ["y"] = 1, ["z"] = 4, ["name"] = "cloud_items:ongen_big"}, {["x"] = 7, ["y"] = 1, ["z"] = 5, ["name"] = "cloud_items:ongen_big"}, {["x"] = 7, ["y"] = 1, ["z"] = 6, ["name"] = "cloud_items:ongen_big"}, {["x"] = 7, ["y"] = 1, ["z"] = 7, ["name"] = "cloud_items:ongen_big"}, {["x"] = 7, ["y"] = 1, ["z"] = 8, ["name"] = "cloud_items:ongen_big"}, {["x"] = 7, ["y"] = 1, ["z"] = 9, ["name"] = "cloud_items:ongen_big"}, {["x"] = 7, ["y"] = 1, ["z"] = 10, ["name"] = "cloud_items:ongen_big"}, {["x"] = 7, ["y"] = 1, ["z"] = 11, ["name"] = "cloud_items:ongen_big"}, {["x"] = 7, ["y"] = 1, ["z"] = 12, ["name"] = "cloud_items:ongen_big"}, {["x"] = 7, ["y"] = 1, ["z"] = 13, ["name"] = "cloud_items:ongen_big"}, {["x"] = 7, ["y"] = 1, ["z"] = 14, ["name"] = "cloud_items:ongen_big"}, {["x"] = 7, ["y"] = 1, ["z"] = 15, ["name"] = "cloud_items:ongen_big"}, {["x"] = 7, ["y"] = 1, ["z"] = 16, ["name"] = "cloud_items:ongen_big"}, {["x"] = 7, ["y"] = 1, ["z"] = 17, ["name"] = "cloud_items:ongen_big"}, {["x"] = 7, ["y"] = 1, ["z"] = 18, ["name"] = "cloud_items:ongen_big"}, {["x"] = 7, ["y"] = 1, ["z"] = 19, ["name"] = "cloud_items:ongen_big"}, {["x"] = 7, ["y"] = 1, ["z"] = 20, ["name"] = "cloud_items:ongen_big"}, {["x"] = 7, ["y"] = 1, ["z"] = 21, ["name"] = "cloud_items:ongen_big"}, {["x"] = 7, ["y"] = 1, ["z"] = 22, ["name"] = "cloud_items:ongen_big"}, {["x"] = 7, ["y"] = 2, ["z"] = 4, ["name"] = "cloud_items:ongen_big"}, {["x"] = 7, ["y"] = 2, ["z"] = 5, ["name"] = "cloud_items:ongen_big"}, {["x"] = 7, ["y"] = 2, ["z"] = 6, ["name"] = "cloud_items:ongen_big"}, {["x"] = 7, ["y"] = 2, ["z"] = 7, ["name"] = "cloud_items:ongen_big"}, {["x"] = 7, ["y"] = 2, ["z"] = 8, ["name"] = "cloud_items:ongen_big"}, {["x"] = 7, ["y"] = 2, ["z"] = 9, ["name"] = "cloud_items:ongen_big"}, {["x"] = 7, ["y"] = 2, ["z"] = 10, ["name"] = "cloud_items:ongen_big"}, {["x"] = 7, ["y"] = 2, ["z"] = 11, ["name"] = "cloud_items:ongen_big"}, {["x"] = 7, ["y"] = 2, ["z"] = 12, ["name"] = "cloud_items:ongen_big"}, {["x"] = 7, ["y"] = 2, ["z"] = 13, ["name"] = "cloud_items:ongen_big"}, {["x"] = 7, ["y"] = 2, ["z"] = 14, ["name"] = "cloud_items:ongen_big"}, {["x"] = 7, ["y"] = 2, ["z"] = 15, ["name"] = "cloud_items:ongen_big"}, {["x"] = 7, ["y"] = 2, ["z"] = 16, ["name"] = "cloud_items:ongen_big"}, {["x"] = 7, ["y"] = 2, ["z"] = 17, ["name"] = "cloud_items:ongen_big"}, {["x"] = 7, ["y"] = 2, ["z"] = 18, ["name"] = "cloud_items:ongen_big"}, {["x"] = 7, ["y"] = 2, ["z"] = 19, ["name"] = "cloud_items:ongen_big"}, {["x"] = 7, ["y"] = 3, ["z"] = 6, ["name"] = "cloud_items:ongen_big"}, {["x"] = 7, ["y"] = 3, ["z"] = 7, ["name"] = "cloud_items:ongen_big"}, {["x"] = 7, ["y"] = 3, ["z"] = 8, ["name"] = "cloud_items:ongen_big"}, {["x"] = 7, ["y"] = 3, ["z"] = 9, ["name"] = "cloud_items:ongen_big"}, {["x"] = 7, ["y"] = 3, ["z"] = 10, ["name"] = "cloud_items:ongen_big"}, {["x"] = 7, ["y"] = 3, ["z"] = 11, ["name"] = "cloud_items:ongen_big"}, {["x"] = 7, ["y"] = 3, ["z"] = 12, ["name"] = "cloud_items:ongen_big"}, {["x"] = 7, ["y"] = 3, ["z"] = 13, ["name"] = "cloud_items:ongen_big"}, {["x"] = 7, ["y"] = 3, ["z"] = 14, ["name"] = "cloud_items:ongen_big"}, {["x"] = 7, ["y"] = 3, ["z"] = 15, ["name"] = "cloud_items:ongen_big"}, {["x"] = 7, ["y"] = 3, ["z"] = 16, ["name"] = "cloud_items:ongen_big"}, {["x"] = 7, ["y"] = 3, ["z"] = 17, ["name"] = "cloud_items:ongen_big"}, {["x"] = 7, ["y"] = 3, ["z"] = 18, ["name"] = "cloud_items:ongen_big"}, {["x"] = 7, ["y"] = 4, ["z"] = 7, ["name"] = "cloud_items:ongen_big"}, {["x"] = 7, ["y"] = 4, ["z"] = 8, ["name"] = "cloud_items:ongen_big"}, {["x"] = 7, ["y"] = 4, ["z"] = 9, ["name"] = "cloud_items:ongen_big"}, {["x"] = 7, ["y"] = 4, ["z"] = 10, ["name"] = "cloud_items:ongen_big"}, {["x"] = 7, ["y"] = 4, ["z"] = 11, ["name"] = "cloud_items:ongen_big"}, {["x"] = 7, ["y"] = 4, ["z"] = 12, ["name"] = "cloud_items:ongen_big"}, {["x"] = 7, ["y"] = 4, ["z"] = 13, ["name"] = "cloud_items:ongen_big"}, {["x"] = 7, ["y"] = 4, ["z"] = 14, ["name"] = "cloud_items:ongen_big"}, {["x"] = 7, ["y"] = 4, ["z"] = 15, ["name"] = "cloud_items:ongen_big"}, {["x"] = 7, ["y"] = 4, ["z"] = 16, ["name"] = "cloud_items:ongen_big"}, {["x"] = 7, ["y"] = 4, ["z"] = 17, ["name"] = "cloud_items:ongen_big"}, {["x"] = 7, ["y"] = 5, ["z"] = 8, ["name"] = "cloud_items:ongen_big"}, {["x"] = 7, ["y"] = 5, ["z"] = 9, ["name"] = "cloud_items:ongen_big"}, {["x"] = 7, ["y"] = 5, ["z"] = 10, ["name"] = "cloud_items:ongen_big"}, {["x"] = 7, ["y"] = 5, ["z"] = 11, ["name"] = "cloud_items:ongen_big"}, {["x"] = 7, ["y"] = 5, ["z"] = 12, ["name"] = "cloud_items:ongen_big"}, {["x"] = 7, ["y"] = 5, ["z"] = 13, ["name"] = "cloud_items:ongen_big"}, {["x"] = 7, ["y"] = 5, ["z"] = 14, ["name"] = "cloud_items:ongen_big"}, {["x"] = 7, ["y"] = 5, ["z"] = 15, ["name"] = "cloud_items:ongen_big"}, {["x"] = 7, ["y"] = 5, ["z"] = 16, ["name"] = "cloud_items:ongen_big"}, {["x"] = 8, ["y"] = 1, ["z"] = 2, ["name"] = "cloud_items:ongen_big"}, {["x"] = 8, ["y"] = 1, ["z"] = 3, ["name"] = "cloud_items:ongen_big"}, {["x"] = 8, ["y"] = 1, ["z"] = 4, ["name"] = "cloud_items:ongen_big"}, {["x"] = 8, ["y"] = 1, ["z"] = 5, ["name"] = "cloud_items:ongen_big"}, {["x"] = 8, ["y"] = 1, ["z"] = 6, ["name"] = "cloud_items:ongen_big"}, {["x"] = 8, ["y"] = 1, ["z"] = 7, ["name"] = "cloud_items:ongen_big"}, {["x"] = 8, ["y"] = 1, ["z"] = 8, ["name"] = "cloud_items:ongen_big"}, {["x"] = 8, ["y"] = 1, ["z"] = 9, ["name"] = "cloud_items:ongen_big"}, {["x"] = 8, ["y"] = 1, ["z"] = 10, ["name"] = "cloud_items:ongen_big"}, {["x"] = 8, ["y"] = 1, ["z"] = 11, ["name"] = "cloud_items:ongen_big"}, {["x"] = 8, ["y"] = 1, ["z"] = 12, ["name"] = "cloud_items:ongen_big"}, {["x"] = 8, ["y"] = 1, ["z"] = 13, ["name"] = "cloud_items:ongen_big"}, {["x"] = 8, ["y"] = 1, ["z"] = 14, ["name"] = "cloud_items:ongen_big"}, {["x"] = 8, ["y"] = 1, ["z"] = 15, ["name"] = "cloud_items:ongen_big"}, {["x"] = 8, ["y"] = 1, ["z"] = 16, ["name"] = "cloud_items:ongen_big"}, {["x"] = 8, ["y"] = 1, ["z"] = 17, ["name"] = "cloud_items:ongen_big"}, {["x"] = 8, ["y"] = 1, ["z"] = 18, ["name"] = "cloud_items:ongen_big"}, {["x"] = 8, ["y"] = 1, ["z"] = 19, ["name"] = "cloud_items:ongen_big"}, {["x"] = 8, ["y"] = 1, ["z"] = 20, ["name"] = "cloud_items:ongen_big"}, {["x"] = 8, ["y"] = 1, ["z"] = 21, ["name"] = "cloud_items:ongen_big"}, {["x"] = 8, ["y"] = 1, ["z"] = 22, ["name"] = "cloud_items:ongen_big"}, {["x"] = 8, ["y"] = 2, ["z"] = 4, ["name"] = "cloud_items:ongen_big"}, {["x"] = 8, ["y"] = 2, ["z"] = 5, ["name"] = "cloud_items:ongen_big"}, {["x"] = 8, ["y"] = 2, ["z"] = 6, ["name"] = "cloud_items:ongen_big"}, {["x"] = 8, ["y"] = 2, ["z"] = 7, ["name"] = "cloud_items:ongen_big"}, {["x"] = 8, ["y"] = 2, ["z"] = 8, ["name"] = "cloud_items:ongen_big"}, {["x"] = 8, ["y"] = 2, ["z"] = 9, ["name"] = "cloud_items:ongen_big"}, {["x"] = 8, ["y"] = 2, ["z"] = 10, ["name"] = "cloud_items:ongen_big"}, {["x"] = 8, ["y"] = 2, ["z"] = 11, ["name"] = "cloud_items:ongen_big"}, {["x"] = 8, ["y"] = 2, ["z"] = 12, ["name"] = "cloud_items:ongen_big"}, {["x"] = 8, ["y"] = 2, ["z"] = 13, ["name"] = "cloud_items:ongen_big"}, {["x"] = 8, ["y"] = 2, ["z"] = 14, ["name"] = "cloud_items:ongen_big"}, {["x"] = 8, ["y"] = 2, ["z"] = 15, ["name"] = "cloud_items:ongen_big"}, {["x"] = 8, ["y"] = 2, ["z"] = 16, ["name"] = "cloud_items:ongen_big"}, {["x"] = 8, ["y"] = 2, ["z"] = 17, ["name"] = "cloud_items:ongen_big"}, {["x"] = 8, ["y"] = 2, ["z"] = 18, ["name"] = "cloud_items:ongen_big"}, {["x"] = 8, ["y"] = 2, ["z"] = 19, ["name"] = "cloud_items:ongen_big"}, {["x"] = 8, ["y"] = 2, ["z"] = 20, ["name"] = "cloud_items:ongen_big"}, {["x"] = 8, ["y"] = 3, ["z"] = 6, ["name"] = "cloud_items:ongen_big"}, {["x"] = 8, ["y"] = 3, ["z"] = 7, ["name"] = "cloud_items:ongen_big"}, {["x"] = 8, ["y"] = 3, ["z"] = 8, ["name"] = "cloud_items:ongen_big"}, {["x"] = 8, ["y"] = 3, ["z"] = 9, ["name"] = "cloud_items:ongen_big"}, {["x"] = 8, ["y"] = 3, ["z"] = 10, ["name"] = "cloud_items:ongen_big"}, {["x"] = 8, ["y"] = 3, ["z"] = 11, ["name"] = "cloud_items:ongen_big"}, {["x"] = 8, ["y"] = 3, ["z"] = 12, ["name"] = "cloud_items:ongen_big"}, {["x"] = 8, ["y"] = 3, ["z"] = 13, ["name"] = "cloud_items:ongen_big"}, {["x"] = 8, ["y"] = 3, ["z"] = 14, ["name"] = "cloud_items:ongen_big"}, {["x"] = 8, ["y"] = 3, ["z"] = 15, ["name"] = "cloud_items:ongen_big"}, {["x"] = 8, ["y"] = 3, ["z"] = 16, ["name"] = "cloud_items:ongen_big"}, {["x"] = 8, ["y"] = 3, ["z"] = 17, ["name"] = "cloud_items:ongen_big"}, {["x"] = 8, ["y"] = 3, ["z"] = 18, ["name"] = "cloud_items:ongen_big"}, {["x"] = 8, ["y"] = 4, ["z"] = 7, ["name"] = "cloud_items:ongen_big"}, {["x"] = 8, ["y"] = 4, ["z"] = 8, ["name"] = "cloud_items:ongen_big"}, {["x"] = 8, ["y"] = 4, ["z"] = 16, ["name"] = "cloud_items:ongen_big"}, {["x"] = 8, ["y"] = 4, ["z"] = 17, ["name"] = "cloud_items:ongen_big"}, {["x"] = 8, ["y"] = 5, ["z"] = 8, ["name"] = "cloud_items:ongen_big"}, {["x"] = 8, ["y"] = 5, ["z"] = 9, ["name"] = "cloud_items:ongen_big"}, {["x"] = 8, ["y"] = 5, ["z"] = 10, ["name"] = "cloud_items:ongen_big"}, {["x"] = 8, ["y"] = 5, ["z"] = 11, ["name"] = "cloud_items:ongen_big"}, {["x"] = 8, ["y"] = 5, ["z"] = 12, ["name"] = "cloud_items:ongen_big"}, {["x"] = 8, ["y"] = 5, ["z"] = 13, ["name"] = "cloud_items:ongen_big"}, {["x"] = 8, ["y"] = 5, ["z"] = 14, ["name"] = "cloud_items:ongen_big"}, {["x"] = 8, ["y"] = 5, ["z"] = 15, ["name"] = "cloud_items:ongen_big"}, {["x"] = 8, ["y"] = 5, ["z"] = 16, ["name"] = "cloud_items:ongen_big"}, {["x"] = 8, ["y"] = 6, ["z"] = 10, ["name"] = "cloud_items:ongen_big"}, {["x"] = 8, ["y"] = 6, ["z"] = 11, ["name"] = "cloud_items:ongen_big"}, {["x"] = 8, ["y"] = 6, ["z"] = 12, ["name"] = "cloud_items:ongen_big"}, {["x"] = 8, ["y"] = 6, ["z"] = 13, ["name"] = "cloud_items:ongen_big"}, {["x"] = 8, ["y"] = 6, ["z"] = 14, ["name"] = "cloud_items:ongen_big"}, {["x"] = 9, ["y"] = 1, ["z"] = 1, ["name"] = "cloud_items:ongen_big"}, {["x"] = 9, ["y"] = 1, ["z"] = 2, ["name"] = "cloud_items:ongen_big"}, {["x"] = 9, ["y"] = 1, ["z"] = 3, ["name"] = "cloud_items:ongen_big"}, {["x"] = 9, ["y"] = 1, ["z"] = 4, ["name"] = "cloud_items:ongen_big"}, {["x"] = 9, ["y"] = 1, ["z"] = 5, ["name"] = "cloud_items:ongen_big"}, {["x"] = 9, ["y"] = 1, ["z"] = 6, ["name"] = "cloud_items:ongen_big"}, {["x"] = 9, ["y"] = 1, ["z"] = 7, ["name"] = "cloud_items:ongen_big"}, {["x"] = 9, ["y"] = 1, ["z"] = 8, ["name"] = "cloud_items:ongen_big"}, {["x"] = 9, ["y"] = 1, ["z"] = 9, ["name"] = "cloud_items:ongen_big"}, {["x"] = 9, ["y"] = 1, ["z"] = 10, ["name"] = "cloud_items:ongen_big"}, {["x"] = 9, ["y"] = 1, ["z"] = 11, ["name"] = "cloud_items:ongen_big"}, {["x"] = 9, ["y"] = 1, ["z"] = 12, ["name"] = "cloud_items:ongen_big"}, {["x"] = 9, ["y"] = 1, ["z"] = 13, ["name"] = "cloud_items:ongen_big"}, {["x"] = 9, ["y"] = 1, ["z"] = 14, ["name"] = "cloud_items:ongen_big"}, {["x"] = 9, ["y"] = 1, ["z"] = 15, ["name"] = "cloud_items:ongen_big"}, {["x"] = 9, ["y"] = 1, ["z"] = 16, ["name"] = "cloud_items:ongen_big"}, {["x"] = 9, ["y"] = 1, ["z"] = 17, ["name"] = "cloud_items:ongen_big"}, {["x"] = 9, ["y"] = 1, ["z"] = 18, ["name"] = "cloud_items:ongen_big"}, {["x"] = 9, ["y"] = 1, ["z"] = 19, ["name"] = "cloud_items:ongen_big"}, {["x"] = 9, ["y"] = 1, ["z"] = 20, ["name"] = "cloud_items:ongen_big"}, {["x"] = 9, ["y"] = 1, ["z"] = 21, ["name"] = "cloud_items:ongen_big"}, {["x"] = 9, ["y"] = 1, ["z"] = 22, ["name"] = "cloud_items:ongen_big"}, {["x"] = 9, ["y"] = 2, ["z"] = 4, ["name"] = "cloud_items:ongen_big"}, {["x"] = 9, ["y"] = 2, ["z"] = 5, ["name"] = "cloud_items:ongen_big"}, {["x"] = 9, ["y"] = 2, ["z"] = 6, ["name"] = "cloud_items:ongen_big"}, {["x"] = 9, ["y"] = 2, ["z"] = 7, ["name"] = "cloud_items:ongen_big"}, {["x"] = 9, ["y"] = 2, ["z"] = 8, ["name"] = "cloud_items:ongen_big"}, {["x"] = 9, ["y"] = 2, ["z"] = 9, ["name"] = "cloud_items:ongen_big"}, {["x"] = 9, ["y"] = 2, ["z"] = 10, ["name"] = "cloud_items:ongen_big"}, {["x"] = 9, ["y"] = 2, ["z"] = 11, ["name"] = "cloud_items:ongen_big"}, {["x"] = 9, ["y"] = 2, ["z"] = 12, ["name"] = "cloud_items:ongen_big"}, {["x"] = 9, ["y"] = 2, ["z"] = 13, ["name"] = "cloud_items:ongen_big"}, {["x"] = 9, ["y"] = 2, ["z"] = 14, ["name"] = "cloud_items:ongen_big"}, {["x"] = 9, ["y"] = 2, ["z"] = 15, ["name"] = "cloud_items:ongen_big"}, {["x"] = 9, ["y"] = 2, ["z"] = 16, ["name"] = "cloud_items:ongen_big"}, {["x"] = 9, ["y"] = 2, ["z"] = 17, ["name"] = "cloud_items:ongen_big"}, {["x"] = 9, ["y"] = 2, ["z"] = 18, ["name"] = "cloud_items:ongen_big"}, {["x"] = 9, ["y"] = 2, ["z"] = 19, ["name"] = "cloud_items:ongen_big"}, {["x"] = 9, ["y"] = 2, ["z"] = 20, ["name"] = "cloud_items:ongen_big"}, {["x"] = 9, ["y"] = 2, ["z"] = 21, ["name"] = "cloud_items:ongen_big"}, {["x"] = 9, ["y"] = 3, ["z"] = 6, ["name"] = "cloud_items:ongen_big"}, {["x"] = 9, ["y"] = 3, ["z"] = 7, ["name"] = "cloud_items:ongen_big"}, {["x"] = 9, ["y"] = 3, ["z"] = 8, ["name"] = "cloud_items:ongen_big"}, {["x"] = 9, ["y"] = 3, ["z"] = 9, ["name"] = "cloud_items:ongen_big"}, {["x"] = 9, ["y"] = 3, ["z"] = 10, ["name"] = "cloud_items:ongen_big"}, {["x"] = 9, ["y"] = 3, ["z"] = 11, ["name"] = "cloud_items:ongen_big"}, {["x"] = 9, ["y"] = 3, ["z"] = 12, ["name"] = "cloud_items:ongen_big"}, {["x"] = 9, ["y"] = 3, ["z"] = 13, ["name"] = "cloud_items:ongen_big"}, {["x"] = 9, ["y"] = 3, ["z"] = 14, ["name"] = "cloud_items:ongen_big"}, {["x"] = 9, ["y"] = 3, ["z"] = 15, ["name"] = "cloud_items:ongen_big"}, {["x"] = 9, ["y"] = 3, ["z"] = 16, ["name"] = "cloud_items:ongen_big"}, {["x"] = 9, ["y"] = 3, ["z"] = 17, ["name"] = "cloud_items:ongen_big"}, {["x"] = 9, ["y"] = 3, ["z"] = 18, ["name"] = "cloud_items:ongen_big"}, {["x"] = 9, ["y"] = 4, ["z"] = 7, ["name"] = "cloud_items:ongen_big"}, {["x"] = 9, ["y"] = 4, ["z"] = 8, ["name"] = "cloud_items:ongen_big"}, {["x"] = 9, ["y"] = 4, ["z"] = 16, ["name"] = "cloud_items:ongen_big"}, {["x"] = 9, ["y"] = 4, ["z"] = 17, ["name"] = "cloud_items:ongen_big"}, {["x"] = 9, ["y"] = 5, ["z"] = 8, ["name"] = "cloud_items:ongen_big"}, {["x"] = 9, ["y"] = 5, ["z"] = 9, ["name"] = "cloud_items:ongen_big"}, {["x"] = 9, ["y"] = 5, ["z"] = 15, ["name"] = "cloud_items:ongen_big"}, {["x"] = 9, ["y"] = 5, ["z"] = 16, ["name"] = "cloud_items:ongen_big"}, {["x"] = 9, ["y"] = 6, ["z"] = 9, ["name"] = "cloud_items:ongen_big"}, {["x"] = 9, ["y"] = 6, ["z"] = 10, ["name"] = "cloud_items:ongen_big"}, {["x"] = 9, ["y"] = 6, ["z"] = 11, ["name"] = "cloud_items:ongen_big"}, {["x"] = 9, ["y"] = 6, ["z"] = 12, ["name"] = "cloud_items:ongen_big"}, {["x"] = 9, ["y"] = 6, ["z"] = 13, ["name"] = "cloud_items:ongen_big"}, {["x"] = 9, ["y"] = 6, ["z"] = 14, ["name"] = "cloud_items:ongen_big"}, {["x"] = 9, ["y"] = 6, ["z"] = 15, ["name"] = "cloud_items:ongen_big"}, {["x"] = 10, ["y"] = 1, ["z"] = 0, ["name"] = "cloud_items:ongen_big"}, {["x"] = 10, ["y"] = 1, ["z"] = 1, ["name"] = "cloud_items:ongen_big"}, {["x"] = 10, ["y"] = 1, ["z"] = 2, ["name"] = "cloud_items:ongen_big"}, {["x"] = 10, ["y"] = 1, ["z"] = 3, ["name"] = "cloud_items:ongen_big"}, {["x"] = 10, ["y"] = 1, ["z"] = 4, ["name"] = "cloud_items:ongen_big"}, {["x"] = 10, ["y"] = 1, ["z"] = 5, ["name"] = "cloud_items:ongen_big"}, {["x"] = 10, ["y"] = 1, ["z"] = 6, ["name"] = "cloud_items:ongen_big"}, {["x"] = 10, ["y"] = 1, ["z"] = 7, ["name"] = "cloud_items:ongen_big"}, {["x"] = 10, ["y"] = 1, ["z"] = 8, ["name"] = "cloud_items:ongen_big"}, {["x"] = 10, ["y"] = 1, ["z"] = 9, ["name"] = "cloud_items:ongen_big"}, {["x"] = 10, ["y"] = 1, ["z"] = 10, ["name"] = "cloud_items:ongen_big"}, {["x"] = 10, ["y"] = 1, ["z"] = 11, ["name"] = "cloud_items:ongen_big"}, {["x"] = 10, ["y"] = 1, ["z"] = 12, ["name"] = "cloud_items:ongen_big"}, {["x"] = 10, ["y"] = 1, ["z"] = 13, ["name"] = "cloud_items:ongen_big"}, {["x"] = 10, ["y"] = 1, ["z"] = 14, ["name"] = "cloud_items:ongen_big"}, {["x"] = 10, ["y"] = 1, ["z"] = 15, ["name"] = "cloud_items:ongen_big"}, {["x"] = 10, ["y"] = 1, ["z"] = 16, ["name"] = "cloud_items:ongen_big"}, {["x"] = 10, ["y"] = 1, ["z"] = 17, ["name"] = "cloud_items:ongen_big"}, {["x"] = 10, ["y"] = 1, ["z"] = 18, ["name"] = "cloud_items:ongen_big"}, {["x"] = 10, ["y"] = 1, ["z"] = 19, ["name"] = "cloud_items:ongen_big"}, {["x"] = 10, ["y"] = 1, ["z"] = 20, ["name"] = "cloud_items:ongen_big"}, {["x"] = 10, ["y"] = 1, ["z"] = 21, ["name"] = "cloud_items:ongen_big"}, {["x"] = 10, ["y"] = 1, ["z"] = 22, ["name"] = "cloud_items:ongen_big"}, {["x"] = 10, ["y"] = 2, ["z"] = 4, ["name"] = "cloud_items:ongen_big"}, {["x"] = 10, ["y"] = 2, ["z"] = 5, ["name"] = "cloud_items:ongen_big"}, {["x"] = 10, ["y"] = 2, ["z"] = 6, ["name"] = "cloud_items:ongen_big"}, {["x"] = 10, ["y"] = 2, ["z"] = 7, ["name"] = "cloud_items:ongen_big"}, {["x"] = 10, ["y"] = 2, ["z"] = 8, ["name"] = "cloud_items:ongen_big"}, {["x"] = 10, ["y"] = 2, ["z"] = 9, ["name"] = "cloud_items:ongen_big"}, {["x"] = 10, ["y"] = 2, ["z"] = 10, ["name"] = "cloud_items:ongen_big"}, {["x"] = 10, ["y"] = 2, ["z"] = 11, ["name"] = "cloud_items:ongen_big"}, {["x"] = 10, ["y"] = 2, ["z"] = 12, ["name"] = "cloud_items:ongen_big"}, {["x"] = 10, ["y"] = 2, ["z"] = 13, ["name"] = "cloud_items:ongen_big"}, {["x"] = 10, ["y"] = 2, ["z"] = 14, ["name"] = "cloud_items:ongen_big"}, {["x"] = 10, ["y"] = 2, ["z"] = 15, ["name"] = "cloud_items:ongen_big"}, {["x"] = 10, ["y"] = 2, ["z"] = 16, ["name"] = "cloud_items:ongen_big"}, {["x"] = 10, ["y"] = 2, ["z"] = 17, ["name"] = "cloud_items:ongen_big"}, {["x"] = 10, ["y"] = 2, ["z"] = 18, ["name"] = "cloud_items:ongen_big"}, {["x"] = 10, ["y"] = 2, ["z"] = 19, ["name"] = "cloud_items:ongen_big"}, {["x"] = 10, ["y"] = 2, ["z"] = 20, ["name"] = "cloud_items:ongen_big"}, {["x"] = 10, ["y"] = 2, ["z"] = 21, ["name"] = "cloud_items:ongen_big"}, {["x"] = 10, ["y"] = 3, ["z"] = 6, ["name"] = "cloud_items:ongen_big"}, {["x"] = 10, ["y"] = 3, ["z"] = 7, ["name"] = "cloud_items:ongen_big"}, {["x"] = 10, ["y"] = 3, ["z"] = 8, ["name"] = "cloud_items:ongen_big"}, {["x"] = 10, ["y"] = 3, ["z"] = 9, ["name"] = "cloud_items:ongen_big"}, {["x"] = 10, ["y"] = 3, ["z"] = 10, ["name"] = "cloud_items:ongen_big"}, {["x"] = 10, ["y"] = 3, ["z"] = 11, ["name"] = "cloud_items:ongen_big"}, {["x"] = 10, ["y"] = 3, ["z"] = 12, ["name"] = "cloud_items:ongen_big"}, {["x"] = 10, ["y"] = 3, ["z"] = 13, ["name"] = "cloud_items:ongen_big"}, {["x"] = 10, ["y"] = 3, ["z"] = 14, ["name"] = "cloud_items:ongen_big"}, {["x"] = 10, ["y"] = 3, ["z"] = 15, ["name"] = "cloud_items:ongen_big"}, {["x"] = 10, ["y"] = 3, ["z"] = 16, ["name"] = "cloud_items:ongen_big"}, {["x"] = 10, ["y"] = 3, ["z"] = 17, ["name"] = "cloud_items:ongen_big"}, {["x"] = 10, ["y"] = 3, ["z"] = 18, ["name"] = "cloud_items:ongen_big"}, {["x"] = 10, ["y"] = 4, ["z"] = 7, ["name"] = "cloud_items:ongen_big"}, {["x"] = 10, ["y"] = 4, ["z"] = 8, ["name"] = "cloud_items:ongen_big"}, {["x"] = 10, ["y"] = 4, ["z"] = 12, ["name"] = "cloud_items:ongen_big"}, {["x"] = 10, ["y"] = 4, ["z"] = 16, ["name"] = "cloud_items:ongen_big"}, {["x"] = 10, ["y"] = 4, ["z"] = 17, ["name"] = "cloud_items:ongen_big"}, {["x"] = 10, ["y"] = 5, ["z"] = 8, ["name"] = "cloud_items:ongen_big"}, {["x"] = 10, ["y"] = 5, ["z"] = 9, ["name"] = "cloud_items:ongen_big"}, {["x"] = 10, ["y"] = 5, ["z"] = 12, ["name"] = "cloud_items:ongen_big"}, {["x"] = 10, ["y"] = 5, ["z"] = 15, ["name"] = "cloud_items:ongen_big"}, {["x"] = 10, ["y"] = 5, ["z"] = 16, ["name"] = "cloud_items:ongen_big"}, {["x"] = 10, ["y"] = 6, ["z"] = 9, ["name"] = "cloud_items:ongen_big"}, {["x"] = 10, ["y"] = 6, ["z"] = 10, ["name"] = "cloud_items:ongen_big"}, {["x"] = 10, ["y"] = 6, ["z"] = 11, ["name"] = "cloud_items:ongen_big"}, {["x"] = 10, ["y"] = 6, ["z"] = 12, ["name"] = "cloud_items:ongen_big"}, {["x"] = 10, ["y"] = 6, ["z"] = 13, ["name"] = "cloud_items:ongen_big"}, {["x"] = 10, ["y"] = 6, ["z"] = 14, ["name"] = "cloud_items:ongen_big"}, {["x"] = 10, ["y"] = 6, ["z"] = 15, ["name"] = "cloud_items:ongen_big"}, {["x"] = 11, ["y"] = 1, ["z"] = 0, ["name"] = "cloud_items:ongen_big"}, {["x"] = 11, ["y"] = 1, ["z"] = 1, ["name"] = "cloud_items:ongen_big"}, {["x"] = 11, ["y"] = 1, ["z"] = 2, ["name"] = "cloud_items:ongen_big"}, {["x"] = 11, ["y"] = 1, ["z"] = 3, ["name"] = "cloud_items:ongen_big"}, {["x"] = 11, ["y"] = 1, ["z"] = 4, ["name"] = "cloud_items:ongen_big"}, {["x"] = 11, ["y"] = 1, ["z"] = 5, ["name"] = "cloud_items:ongen_big"}, {["x"] = 11, ["y"] = 1, ["z"] = 6, ["name"] = "cloud_items:ongen_big"}, {["x"] = 11, ["y"] = 1, ["z"] = 7, ["name"] = "cloud_items:ongen_big"}, {["x"] = 11, ["y"] = 1, ["z"] = 8, ["name"] = "cloud_items:ongen_big"}, {["x"] = 11, ["y"] = 1, ["z"] = 9, ["name"] = "cloud_items:ongen_big"}, {["x"] = 11, ["y"] = 1, ["z"] = 10, ["name"] = "cloud_items:ongen_big"}, {["x"] = 11, ["y"] = 1, ["z"] = 11, ["name"] = "cloud_items:ongen_big"}, {["x"] = 11, ["y"] = 1, ["z"] = 12, ["name"] = "cloud_items:ongen_big"}, {["x"] = 11, ["y"] = 1, ["z"] = 13, ["name"] = "cloud_items:ongen_big"}, {["x"] = 11, ["y"] = 1, ["z"] = 14, ["name"] = "cloud_items:ongen_big"}, {["x"] = 11, ["y"] = 1, ["z"] = 15, ["name"] = "cloud_items:ongen_big"}, {["x"] = 11, ["y"] = 1, ["z"] = 16, ["name"] = "cloud_items:ongen_big"}, {["x"] = 11, ["y"] = 1, ["z"] = 17, ["name"] = "cloud_items:ongen_big"}, {["x"] = 11, ["y"] = 1, ["z"] = 18, ["name"] = "cloud_items:ongen_big"}, {["x"] = 11, ["y"] = 1, ["z"] = 19, ["name"] = "cloud_items:ongen_big"}, {["x"] = 11, ["y"] = 1, ["z"] = 20, ["name"] = "cloud_items:ongen_big"}, {["x"] = 11, ["y"] = 1, ["z"] = 21, ["name"] = "cloud_items:ongen_big"}, {["x"] = 11, ["y"] = 1, ["z"] = 22, ["name"] = "cloud_items:ongen_big"}, {["x"] = 11, ["y"] = 2, ["z"] = 4, ["name"] = "cloud_items:ongen_big"}, {["x"] = 11, ["y"] = 2, ["z"] = 5, ["name"] = "cloud_items:ongen_big"}, {["x"] = 11, ["y"] = 2, ["z"] = 6, ["name"] = "cloud_items:ongen_big"}, {["x"] = 11, ["y"] = 2, ["z"] = 7, ["name"] = "cloud_items:ongen_big"}, {["x"] = 11, ["y"] = 2, ["z"] = 8, ["name"] = "cloud_items:ongen_big"}, {["x"] = 11, ["y"] = 2, ["z"] = 9, ["name"] = "cloud_items:ongen_big"}, {["x"] = 11, ["y"] = 2, ["z"] = 10, ["name"] = "cloud_items:ongen_big"}, {["x"] = 11, ["y"] = 2, ["z"] = 11, ["name"] = "cloud_items:ongen_big"}, {["x"] = 11, ["y"] = 2, ["z"] = 12, ["name"] = "cloud_items:ongen_big"}, {["x"] = 11, ["y"] = 2, ["z"] = 13, ["name"] = "cloud_items:ongen_big"}, {["x"] = 11, ["y"] = 2, ["z"] = 14, ["name"] = "cloud_items:ongen_big"}, {["x"] = 11, ["y"] = 2, ["z"] = 15, ["name"] = "cloud_items:ongen_big"}, {["x"] = 11, ["y"] = 2, ["z"] = 16, ["name"] = "cloud_items:ongen_big"}, {["x"] = 11, ["y"] = 2, ["z"] = 17, ["name"] = "cloud_items:ongen_big"}, {["x"] = 11, ["y"] = 2, ["z"] = 18, ["name"] = "cloud_items:ongen_big"}, {["x"] = 11, ["y"] = 2, ["z"] = 19, ["name"] = "cloud_items:ongen_big"}, {["x"] = 11, ["y"] = 2, ["z"] = 20, ["name"] = "cloud_items:ongen_big"}, {["x"] = 11, ["y"] = 2, ["z"] = 21, ["name"] = "cloud_items:ongen_big"}, {["x"] = 11, ["y"] = 3, ["z"] = 6, ["name"] = "cloud_items:ongen_big"}, {["x"] = 11, ["y"] = 3, ["z"] = 7, ["name"] = "cloud_items:ongen_big"}, {["x"] = 11, ["y"] = 3, ["z"] = 8, ["name"] = "cloud_items:ongen_big"}, {["x"] = 11, ["y"] = 3, ["z"] = 9, ["name"] = "cloud_items:ongen_big"}, {["x"] = 11, ["y"] = 3, ["z"] = 10, ["name"] = "cloud_items:ongen_big"}, {["x"] = 11, ["y"] = 3, ["z"] = 11, ["name"] = "cloud_items:ongen_big"}, {["x"] = 11, ["y"] = 3, ["z"] = 12, ["name"] = "cloud_items:ongen_big"}, {["x"] = 11, ["y"] = 3, ["z"] = 13, ["name"] = "cloud_items:ongen_big"}, {["x"] = 11, ["y"] = 3, ["z"] = 14, ["name"] = "cloud_items:ongen_big"}, {["x"] = 11, ["y"] = 3, ["z"] = 15, ["name"] = "cloud_items:ongen_big"}, {["x"] = 11, ["y"] = 3, ["z"] = 16, ["name"] = "cloud_items:ongen_big"}, {["x"] = 11, ["y"] = 3, ["z"] = 17, ["name"] = "cloud_items:ongen_big"}, {["x"] = 11, ["y"] = 3, ["z"] = 18, ["name"] = "cloud_items:ongen_big"}, {["x"] = 11, ["y"] = 4, ["z"] = 7, ["name"] = "cloud_items:ongen_big"}, {["x"] = 11, ["y"] = 4, ["z"] = 8, ["name"] = "cloud_items:ongen_big"}, {["x"] = 11, ["y"] = 4, ["z"] = 11, ["name"] = "cloud_items:ongen_big"}, {["x"] = 11, ["y"] = 4, ["z"] = 13, ["name"] = "cloud_items:ongen_big"}, {["x"] = 11, ["y"] = 4, ["z"] = 16, ["name"] = "cloud_items:ongen_big"}, {["x"] = 11, ["y"] = 4, ["z"] = 17, ["name"] = "cloud_items:ongen_big"}, {["x"] = 11, ["y"] = 5, ["z"] = 8, ["name"] = "cloud_items:ongen_big"}, {["x"] = 11, ["y"] = 5, ["z"] = 9, ["name"] = "cloud_items:ongen_big"}, {["x"] = 11, ["y"] = 5, ["z"] = 11, ["name"] = "cloud_items:ongen_big"}, {["x"] = 11, ["y"] = 5, ["z"] = 13, ["name"] = "cloud_items:ongen_big"}, {["x"] = 11, ["y"] = 5, ["z"] = 15, ["name"] = "cloud_items:ongen_big"}, {["x"] = 11, ["y"] = 5, ["z"] = 16, ["name"] = "cloud_items:ongen_big"}, {["x"] = 11, ["y"] = 6, ["z"] = 9, ["name"] = "cloud_items:ongen_big"}, {["x"] = 11, ["y"] = 6, ["z"] = 10, ["name"] = "cloud_items:ongen_big"}, {["x"] = 11, ["y"] = 6, ["z"] = 11, ["name"] = "cloud_items:ongen_big"}, {["x"] = 11, ["y"] = 6, ["z"] = 12, ["name"] = "cloud_items:ongen_big"}, {["x"] = 11, ["y"] = 6, ["z"] = 13, ["name"] = "cloud_items:ongen_big"}, {["x"] = 11, ["y"] = 6, ["z"] = 14, ["name"] = "cloud_items:ongen_big"}, {["x"] = 11, ["y"] = 6, ["z"] = 15, ["name"] = "cloud_items:ongen_big"}, {["x"] = 12, ["y"] = 1, ["z"] = 0, ["name"] = "cloud_items:ongen_big"}, {["x"] = 12, ["y"] = 1, ["z"] = 1, ["name"] = "cloud_items:ongen_big"}, {["x"] = 12, ["y"] = 1, ["z"] = 2, ["name"] = "cloud_items:ongen_big"}, {["x"] = 12, ["y"] = 1, ["z"] = 3, ["name"] = "cloud_items:ongen_big"}, {["x"] = 12, ["y"] = 1, ["z"] = 4, ["name"] = "cloud_items:ongen_big"}, {["x"] = 12, ["y"] = 1, ["z"] = 5, ["name"] = "cloud_items:ongen_big"}, {["x"] = 12, ["y"] = 1, ["z"] = 6, ["name"] = "cloud_items:ongen_big"}, {["x"] = 12, ["y"] = 1, ["z"] = 7, ["name"] = "cloud_items:ongen_big"}, {["x"] = 12, ["y"] = 1, ["z"] = 8, ["name"] = "cloud_items:ongen_big"}, {["x"] = 12, ["y"] = 1, ["z"] = 9, ["name"] = "cloud_items:ongen_big"}, {["x"] = 12, ["y"] = 1, ["z"] = 10, ["name"] = "cloud_items:ongen_big"}, {["x"] = 12, ["y"] = 1, ["z"] = 11, ["name"] = "cloud_items:ongen_big"}, {["x"] = 12, ["y"] = 1, ["z"] = 12, ["name"] = "cloud_items:ongen_big"}, {["x"] = 12, ["y"] = 1, ["z"] = 13, ["name"] = "cloud_items:ongen_big"}, {["x"] = 12, ["y"] = 1, ["z"] = 14, ["name"] = "cloud_items:ongen_big"}, {["x"] = 12, ["y"] = 1, ["z"] = 15, ["name"] = "cloud_items:ongen_big"}, {["x"] = 12, ["y"] = 1, ["z"] = 16, ["name"] = "cloud_items:ongen_big"}, {["x"] = 12, ["y"] = 1, ["z"] = 17, ["name"] = "cloud_items:ongen_big"}, {["x"] = 12, ["y"] = 1, ["z"] = 18, ["name"] = "cloud_items:ongen_big"}, {["x"] = 12, ["y"] = 1, ["z"] = 19, ["name"] = "cloud_items:ongen_big"}, {["x"] = 12, ["y"] = 1, ["z"] = 20, ["name"] = "cloud_items:ongen_big"}, {["x"] = 12, ["y"] = 1, ["z"] = 21, ["name"] = "cloud_items:ongen_big"}, {["x"] = 12, ["y"] = 1, ["z"] = 22, ["name"] = "cloud_items:ongen_big"}, {["x"] = 12, ["y"] = 2, ["z"] = 4, ["name"] = "cloud_items:ongen_big"}, {["x"] = 12, ["y"] = 2, ["z"] = 5, ["name"] = "cloud_items:ongen_big"}, {["x"] = 12, ["y"] = 2, ["z"] = 6, ["name"] = "cloud_items:ongen_big"}, {["x"] = 12, ["y"] = 2, ["z"] = 7, ["name"] = "cloud_items:ongen_big"}, {["x"] = 12, ["y"] = 2, ["z"] = 8, ["name"] = "cloud_items:ongen_big"}, {["x"] = 12, ["y"] = 2, ["z"] = 9, ["name"] = "cloud_items:ongen_big"}, {["x"] = 12, ["y"] = 2, ["z"] = 10, ["name"] = "cloud_items:ongen_big"}, {["x"] = 12, ["y"] = 2, ["z"] = 11, ["name"] = "cloud_items:ongen_big"}, {["x"] = 12, ["y"] = 2, ["z"] = 12, ["name"] = "cloud_items:ongen_big"}, {["x"] = 12, ["y"] = 2, ["z"] = 13, ["name"] = "cloud_items:ongen_big"}, {["x"] = 12, ["y"] = 2, ["z"] = 14, ["name"] = "cloud_items:ongen_big"}, {["x"] = 12, ["y"] = 2, ["z"] = 15, ["name"] = "cloud_items:ongen_big"}, {["x"] = 12, ["y"] = 2, ["z"] = 16, ["name"] = "cloud_items:ongen_big"}, {["x"] = 12, ["y"] = 2, ["z"] = 17, ["name"] = "cloud_items:ongen_big"}, {["x"] = 12, ["y"] = 2, ["z"] = 18, ["name"] = "cloud_items:ongen_big"}, {["x"] = 12, ["y"] = 2, ["z"] = 19, ["name"] = "cloud_items:ongen_big"}, {["x"] = 12, ["y"] = 2, ["z"] = 20, ["name"] = "cloud_items:ongen_big"}, {["x"] = 12, ["y"] = 2, ["z"] = 21, ["name"] = "cloud_items:ongen_big"}, {["x"] = 12, ["y"] = 3, ["z"] = 6, ["name"] = "cloud_items:ongen_big"}, {["x"] = 12, ["y"] = 3, ["z"] = 7, ["name"] = "cloud_items:ongen_big"}, {["x"] = 12, ["y"] = 3, ["z"] = 8, ["name"] = "cloud_items:ongen_big"}, {["x"] = 12, ["y"] = 3, ["z"] = 9, ["name"] = "cloud_items:ongen_big"}, {["x"] = 12, ["y"] = 3, ["z"] = 10, ["name"] = "cloud_items:ongen_big"}, {["x"] = 12, ["y"] = 3, ["z"] = 11, ["name"] = "cloud_items:ongen_big"}, {["x"] = 12, ["y"] = 3, ["z"] = 12, ["name"] = "cloud_items:ongen_big"}, {["x"] = 12, ["y"] = 3, ["z"] = 13, ["name"] = "cloud_items:ongen_big"}, {["x"] = 12, ["y"] = 3, ["z"] = 14, ["name"] = "cloud_items:ongen_big"}, {["x"] = 12, ["y"] = 3, ["z"] = 15, ["name"] = "cloud_items:ongen_big"}, {["x"] = 12, ["y"] = 3, ["z"] = 16, ["name"] = "cloud_items:ongen_big"}, {["x"] = 12, ["y"] = 3, ["z"] = 17, ["name"] = "cloud_items:ongen_big"}, {["x"] = 12, ["y"] = 3, ["z"] = 18, ["name"] = "cloud_items:ongen_big"}, {["x"] = 12, ["y"] = 4, ["z"] = 7, ["name"] = "cloud_items:ongen_big"}, {["x"] = 12, ["y"] = 4, ["z"] = 8, ["name"] = "cloud_items:ongen_big"}, {["x"] = 12, ["y"] = 4, ["z"] = 10, ["name"] = "cloud_items:ongen_big"}, {["x"] = 12, ["y"] = 4, ["z"] = 12, ["name"] = "cloud_items:ongen_big"}, {["x"] = 12, ["y"] = 4, ["z"] = 14, ["name"] = "cloud_items:ongen_big"}, {["x"] = 12, ["y"] = 4, ["z"] = 16, ["name"] = "cloud_items:ongen_big"}, {["x"] = 12, ["y"] = 4, ["z"] = 17, ["name"] = "cloud_items:ongen_big"}, {["x"] = 12, ["y"] = 5, ["z"] = 8, ["name"] = "cloud_items:ongen_big"}, {["x"] = 12, ["y"] = 5, ["z"] = 9, ["name"] = "cloud_items:ongen_big"}, {["x"] = 12, ["y"] = 5, ["z"] = 15, ["name"] = "cloud_items:ongen_big"}, {["x"] = 12, ["y"] = 5, ["z"] = 16, ["name"] = "cloud_items:ongen_big"}, {["x"] = 12, ["y"] = 6, ["z"] = 9, ["name"] = "cloud_items:ongen_big"}, {["x"] = 12, ["y"] = 6, ["z"] = 10, ["name"] = "cloud_items:ongen_big"}, {["x"] = 12, ["y"] = 6, ["z"] = 11, ["name"] = "cloud_items:ongen_big"}, {["x"] = 12, ["y"] = 6, ["z"] = 12, ["name"] = "cloud_items:ongen_big"}, {["x"] = 12, ["y"] = 6, ["z"] = 13, ["name"] = "cloud_items:ongen_big"}, {["x"] = 12, ["y"] = 6, ["z"] = 14, ["name"] = "cloud_items:ongen_big"}, {["x"] = 12, ["y"] = 6, ["z"] = 15, ["name"] = "cloud_items:ongen_big"}, {["x"] = 13, ["y"] = 1, ["z"] = 1, ["name"] = "cloud_items:ongen_big"}, {["x"] = 13, ["y"] = 1, ["z"] = 2, ["name"] = "cloud_items:ongen_big"}, {["x"] = 13, ["y"] = 1, ["z"] = 3, ["name"] = "cloud_items:ongen_big"}, {["x"] = 13, ["y"] = 1, ["z"] = 4, ["name"] = "cloud_items:ongen_big"}, {["x"] = 13, ["y"] = 1, ["z"] = 5, ["name"] = "cloud_items:ongen_big"}, {["x"] = 13, ["y"] = 1, ["z"] = 6, ["name"] = "cloud_items:ongen_big"}, {["x"] = 13, ["y"] = 1, ["z"] = 7, ["name"] = "cloud_items:ongen_big"}, {["x"] = 13, ["y"] = 1, ["z"] = 8, ["name"] = "cloud_items:ongen_big"}, {["x"] = 13, ["y"] = 1, ["z"] = 9, ["name"] = "cloud_items:ongen_big"}, {["x"] = 13, ["y"] = 1, ["z"] = 10, ["name"] = "cloud_items:ongen_big"}, {["x"] = 13, ["y"] = 1, ["z"] = 11, ["name"] = "cloud_items:ongen_big"}, {["x"] = 13, ["y"] = 1, ["z"] = 12, ["name"] = "cloud_items:ongen_big"}, {["x"] = 13, ["y"] = 1, ["z"] = 13, ["name"] = "cloud_items:ongen_big"}, {["x"] = 13, ["y"] = 1, ["z"] = 14, ["name"] = "cloud_items:ongen_big"}, {["x"] = 13, ["y"] = 1, ["z"] = 15, ["name"] = "cloud_items:ongen_big"}, {["x"] = 13, ["y"] = 1, ["z"] = 16, ["name"] = "cloud_items:ongen_big"}, {["x"] = 13, ["y"] = 1, ["z"] = 17, ["name"] = "cloud_items:ongen_big"}, {["x"] = 13, ["y"] = 1, ["z"] = 18, ["name"] = "cloud_items:ongen_big"}, {["x"] = 13, ["y"] = 1, ["z"] = 19, ["name"] = "cloud_items:ongen_big"}, {["x"] = 13, ["y"] = 1, ["z"] = 20, ["name"] = "cloud_items:ongen_big"}, {["x"] = 13, ["y"] = 1, ["z"] = 21, ["name"] = "cloud_items:ongen_big"}, {["x"] = 13, ["y"] = 1, ["z"] = 22, ["name"] = "cloud_items:ongen_big"}, {["x"] = 13, ["y"] = 2, ["z"] = 4, ["name"] = "cloud_items:ongen_big"}, {["x"] = 13, ["y"] = 2, ["z"] = 5, ["name"] = "cloud_items:ongen_big"}, {["x"] = 13, ["y"] = 2, ["z"] = 6, ["name"] = "cloud_items:ongen_big"}, {["x"] = 13, ["y"] = 2, ["z"] = 7, ["name"] = "cloud_items:ongen_big"}, {["x"] = 13, ["y"] = 2, ["z"] = 8, ["name"] = "cloud_items:ongen_big"}, {["x"] = 13, ["y"] = 2, ["z"] = 9, ["name"] = "cloud_items:ongen_big"}, {["x"] = 13, ["y"] = 2, ["z"] = 10, ["name"] = "cloud_items:ongen_big"}, {["x"] = 13, ["y"] = 2, ["z"] = 11, ["name"] = "cloud_items:ongen_big"}, {["x"] = 13, ["y"] = 2, ["z"] = 12, ["name"] = "cloud_items:ongen_big"}, {["x"] = 13, ["y"] = 2, ["z"] = 13, ["name"] = "cloud_items:ongen_big"}, {["x"] = 13, ["y"] = 2, ["z"] = 14, ["name"] = "cloud_items:ongen_big"}, {["x"] = 13, ["y"] = 2, ["z"] = 15, ["name"] = "cloud_items:ongen_big"}, {["x"] = 13, ["y"] = 2, ["z"] = 16, ["name"] = "cloud_items:ongen_big"}, {["x"] = 13, ["y"] = 2, ["z"] = 17, ["name"] = "cloud_items:ongen_big"}, {["x"] = 13, ["y"] = 2, ["z"] = 18, ["name"] = "cloud_items:ongen_big"}, {["x"] = 13, ["y"] = 2, ["z"] = 19, ["name"] = "cloud_items:ongen_big"}, {["x"] = 13, ["y"] = 2, ["z"] = 20, ["name"] = "cloud_items:ongen_big"}, {["x"] = 13, ["y"] = 2, ["z"] = 21, ["name"] = "cloud_items:ongen_big"}, {["x"] = 13, ["y"] = 3, ["z"] = 6, ["name"] = "cloud_items:ongen_big"}, {["x"] = 13, ["y"] = 3, ["z"] = 7, ["name"] = "cloud_items:ongen_big"}, {["x"] = 13, ["y"] = 3, ["z"] = 8, ["name"] = "cloud_items:ongen_big"}, {["x"] = 13, ["y"] = 3, ["z"] = 9, ["name"] = "cloud_items:ongen_big"}, {["x"] = 13, ["y"] = 3, ["z"] = 10, ["name"] = "cloud_items:ongen_big"}, {["x"] = 13, ["y"] = 3, ["z"] = 11, ["name"] = "cloud_items:ongen_big"}, {["x"] = 13, ["y"] = 3, ["z"] = 12, ["name"] = "cloud_items:ongen_big"}, {["x"] = 13, ["y"] = 3, ["z"] = 13, ["name"] = "cloud_items:ongen_big"}, {["x"] = 13, ["y"] = 3, ["z"] = 14, ["name"] = "cloud_items:ongen_big"}, {["x"] = 13, ["y"] = 3, ["z"] = 15, ["name"] = "cloud_items:ongen_big"}, {["x"] = 13, ["y"] = 3, ["z"] = 16, ["name"] = "cloud_items:ongen_big"}, {["x"] = 13, ["y"] = 3, ["z"] = 17, ["name"] = "cloud_items:ongen_big"}, {["x"] = 13, ["y"] = 3, ["z"] = 18, ["name"] = "cloud_items:ongen_big"}, {["x"] = 13, ["y"] = 4, ["z"] = 7, ["name"] = "cloud_items:ongen_big"}, {["x"] = 13, ["y"] = 4, ["z"] = 8, ["name"] = "cloud_items:ongen_big"}, {["x"] = 13, ["y"] = 4, ["z"] = 11, ["name"] = "cloud_items:ongen_big"}, {["x"] = 13, ["y"] = 4, ["z"] = 13, ["name"] = "cloud_items:ongen_big"}, {["x"] = 13, ["y"] = 4, ["z"] = 16, ["name"] = "cloud_items:ongen_big"}, {["x"] = 13, ["y"] = 4, ["z"] = 17, ["name"] = "cloud_items:ongen_big"}, {["x"] = 13, ["y"] = 5, ["z"] = 8, ["name"] = "cloud_items:ongen_big"}, {["x"] = 13, ["y"] = 5, ["z"] = 9, ["name"] = "cloud_items:ongen_big"}, {["x"] = 13, ["y"] = 5, ["z"] = 11, ["name"] = "cloud_items:ongen_big"}, {["x"] = 13, ["y"] = 5, ["z"] = 13, ["name"] = "cloud_items:ongen_big"}, {["x"] = 13, ["y"] = 5, ["z"] = 15, ["name"] = "cloud_items:ongen_big"}, {["x"] = 13, ["y"] = 5, ["z"] = 16, ["name"] = "cloud_items:ongen_big"}, {["x"] = 13, ["y"] = 6, ["z"] = 9, ["name"] = "cloud_items:ongen_big"}, {["x"] = 13, ["y"] = 6, ["z"] = 10, ["name"] = "cloud_items:ongen_big"}, {["x"] = 13, ["y"] = 6, ["z"] = 11, ["name"] = "cloud_items:ongen_big"}, {["x"] = 13, ["y"] = 6, ["z"] = 12, ["name"] = "cloud_items:ongen_big"}, {["x"] = 13, ["y"] = 6, ["z"] = 13, ["name"] = "cloud_items:ongen_big"}, {["x"] = 13, ["y"] = 6, ["z"] = 14, ["name"] = "cloud_items:ongen_big"}, {["x"] = 13, ["y"] = 6, ["z"] = 15, ["name"] = "cloud_items:ongen_big"}, {["x"] = 14, ["y"] = 1, ["z"] = 1, ["name"] = "cloud_items:ongen_big"}, {["x"] = 14, ["y"] = 1, ["z"] = 2, ["name"] = "cloud_items:ongen_big"}, {["x"] = 14, ["y"] = 1, ["z"] = 3, ["name"] = "cloud_items:ongen_big"}, {["x"] = 14, ["y"] = 1, ["z"] = 4, ["name"] = "cloud_items:ongen_big"}, {["x"] = 14, ["y"] = 1, ["z"] = 5, ["name"] = "cloud_items:ongen_big"}, {["x"] = 14, ["y"] = 1, ["z"] = 6, ["name"] = "cloud_items:ongen_big"}, {["x"] = 14, ["y"] = 1, ["z"] = 7, ["name"] = "cloud_items:ongen_big"}, {["x"] = 14, ["y"] = 1, ["z"] = 8, ["name"] = "cloud_items:ongen_big"}, {["x"] = 14, ["y"] = 1, ["z"] = 9, ["name"] = "cloud_items:ongen_big"}, {["x"] = 14, ["y"] = 1, ["z"] = 10, ["name"] = "cloud_items:ongen_big"}, {["x"] = 14, ["y"] = 1, ["z"] = 11, ["name"] = "cloud_items:ongen_big"}, {["x"] = 14, ["y"] = 1, ["z"] = 12, ["name"] = "cloud_items:ongen_big"}, {["x"] = 14, ["y"] = 1, ["z"] = 13, ["name"] = "cloud_items:ongen_big"}, {["x"] = 14, ["y"] = 1, ["z"] = 14, ["name"] = "cloud_items:ongen_big"}, {["x"] = 14, ["y"] = 1, ["z"] = 15, ["name"] = "cloud_items:ongen_big"}, {["x"] = 14, ["y"] = 1, ["z"] = 16, ["name"] = "cloud_items:ongen_big"}, {["x"] = 14, ["y"] = 1, ["z"] = 17, ["name"] = "cloud_items:ongen_big"}, {["x"] = 14, ["y"] = 1, ["z"] = 18, ["name"] = "cloud_items:ongen_big"}, {["x"] = 14, ["y"] = 1, ["z"] = 19, ["name"] = "cloud_items:ongen_big"}, {["x"] = 14, ["y"] = 1, ["z"] = 20, ["name"] = "cloud_items:ongen_big"}, {["x"] = 14, ["y"] = 1, ["z"] = 21, ["name"] = "cloud_items:ongen_big"}, {["x"] = 14, ["y"] = 1, ["z"] = 22, ["name"] = "cloud_items:ongen_big"}, {["x"] = 14, ["y"] = 2, ["z"] = 4, ["name"] = "cloud_items:ongen_big"}, {["x"] = 14, ["y"] = 2, ["z"] = 5, ["name"] = "cloud_items:ongen_big"}, {["x"] = 14, ["y"] = 2, ["z"] = 6, ["name"] = "cloud_items:ongen_big"}, {["x"] = 14, ["y"] = 2, ["z"] = 7, ["name"] = "cloud_items:ongen_big"}, {["x"] = 14, ["y"] = 2, ["z"] = 8, ["name"] = "cloud_items:ongen_big"}, {["x"] = 14, ["y"] = 2, ["z"] = 9, ["name"] = "cloud_items:ongen_big"}, {["x"] = 14, ["y"] = 2, ["z"] = 10, ["name"] = "cloud_items:ongen_big"}, {["x"] = 14, ["y"] = 2, ["z"] = 11, ["name"] = "cloud_items:ongen_big"}, {["x"] = 14, ["y"] = 2, ["z"] = 12, ["name"] = "cloud_items:ongen_big"}, {["x"] = 14, ["y"] = 2, ["z"] = 13, ["name"] = "cloud_items:ongen_big"}, {["x"] = 14, ["y"] = 2, ["z"] = 14, ["name"] = "cloud_items:ongen_big"}, {["x"] = 14, ["y"] = 2, ["z"] = 15, ["name"] = "cloud_items:ongen_big"}, {["x"] = 14, ["y"] = 2, ["z"] = 16, ["name"] = "cloud_items:ongen_big"}, {["x"] = 14, ["y"] = 2, ["z"] = 17, ["name"] = "cloud_items:ongen_big"}, {["x"] = 14, ["y"] = 2, ["z"] = 18, ["name"] = "cloud_items:ongen_big"}, {["x"] = 14, ["y"] = 2, ["z"] = 19, ["name"] = "cloud_items:ongen_big"}, {["x"] = 14, ["y"] = 2, ["z"] = 20, ["name"] = "cloud_items:ongen_big"}, {["x"] = 14, ["y"] = 2, ["z"] = 21, ["name"] = "cloud_items:ongen_big"}, {["x"] = 14, ["y"] = 3, ["z"] = 6, ["name"] = "cloud_items:ongen_big"}, {["x"] = 14, ["y"] = 3, ["z"] = 7, ["name"] = "cloud_items:ongen_big"}, {["x"] = 14, ["y"] = 3, ["z"] = 8, ["name"] = "cloud_items:ongen_big"}, {["x"] = 14, ["y"] = 3, ["z"] = 9, ["name"] = "cloud_items:ongen_big"}, {["x"] = 14, ["y"] = 3, ["z"] = 10, ["name"] = "cloud_items:ongen_big"}, {["x"] = 14, ["y"] = 3, ["z"] = 11, ["name"] = "cloud_items:ongen_big"}, {["x"] = 14, ["y"] = 3, ["z"] = 12, ["name"] = "cloud_items:ongen_big"}, {["x"] = 14, ["y"] = 3, ["z"] = 13, ["name"] = "cloud_items:ongen_big"}, {["x"] = 14, ["y"] = 3, ["z"] = 14, ["name"] = "cloud_items:ongen_big"}, {["x"] = 14, ["y"] = 3, ["z"] = 15, ["name"] = "cloud_items:ongen_big"}, {["x"] = 14, ["y"] = 3, ["z"] = 16, ["name"] = "cloud_items:ongen_big"}, {["x"] = 14, ["y"] = 3, ["z"] = 17, ["name"] = "cloud_items:ongen_big"}, {["x"] = 14, ["y"] = 3, ["z"] = 18, ["name"] = "cloud_items:ongen_big"}, {["x"] = 14, ["y"] = 4, ["z"] = 7, ["name"] = "cloud_items:ongen_big"}, {["x"] = 14, ["y"] = 4, ["z"] = 8, ["name"] = "cloud_items:ongen_big"}, {["x"] = 14, ["y"] = 4, ["z"] = 12, ["name"] = "cloud_items:ongen_big"}, {["x"] = 14, ["y"] = 4, ["z"] = 16, ["name"] = "cloud_items:ongen_big"}, {["x"] = 14, ["y"] = 4, ["z"] = 17, ["name"] = "cloud_items:ongen_big"}, {["x"] = 14, ["y"] = 5, ["z"] = 8, ["name"] = "cloud_items:ongen_big"}, {["x"] = 14, ["y"] = 5, ["z"] = 9, ["name"] = "cloud_items:ongen_big"}, {["x"] = 14, ["y"] = 5, ["z"] = 12, ["name"] = "cloud_items:ongen_big"}, {["x"] = 14, ["y"] = 5, ["z"] = 15, ["name"] = "cloud_items:ongen_big"}, {["x"] = 14, ["y"] = 5, ["z"] = 16, ["name"] = "cloud_items:ongen_big"}, {["x"] = 14, ["y"] = 6, ["z"] = 9, ["name"] = "cloud_items:ongen_big"}, {["x"] = 14, ["y"] = 6, ["z"] = 10, ["name"] = "cloud_items:ongen_big"}, {["x"] = 14, ["y"] = 6, ["z"] = 11, ["name"] = "cloud_items:ongen_big"}, {["x"] = 14, ["y"] = 6, ["z"] = 12, ["name"] = "cloud_items:ongen_big"}, {["x"] = 14, ["y"] = 6, ["z"] = 13, ["name"] = "cloud_items:ongen_big"}, {["x"] = 14, ["y"] = 6, ["z"] = 14, ["name"] = "cloud_items:ongen_big"}, {["x"] = 14, ["y"] = 6, ["z"] = 15, ["name"] = "cloud_items:ongen_big"}, {["x"] = 15, ["y"] = 1, ["z"] = 2, ["name"] = "cloud_items:ongen_big"}, {["x"] = 15, ["y"] = 1, ["z"] = 3, ["name"] = "cloud_items:ongen_big"}, {["x"] = 15, ["y"] = 1, ["z"] = 4, ["name"] = "cloud_items:ongen_big"}, {["x"] = 15, ["y"] = 1, ["z"] = 5, ["name"] = "cloud_items:ongen_big"}, {["x"] = 15, ["y"] = 1, ["z"] = 6, ["name"] = "cloud_items:ongen_big"}, {["x"] = 15, ["y"] = 1, ["z"] = 7, ["name"] = "cloud_items:ongen_big"}, {["x"] = 15, ["y"] = 1, ["z"] = 8, ["name"] = "cloud_items:ongen_big"}, {["x"] = 15, ["y"] = 1, ["z"] = 9, ["name"] = "cloud_items:ongen_big"}, {["x"] = 15, ["y"] = 1, ["z"] = 10, ["name"] = "cloud_items:ongen_big"}, {["x"] = 15, ["y"] = 1, ["z"] = 11, ["name"] = "cloud_items:ongen_big"}, {["x"] = 15, ["y"] = 1, ["z"] = 12, ["name"] = "cloud_items:ongen_big"}, {["x"] = 15, ["y"] = 1, ["z"] = 13, ["name"] = "cloud_items:ongen_big"}, {["x"] = 15, ["y"] = 1, ["z"] = 14, ["name"] = "cloud_items:ongen_big"}, {["x"] = 15, ["y"] = 1, ["z"] = 15, ["name"] = "cloud_items:ongen_big"}, {["x"] = 15, ["y"] = 1, ["z"] = 16, ["name"] = "cloud_items:ongen_big"}, {["x"] = 15, ["y"] = 1, ["z"] = 17, ["name"] = "cloud_items:ongen_big"}, {["x"] = 15, ["y"] = 1, ["z"] = 18, ["name"] = "cloud_items:ongen_big"}, {["x"] = 15, ["y"] = 1, ["z"] = 19, ["name"] = "cloud_items:ongen_big"}, {["x"] = 15, ["y"] = 1, ["z"] = 20, ["name"] = "cloud_items:ongen_big"}, {["x"] = 15, ["y"] = 1, ["z"] = 21, ["name"] = "cloud_items:ongen_big"}, {["x"] = 15, ["y"] = 1, ["z"] = 22, ["name"] = "cloud_items:ongen_big"}, {["x"] = 15, ["y"] = 2, ["z"] = 4, ["name"] = "cloud_items:ongen_big"}, {["x"] = 15, ["y"] = 2, ["z"] = 5, ["name"] = "cloud_items:ongen_big"}, {["x"] = 15, ["y"] = 2, ["z"] = 6, ["name"] = "cloud_items:ongen_big"}, {["x"] = 15, ["y"] = 2, ["z"] = 7, ["name"] = "cloud_items:ongen_big"}, {["x"] = 15, ["y"] = 2, ["z"] = 8, ["name"] = "cloud_items:ongen_big"}, {["x"] = 15, ["y"] = 2, ["z"] = 9, ["name"] = "cloud_items:ongen_big"}, {["x"] = 15, ["y"] = 2, ["z"] = 10, ["name"] = "cloud_items:ongen_big"}, {["x"] = 15, ["y"] = 2, ["z"] = 11, ["name"] = "cloud_items:ongen_big"}, {["x"] = 15, ["y"] = 2, ["z"] = 12, ["name"] = "cloud_items:ongen_big"}, {["x"] = 15, ["y"] = 2, ["z"] = 13, ["name"] = "cloud_items:ongen_big"}, {["x"] = 15, ["y"] = 2, ["z"] = 14, ["name"] = "cloud_items:ongen_big"}, {["x"] = 15, ["y"] = 2, ["z"] = 15, ["name"] = "cloud_items:ongen_big"}, {["x"] = 15, ["y"] = 2, ["z"] = 16, ["name"] = "cloud_items:ongen_big"}, {["x"] = 15, ["y"] = 2, ["z"] = 17, ["name"] = "cloud_items:ongen_big"}, {["x"] = 15, ["y"] = 2, ["z"] = 18, ["name"] = "cloud_items:ongen_big"}, {["x"] = 15, ["y"] = 2, ["z"] = 19, ["name"] = "cloud_items:ongen_big"}, {["x"] = 15, ["y"] = 2, ["z"] = 20, ["name"] = "cloud_items:ongen_big"}, {["x"] = 15, ["y"] = 3, ["z"] = 6, ["name"] = "cloud_items:ongen_big"}, {["x"] = 15, ["y"] = 3, ["z"] = 7, ["name"] = "cloud_items:ongen_big"}, {["x"] = 15, ["y"] = 3, ["z"] = 8, ["name"] = "cloud_items:ongen_big"}, {["x"] = 15, ["y"] = 3, ["z"] = 9, ["name"] = "cloud_items:ongen_big"}, {["x"] = 15, ["y"] = 3, ["z"] = 10, ["name"] = "cloud_items:ongen_big"}, {["x"] = 15, ["y"] = 3, ["z"] = 11, ["name"] = "cloud_items:ongen_big"}, {["x"] = 15, ["y"] = 3, ["z"] = 12, ["name"] = "cloud_items:ongen_big"}, {["x"] = 15, ["y"] = 3, ["z"] = 13, ["name"] = "cloud_items:ongen_big"}, {["x"] = 15, ["y"] = 3, ["z"] = 14, ["name"] = "cloud_items:ongen_big"}, {["x"] = 15, ["y"] = 3, ["z"] = 15, ["name"] = "cloud_items:ongen_big"}, {["x"] = 15, ["y"] = 3, ["z"] = 16, ["name"] = "cloud_items:ongen_big"}, {["x"] = 15, ["y"] = 3, ["z"] = 17, ["name"] = "cloud_items:ongen_big"}, {["x"] = 15, ["y"] = 3, ["z"] = 18, ["name"] = "cloud_items:ongen_big"}, {["x"] = 15, ["y"] = 4, ["z"] = 7, ["name"] = "cloud_items:ongen_big"}, {["x"] = 15, ["y"] = 4, ["z"] = 8, ["name"] = "cloud_items:ongen_big"}, {["x"] = 15, ["y"] = 4, ["z"] = 16, ["name"] = "cloud_items:ongen_big"}, {["x"] = 15, ["y"] = 4, ["z"] = 17, ["name"] = "cloud_items:ongen_big"}, {["x"] = 15, ["y"] = 5, ["z"] = 8, ["name"] = "cloud_items:ongen_big"}, {["x"] = 15, ["y"] = 5, ["z"] = 9, ["name"] = "cloud_items:ongen_big"}, {["x"] = 15, ["y"] = 5, ["z"] = 10, ["name"] = "cloud_items:ongen_big"}, {["x"] = 15, ["y"] = 5, ["z"] = 11, ["name"] = "cloud_items:ongen_big"}, {["x"] = 15, ["y"] = 5, ["z"] = 12, ["name"] = "cloud_items:ongen_big"}, {["x"] = 15, ["y"] = 5, ["z"] = 13, ["name"] = "cloud_items:ongen_big"}, {["x"] = 15, ["y"] = 5, ["z"] = 14, ["name"] = "cloud_items:ongen_big"}, {["x"] = 15, ["y"] = 5, ["z"] = 15, ["name"] = "cloud_items:ongen_big"}, {["x"] = 15, ["y"] = 5, ["z"] = 16, ["name"] = "cloud_items:ongen_big"}, {["x"] = 15, ["y"] = 6, ["z"] = 10, ["name"] = "cloud_items:ongen_big"}, {["x"] = 15, ["y"] = 6, ["z"] = 11, ["name"] = "cloud_items:ongen_big"}, {["x"] = 15, ["y"] = 6, ["z"] = 12, ["name"] = "cloud_items:ongen_big"}, {["x"] = 15, ["y"] = 6, ["z"] = 13, ["name"] = "cloud_items:ongen_big"}, {["x"] = 15, ["y"] = 6, ["z"] = 14, ["name"] = "cloud_items:ongen_big"}, {["x"] = 16, ["y"] = 1, ["z"] = 3, ["name"] = "cloud_items:ongen_big"}, {["x"] = 16, ["y"] = 1, ["z"] = 4, ["name"] = "cloud_items:ongen_big"}, {["x"] = 16, ["y"] = 1, ["z"] = 5, ["name"] = "cloud_items:ongen_big"}, {["x"] = 16, ["y"] = 1, ["z"] = 6, ["name"] = "cloud_items:ongen_big"}, {["x"] = 16, ["y"] = 1, ["z"] = 7, ["name"] = "cloud_items:ongen_big"}, {["x"] = 16, ["y"] = 1, ["z"] = 8, ["name"] = "cloud_items:ongen_big"}, {["x"] = 16, ["y"] = 1, ["z"] = 9, ["name"] = "cloud_items:ongen_big"}, {["x"] = 16, ["y"] = 1, ["z"] = 10, ["name"] = "cloud_items:ongen_big"}, {["x"] = 16, ["y"] = 1, ["z"] = 11, ["name"] = "cloud_items:ongen_big"}, {["x"] = 16, ["y"] = 1, ["z"] = 12, ["name"] = "cloud_items:ongen_big"}, {["x"] = 16, ["y"] = 1, ["z"] = 13, ["name"] = "cloud_items:ongen_big"}, {["x"] = 16, ["y"] = 1, ["z"] = 14, ["name"] = "cloud_items:ongen_big"}, {["x"] = 16, ["y"] = 1, ["z"] = 15, ["name"] = "cloud_items:ongen_big"}, {["x"] = 16, ["y"] = 1, ["z"] = 16, ["name"] = "cloud_items:ongen_big"}, {["x"] = 16, ["y"] = 1, ["z"] = 17, ["name"] = "cloud_items:ongen_big"}, {["x"] = 16, ["y"] = 1, ["z"] = 18, ["name"] = "cloud_items:ongen_big"}, {["x"] = 16, ["y"] = 1, ["z"] = 19, ["name"] = "cloud_items:ongen_big"}, {["x"] = 16, ["y"] = 1, ["z"] = 20, ["name"] = "cloud_items:ongen_big"}, {["x"] = 16, ["y"] = 1, ["z"] = 21, ["name"] = "cloud_items:ongen_big"}, {["x"] = 16, ["y"] = 2, ["z"] = 4, ["name"] = "cloud_items:ongen_big"}, {["x"] = 16, ["y"] = 2, ["z"] = 5, ["name"] = "cloud_items:ongen_big"}, {["x"] = 16, ["y"] = 2, ["z"] = 6, ["name"] = "cloud_items:ongen_big"}, {["x"] = 16, ["y"] = 2, ["z"] = 7, ["name"] = "cloud_items:ongen_big"}, {["x"] = 16, ["y"] = 2, ["z"] = 8, ["name"] = "cloud_items:ongen_big"}, {["x"] = 16, ["y"] = 2, ["z"] = 9, ["name"] = "cloud_items:ongen_big"}, {["x"] = 16, ["y"] = 2, ["z"] = 10, ["name"] = "cloud_items:ongen_big"}, {["x"] = 16, ["y"] = 2, ["z"] = 11, ["name"] = "cloud_items:ongen_big"}, {["x"] = 16, ["y"] = 2, ["z"] = 12, ["name"] = "cloud_items:ongen_big"}, {["x"] = 16, ["y"] = 2, ["z"] = 13, ["name"] = "cloud_items:ongen_big"}, {["x"] = 16, ["y"] = 2, ["z"] = 14, ["name"] = "cloud_items:ongen_big"}, {["x"] = 16, ["y"] = 2, ["z"] = 15, ["name"] = "cloud_items:ongen_big"}, {["x"] = 16, ["y"] = 2, ["z"] = 16, ["name"] = "cloud_items:ongen_big"}, {["x"] = 16, ["y"] = 2, ["z"] = 17, ["name"] = "cloud_items:ongen_big"}, {["x"] = 16, ["y"] = 2, ["z"] = 18, ["name"] = "cloud_items:ongen_big"}, {["x"] = 16, ["y"] = 2, ["z"] = 19, ["name"] = "cloud_items:ongen_big"}, {["x"] = 16, ["y"] = 3, ["z"] = 6, ["name"] = "cloud_items:ongen_big"}, {["x"] = 16, ["y"] = 3, ["z"] = 7, ["name"] = "cloud_items:ongen_big"}, {["x"] = 16, ["y"] = 3, ["z"] = 8, ["name"] = "cloud_items:ongen_big"}, {["x"] = 16, ["y"] = 3, ["z"] = 9, ["name"] = "cloud_items:ongen_big"}, {["x"] = 16, ["y"] = 3, ["z"] = 10, ["name"] = "cloud_items:ongen_big"}, {["x"] = 16, ["y"] = 3, ["z"] = 11, ["name"] = "cloud_items:ongen_big"}, {["x"] = 16, ["y"] = 3, ["z"] = 12, ["name"] = "cloud_items:ongen_big"}, {["x"] = 16, ["y"] = 3, ["z"] = 13, ["name"] = "cloud_items:ongen_big"}, {["x"] = 16, ["y"] = 3, ["z"] = 14, ["name"] = "cloud_items:ongen_big"}, {["x"] = 16, ["y"] = 3, ["z"] = 15, ["name"] = "cloud_items:ongen_big"}, {["x"] = 16, ["y"] = 3, ["z"] = 16, ["name"] = "cloud_items:ongen_big"}, {["x"] = 16, ["y"] = 3, ["z"] = 17, ["name"] = "cloud_items:ongen_big"}, {["x"] = 16, ["y"] = 3, ["z"] = 18, ["name"] = "cloud_items:ongen_big"}, {["x"] = 16, ["y"] = 4, ["z"] = 7, ["name"] = "cloud_items:ongen_big"}, {["x"] = 16, ["y"] = 4, ["z"] = 8, ["name"] = "cloud_items:ongen_big"}, {["x"] = 16, ["y"] = 4, ["z"] = 9, ["name"] = "cloud_items:ongen_big"}, {["x"] = 16, ["y"] = 4, ["z"] = 10, ["name"] = "cloud_items:ongen_big"}, {["x"] = 16, ["y"] = 4, ["z"] = 11, ["name"] = "cloud_items:ongen_big"}, {["x"] = 16, ["y"] = 4, ["z"] = 12, ["name"] = "cloud_items:ongen_big"}, {["x"] = 16, ["y"] = 4, ["z"] = 13, ["name"] = "cloud_items:ongen_big"}, {["x"] = 16, ["y"] = 4, ["z"] = 14, ["name"] = "cloud_items:ongen_big"}, {["x"] = 16, ["y"] = 4, ["z"] = 15, ["name"] = "cloud_items:ongen_big"}, {["x"] = 16, ["y"] = 4, ["z"] = 16, ["name"] = "cloud_items:ongen_big"}, {["x"] = 16, ["y"] = 4, ["z"] = 17, ["name"] = "cloud_items:ongen_big"}, {["x"] = 16, ["y"] = 5, ["z"] = 9, ["name"] = "cloud_items:ongen_big"}, {["x"] = 16, ["y"] = 5, ["z"] = 10, ["name"] = "cloud_items:ongen_big"}, {["x"] = 16, ["y"] = 5, ["z"] = 11, ["name"] = "cloud_items:ongen_big"}, {["x"] = 16, ["y"] = 5, ["z"] = 12, ["name"] = "cloud_items:ongen_big"}, {["x"] = 16, ["y"] = 5, ["z"] = 13, ["name"] = "cloud_items:ongen_big"}, {["x"] = 16, ["y"] = 5, ["z"] = 14, ["name"] = "cloud_items:ongen_big"}, {["x"] = 16, ["y"] = 5, ["z"] = 15, ["name"] = "cloud_items:ongen_big"}, {["x"] = 17, ["y"] = 1, ["z"] = 3, ["name"] = "cloud_items:ongen_big"}, {["x"] = 17, ["y"] = 1, ["z"] = 4, ["name"] = "cloud_items:ongen_big"}, {["x"] = 17, ["y"] = 1, ["z"] = 5, ["name"] = "cloud_items:ongen_big"}, {["x"] = 17, ["y"] = 1, ["z"] = 6, ["name"] = "cloud_items:ongen_big"}, {["x"] = 17, ["y"] = 1, ["z"] = 7, ["name"] = "cloud_items:ongen_big"}, {["x"] = 17, ["y"] = 1, ["z"] = 8, ["name"] = "cloud_items:ongen_big"}, {["x"] = 17, ["y"] = 1, ["z"] = 9, ["name"] = "cloud_items:ongen_big"}, {["x"] = 17, ["y"] = 1, ["z"] = 10, ["name"] = "cloud_items:ongen_big"}, {["x"] = 17, ["y"] = 1, ["z"] = 11, ["name"] = "cloud_items:ongen_big"}, {["x"] = 17, ["y"] = 1, ["z"] = 12, ["name"] = "cloud_items:ongen_big"}, {["x"] = 17, ["y"] = 1, ["z"] = 13, ["name"] = "cloud_items:ongen_big"}, {["x"] = 17, ["y"] = 1, ["z"] = 14, ["name"] = "cloud_items:ongen_big"}, {["x"] = 17, ["y"] = 1, ["z"] = 15, ["name"] = "cloud_items:ongen_big"}, {["x"] = 17, ["y"] = 1, ["z"] = 16, ["name"] = "cloud_items:ongen_big"}, {["x"] = 17, ["y"] = 1, ["z"] = 17, ["name"] = "cloud_items:ongen_big"}, {["x"] = 17, ["y"] = 1, ["z"] = 18, ["name"] = "cloud_items:ongen_big"}, {["x"] = 17, ["y"] = 1, ["z"] = 19, ["name"] = "cloud_items:ongen_big"}, {["x"] = 17, ["y"] = 1, ["z"] = 20, ["name"] = "cloud_items:ongen_big"}, {["x"] = 17, ["y"] = 2, ["z"] = 4, ["name"] = "cloud_items:ongen_big"}, {["x"] = 17, ["y"] = 2, ["z"] = 5, ["name"] = "cloud_items:ongen_big"}, {["x"] = 17, ["y"] = 2, ["z"] = 6, ["name"] = "cloud_items:ongen_big"}, {["x"] = 17, ["y"] = 2, ["z"] = 7, ["name"] = "cloud_items:ongen_big"}, {["x"] = 17, ["y"] = 2, ["z"] = 8, ["name"] = "cloud_items:ongen_big"}, {["x"] = 17, ["y"] = 2, ["z"] = 9, ["name"] = "cloud_items:ongen_big"}, {["x"] = 17, ["y"] = 2, ["z"] = 10, ["name"] = "cloud_items:ongen_big"}, {["x"] = 17, ["y"] = 2, ["z"] = 11, ["name"] = "cloud_items:ongen_big"}, {["x"] = 17, ["y"] = 2, ["z"] = 12, ["name"] = "cloud_items:ongen_big"}, {["x"] = 17, ["y"] = 2, ["z"] = 13, ["name"] = "cloud_items:ongen_big"}, {["x"] = 17, ["y"] = 2, ["z"] = 14, ["name"] = "cloud_items:ongen_big"}, {["x"] = 17, ["y"] = 2, ["z"] = 15, ["name"] = "cloud_items:ongen_big"}, {["x"] = 17, ["y"] = 2, ["z"] = 16, ["name"] = "cloud_items:ongen_big"}, {["x"] = 17, ["y"] = 2, ["z"] = 17, ["name"] = "cloud_items:ongen_big"}, {["x"] = 17, ["y"] = 2, ["z"] = 18, ["name"] = "cloud_items:ongen_big"}, {["x"] = 17, ["y"] = 2, ["z"] = 19, ["name"] = "cloud_items:ongen_big"}, {["x"] = 17, ["y"] = 3, ["z"] = 6, ["name"] = "cloud_items:ongen_big"}, {["x"] = 17, ["y"] = 3, ["z"] = 7, ["name"] = "cloud_items:ongen_big"}, {["x"] = 17, ["y"] = 3, ["z"] = 8, ["name"] = "cloud_items:ongen_big"}, {["x"] = 17, ["y"] = 3, ["z"] = 9, ["name"] = "cloud_items:ongen_big"}, {["x"] = 17, ["y"] = 3, ["z"] = 10, ["name"] = "cloud_items:ongen_big"}, {["x"] = 17, ["y"] = 3, ["z"] = 11, ["name"] = "cloud_items:ongen_big"}, {["x"] = 17, ["y"] = 3, ["z"] = 12, ["name"] = "cloud_items:ongen_big"}, {["x"] = 17, ["y"] = 3, ["z"] = 13, ["name"] = "cloud_items:ongen_big"}, {["x"] = 17, ["y"] = 3, ["z"] = 14, ["name"] = "cloud_items:ongen_big"}, {["x"] = 17, ["y"] = 3, ["z"] = 15, ["name"] = "cloud_items:ongen_big"}, {["x"] = 17, ["y"] = 3, ["z"] = 16, ["name"] = "cloud_items:ongen_big"}, {["x"] = 17, ["y"] = 3, ["z"] = 17, ["name"] = "cloud_items:ongen_big"}, {["x"] = 17, ["y"] = 3, ["z"] = 18, ["name"] = "cloud_items:ongen_big"}, {["x"] = 17, ["y"] = 4, ["z"] = 7, ["name"] = "cloud_items:ongen_big"}, {["x"] = 17, ["y"] = 4, ["z"] = 8, ["name"] = "cloud_items:ongen_big"}, {["x"] = 17, ["y"] = 4, ["z"] = 9, ["name"] = "cloud_items:ongen_big"}, {["x"] = 17, ["y"] = 4, ["z"] = 10, ["name"] = "cloud_items:ongen_big"}, {["x"] = 17, ["y"] = 4, ["z"] = 11, ["name"] = "cloud_items:ongen_big"}, {["x"] = 17, ["y"] = 4, ["z"] = 12, ["name"] = "cloud_items:ongen_big"}, {["x"] = 17, ["y"] = 4, ["z"] = 13, ["name"] = "cloud_items:ongen_big"}, {["x"] = 17, ["y"] = 4, ["z"] = 14, ["name"] = "cloud_items:ongen_big"}, {["x"] = 17, ["y"] = 4, ["z"] = 15, ["name"] = "cloud_items:ongen_big"}, {["x"] = 17, ["y"] = 4, ["z"] = 16, ["name"] = "cloud_items:ongen_big"}, {["x"] = 17, ["y"] = 4, ["z"] = 17, ["name"] = "cloud_items:ongen_big"}, {["x"] = 18, ["y"] = 1, ["z"] = 3, ["name"] = "cloud_items:ongen_big"}, {["x"] = 18, ["y"] = 1, ["z"] = 4, ["name"] = "cloud_items:ongen_big"}, {["x"] = 18, ["y"] = 1, ["z"] = 5, ["name"] = "cloud_items:ongen_big"}, {["x"] = 18, ["y"] = 1, ["z"] = 6, ["name"] = "cloud_items:ongen_big"}, {["x"] = 18, ["y"] = 1, ["z"] = 7, ["name"] = "cloud_items:ongen_big"}, {["x"] = 18, ["y"] = 1, ["z"] = 8, ["name"] = "cloud_items:ongen_big"}, {["x"] = 18, ["y"] = 1, ["z"] = 9, ["name"] = "cloud_items:ongen_big"}, {["x"] = 18, ["y"] = 1, ["z"] = 10, ["name"] = "cloud_items:ongen_big"}, {["x"] = 18, ["y"] = 1, ["z"] = 11, ["name"] = "cloud_items:ongen_big"}, {["x"] = 18, ["y"] = 1, ["z"] = 12, ["name"] = "cloud_items:ongen_big"}, {["x"] = 18, ["y"] = 1, ["z"] = 13, ["name"] = "cloud_items:ongen_big"}, {["x"] = 18, ["y"] = 1, ["z"] = 14, ["name"] = "cloud_items:ongen_big"}, {["x"] = 18, ["y"] = 1, ["z"] = 15, ["name"] = "cloud_items:ongen_big"}, {["x"] = 18, ["y"] = 1, ["z"] = 16, ["name"] = "cloud_items:ongen_big"}, {["x"] = 18, ["y"] = 1, ["z"] = 17, ["name"] = "cloud_items:ongen_big"}, {["x"] = 18, ["y"] = 1, ["z"] = 18, ["name"] = "cloud_items:ongen_big"}, {["x"] = 18, ["y"] = 1, ["z"] = 19, ["name"] = "cloud_items:ongen_big"}, {["x"] = 18, ["y"] = 1, ["z"] = 20, ["name"] = "cloud_items:ongen_big"}, {["x"] = 18, ["y"] = 2, ["z"] = 5, ["name"] = "cloud_items:ongen_big"}, {["x"] = 18, ["y"] = 2, ["z"] = 6, ["name"] = "cloud_items:ongen_big"}, {["x"] = 18, ["y"] = 2, ["z"] = 7, ["name"] = "cloud_items:ongen_big"}, {["x"] = 18, ["y"] = 2, ["z"] = 8, ["name"] = "cloud_items:ongen_big"}, {["x"] = 18, ["y"] = 2, ["z"] = 9, ["name"] = "cloud_items:ongen_big"}, {["x"] = 18, ["y"] = 2, ["z"] = 10, ["name"] = "cloud_items:ongen_big"}, {["x"] = 18, ["y"] = 2, ["z"] = 11, ["name"] = "cloud_items:ongen_big"}, {["x"] = 18, ["y"] = 2, ["z"] = 12, ["name"] = "cloud_items:ongen_big"}, {["x"] = 18, ["y"] = 2, ["z"] = 13, ["name"] = "cloud_items:ongen_big"}, {["x"] = 18, ["y"] = 2, ["z"] = 14, ["name"] = "cloud_items:ongen_big"}, {["x"] = 18, ["y"] = 2, ["z"] = 15, ["name"] = "cloud_items:ongen_big"}, {["x"] = 18, ["y"] = 2, ["z"] = 16, ["name"] = "cloud_items:ongen_big"}, {["x"] = 18, ["y"] = 2, ["z"] = 17, ["name"] = "cloud_items:ongen_big"}, {["x"] = 18, ["y"] = 2, ["z"] = 18, ["name"] = "cloud_items:ongen_big"}, {["x"] = 18, ["y"] = 2, ["z"] = 19, ["name"] = "cloud_items:ongen_big"}, {["x"] = 18, ["y"] = 3, ["z"] = 6, ["name"] = "cloud_items:ongen_big"}, {["x"] = 18, ["y"] = 3, ["z"] = 7, ["name"] = "cloud_items:ongen_big"}, {["x"] = 18, ["y"] = 3, ["z"] = 8, ["name"] = "cloud_items:ongen_big"}, {["x"] = 18, ["y"] = 3, ["z"] = 9, ["name"] = "cloud_items:ongen_big"}, {["x"] = 18, ["y"] = 3, ["z"] = 10, ["name"] = "cloud_items:ongen_big"}, {["x"] = 18, ["y"] = 3, ["z"] = 11, ["name"] = "cloud_items:ongen_big"}, {["x"] = 18, ["y"] = 3, ["z"] = 12, ["name"] = "cloud_items:ongen_big"}, {["x"] = 18, ["y"] = 3, ["z"] = 13, ["name"] = "cloud_items:ongen_big"}, {["x"] = 18, ["y"] = 3, ["z"] = 14, ["name"] = "cloud_items:ongen_big"}, {["x"] = 18, ["y"] = 3, ["z"] = 15, ["name"] = "cloud_items:ongen_big"}, {["x"] = 18, ["y"] = 3, ["z"] = 16, ["name"] = "cloud_items:ongen_big"}, {["x"] = 18, ["y"] = 3, ["z"] = 17, ["name"] = "cloud_items:ongen_big"}, {["x"] = 18, ["y"] = 3, ["z"] = 18, ["name"] = "cloud_items:ongen_big"}, {["x"] = 19, ["y"] = 1, ["z"] = 4, ["name"] = "cloud_items:ongen_big"}, {["x"] = 19, ["y"] = 1, ["z"] = 5, ["name"] = "cloud_items:ongen_big"}, {["x"] = 19, ["y"] = 1, ["z"] = 6, ["name"] = "cloud_items:ongen_big"}, {["x"] = 19, ["y"] = 1, ["z"] = 7, ["name"] = "cloud_items:ongen_big"}, {["x"] = 19, ["y"] = 1, ["z"] = 8, ["name"] = "cloud_items:ongen_big"}, {["x"] = 19, ["y"] = 1, ["z"] = 9, ["name"] = "cloud_items:ongen_big"}, {["x"] = 19, ["y"] = 1, ["z"] = 10, ["name"] = "cloud_items:ongen_big"}, {["x"] = 19, ["y"] = 1, ["z"] = 11, ["name"] = "cloud_items:ongen_big"}, {["x"] = 19, ["y"] = 1, ["z"] = 12, ["name"] = "cloud_items:ongen_big"}, {["x"] = 19, ["y"] = 1, ["z"] = 13, ["name"] = "cloud_items:ongen_big"}, {["x"] = 19, ["y"] = 1, ["z"] = 14, ["name"] = "cloud_items:ongen_big"}, {["x"] = 19, ["y"] = 1, ["z"] = 15, ["name"] = "cloud_items:ongen_big"}, {["x"] = 19, ["y"] = 1, ["z"] = 16, ["name"] = "cloud_items:ongen_big"}, {["x"] = 19, ["y"] = 1, ["z"] = 17, ["name"] = "cloud_items:ongen_big"}, {["x"] = 19, ["y"] = 1, ["z"] = 18, ["name"] = "cloud_items:ongen_big"}, {["x"] = 19, ["y"] = 1, ["z"] = 19, ["name"] = "cloud_items:ongen_big"}, {["x"] = 19, ["y"] = 1, ["z"] = 20, ["name"] = "cloud_items:ongen_big"}, {["x"] = 19, ["y"] = 2, ["z"] = 5, ["name"] = "cloud_items:ongen_big"}, {["x"] = 19, ["y"] = 2, ["z"] = 6, ["name"] = "cloud_items:ongen_big"}, {["x"] = 19, ["y"] = 2, ["z"] = 7, ["name"] = "cloud_items:ongen_big"}, {["x"] = 19, ["y"] = 2, ["z"] = 8, ["name"] = "cloud_items:ongen_big"}, {["x"] = 19, ["y"] = 2, ["z"] = 9, ["name"] = "cloud_items:ongen_big"}, {["x"] = 19, ["y"] = 2, ["z"] = 10, ["name"] = "cloud_items:ongen_big"}, {["x"] = 19, ["y"] = 2, ["z"] = 11, ["name"] = "cloud_items:ongen_big"}, {["x"] = 19, ["y"] = 2, ["z"] = 12, ["name"] = "cloud_items:ongen_big"}, {["x"] = 19, ["y"] = 2, ["z"] = 13, ["name"] = "cloud_items:ongen_big"}, {["x"] = 19, ["y"] = 2, ["z"] = 14, ["name"] = "cloud_items:ongen_big"}, {["x"] = 19, ["y"] = 2, ["z"] = 15, ["name"] = "cloud_items:ongen_big"}, {["x"] = 19, ["y"] = 2, ["z"] = 16, ["name"] = "cloud_items:ongen_big"}, {["x"] = 19, ["y"] = 2, ["z"] = 17, ["name"] = "cloud_items:ongen_big"}, {["x"] = 19, ["y"] = 2, ["z"] = 18, ["name"] = "cloud_items:ongen_big"}, {["x"] = 19, ["y"] = 2, ["z"] = 19, ["name"] = "cloud_items:ongen_big"}, {["x"] = 20, ["y"] = 1, ["z"] = 5, ["name"] = "cloud_items:ongen_big"}, {["x"] = 20, ["y"] = 1, ["z"] = 6, ["name"] = "cloud_items:ongen_big"}, {["x"] = 20, ["y"] = 1, ["z"] = 7, ["name"] = "cloud_items:ongen_big"}, {["x"] = 20, ["y"] = 1, ["z"] = 8, ["name"] = "cloud_items:ongen_big"}, {["x"] = 20, ["y"] = 1, ["z"] = 9, ["name"] = "cloud_items:ongen_big"}, {["x"] = 20, ["y"] = 1, ["z"] = 10, ["name"] = "cloud_items:ongen_big"}, {["x"] = 20, ["y"] = 1, ["z"] = 11, ["name"] = "cloud_items:ongen_big"}, {["x"] = 20, ["y"] = 1, ["z"] = 12, ["name"] = "cloud_items:ongen_big"}, {["x"] = 20, ["y"] = 1, ["z"] = 13, ["name"] = "cloud_items:ongen_big"}, {["x"] = 20, ["y"] = 1, ["z"] = 14, ["name"] = "cloud_items:ongen_big"}, {["x"] = 20, ["y"] = 1, ["z"] = 15, ["name"] = "cloud_items:ongen_big"}, {["x"] = 20, ["y"] = 1, ["z"] = 16, ["name"] = "cloud_items:ongen_big"}, {["x"] = 20, ["y"] = 1, ["z"] = 17, ["name"] = "cloud_items:ongen_big"}, {["x"] = 20, ["y"] = 1, ["z"] = 18, ["name"] = "cloud_items:ongen_big"}, {["x"] = 20, ["y"] = 1, ["z"] = 19, ["name"] = "cloud_items:ongen_big"}, {["x"] = 21, ["y"] = 1, ["z"] = 7, ["name"] = "cloud_items:ongen_big"}, {["x"] = 21, ["y"] = 1, ["z"] = 8, ["name"] = "cloud_items:ongen_big"}, {["x"] = 21, ["y"] = 1, ["z"] = 9, ["name"] = "cloud_items:ongen_big"}, {["x"] = 21, ["y"] = 1, ["z"] = 10, ["name"] = "cloud_items:ongen_big"}, {["x"] = 21, ["y"] = 1, ["z"] = 11, ["name"] = "cloud_items:ongen_big"}, {["x"] = 21, ["y"] = 1, ["z"] = 12, ["name"] = "cloud_items:ongen_big"}, {["x"] = 21, ["y"] = 1, ["z"] = 13, ["name"] = "cloud_items:ongen_big"}, {["x"] = 21, ["y"] = 1, ["z"] = 14, ["name"] = "cloud_items:ongen_big"}, {["x"] = 21, ["y"] = 1, ["z"] = 15, ["name"] = "cloud_items:ongen_big"}, {["x"] = 21, ["y"] = 1, ["z"] = 16, ["name"] = "cloud_items:ongen_big"}, {["x"] = 21, ["y"] = 1, ["z"] = 17, ["name"] = "cloud_items:ongen_big"}}