return {{["x"] = 0, ["y"] = 1, ["z"] = 4, ["name"] = "cloud_items:ongen_small"}, {["x"] = 0, ["y"] = 1, ["z"] = 5, ["name"] = "cloud_items:ongen_small"}, {["x"] = 0, ["y"] = 1, ["z"] = 6, ["name"] = "cloud_items:ongen_small"}, {["x"] = 0, ["y"] = 1, ["z"] = 7, ["name"] = "cloud_items:ongen_small"}, {["x"] = 0, ["y"] = 1, ["z"] = 8, ["name"] = "cloud_items:ongen_small"}, {["x"] = 0, ["y"] = 1, ["z"] = 9, ["name"] = "cloud_items:ongen_small"}, {["x"] = 1, ["y"] = 1, ["z"] = 3, ["name"] = "cloud_items:ongen_small"}, {["x"] = 1, ["y"] = 1, ["z"] = 4, ["name"] = "cloud_items:ongen_small"}, {["x"] = 1, ["y"] = 1, ["z"] = 5, ["name"] = "cloud_items:ongen_small"}, {["x"] = 1, ["y"] = 1, ["z"] = 6, ["name"] = "cloud_items:ongen_small"}, {["x"] = 1, ["y"] = 1, ["z"] = 7, ["name"] = "cloud_items:ongen_small"}, {["x"] = 1, ["y"] = 1, ["z"] = 8, ["name"] = "cloud_items:ongen_small"}, {["x"] = 1, ["y"] = 1, ["z"] = 9, ["name"] = "cloud_items:ongen_small"}, {["x"] = 1, ["y"] = 2, ["z"] = 4, ["name"] = "cloud_items:ongen_small"}, {["x"] = 1, ["y"] = 2, ["z"] = 5, ["name"] = "cloud_items:ongen_small"}, {["x"] = 1, ["y"] = 2, ["z"] = 6, ["name"] = "cloud_items:ongen_small"}, {["x"] = 1, ["y"] = 2, ["z"] = 7, ["name"] = "cloud_items:ongen_small"}, {["x"] = 1, ["y"] = 2, ["z"] = 8, ["name"] = "cloud_items:ongen_small"}, {["x"] = 2, ["y"] = 1, ["z"] = 2, ["name"] = "cloud_items:ongen_small"}, {["x"] = 2, ["y"] = 1, ["z"] = 3, ["name"] = "cloud_items:ongen_small"}, {["x"] = 2, ["y"] = 1, ["z"] = 4, ["name"] = "cloud_items:ongen_small"}, {["x"] = 2, ["y"] = 1, ["z"] = 5, ["name"] = "cloud_items:ongen_small"}, {["x"] = 2, ["y"] = 1, ["z"] = 6, ["name"] = "cloud_items:ongen_small"}, {["x"] = 2, ["y"] = 1, ["z"] = 7, ["name"] = "cloud_items:ongen_small"}, {["x"] = 2, ["y"] = 1, ["z"] = 8, ["name"] = "cloud_items:ongen_small"}, {["x"] = 2, ["y"] = 1, ["z"] = 9, ["name"] = "cloud_items:ongen_small"}, {["x"] = 2, ["y"] = 1, ["z"] = 10, ["name"] = "cloud_items:ongen_small"}, {["x"] = 2, ["y"] = 1, ["z"] = 11, ["name"] = "cloud_items:ongen_small"}, {["x"] = 2, ["y"] = 2, ["z"] = 3, ["name"] = "cloud_items:ongen_small"}, {["x"] = 2, ["y"] = 2, ["z"] = 4, ["name"] = "cloud_items:ongen_small"}, {["x"] = 2, ["y"] = 2, ["z"] = 5, ["name"] = "cloud_items:ongen_small"}, {["x"] = 2, ["y"] = 2, ["z"] = 6, ["name"] = "cloud_items:ongen_small"}, {["x"] = 2, ["y"] = 2, ["z"] = 7, ["name"] = "cloud_items:ongen_small"}, {["x"] = 2, ["y"] = 2, ["z"] = 8, ["name"] = "cloud_items:ongen_small"}, {["x"] = 2, ["y"] = 2, ["z"] = 9, ["name"] = "cloud_items:ongen_small"}, {["x"] = 2, ["y"] = 3, ["z"] = 4, ["name"] = "cloud_items:ongen_small"}, {["x"] = 2, ["y"] = 3, ["z"] = 5, ["name"] = "cloud_items:ongen_small"}, {["x"] = 2, ["y"] = 3, ["z"] = 6, ["name"] = "cloud_items:ongen_small"}, {["x"] = 2, ["y"] = 3, ["z"] = 7, ["name"] = "cloud_items:ongen_small"}, {["x"] = 2, ["y"] = 3, ["z"] = 8, ["name"] = "cloud_items:ongen_small"}, {["x"] = 3, ["y"] = 1, ["z"] = 0, ["name"] = "cloud_items:ongen_small"}, {["x"] = 3, ["y"] = 1, ["z"] = 1, ["name"] = "cloud_items:ongen_small"}, {["x"] = 3, ["y"] = 1, ["z"] = 2, ["name"] = "cloud_items:ongen_small"}, {["x"] = 3, ["y"] = 1, ["z"] = 3, ["name"] = "cloud_items:ongen_small"}, {["x"] = 3, ["y"] = 1, ["z"] = 4, ["name"] = "cloud_items:ongen_small"}, {["x"] = 3, ["y"] = 1, ["z"] = 5, ["name"] = "cloud_items:ongen_small"}, {["x"] = 3, ["y"] = 1, ["z"] = 6, ["name"] = "cloud_items:ongen_small"}, {["x"] = 3, ["y"] = 1, ["z"] = 7, ["name"] = "cloud_items:ongen_small"}, {["x"] = 3, ["y"] = 1, ["z"] = 8, ["name"] = "cloud_items:ongen_small"}, {["x"] = 3, ["y"] = 1, ["z"] = 9, ["name"] = "cloud_items:ongen_small"}, {["x"] = 3, ["y"] = 1, ["z"] = 10, ["name"] = "cloud_items:ongen_small"}, {["x"] = 3, ["y"] = 1, ["z"] = 11, ["name"] = "cloud_items:ongen_small"}, {["x"] = 3, ["y"] = 1, ["z"] = 12, ["name"] = "cloud_items:ongen_small"}, {["x"] = 3, ["y"] = 2, ["z"] = 1, ["name"] = "cloud_items:ongen_small"}, {["x"] = 3, ["y"] = 2, ["z"] = 2, ["name"] = "cloud_items:ongen_small"}, {["x"] = 3, ["y"] = 2, ["z"] = 3, ["name"] = "cloud_items:ongen_small"}, {["x"] = 3, ["y"] = 2, ["z"] = 4, ["name"] = "cloud_items:ongen_small"}, {["x"] = 3, ["y"] = 2, ["z"] = 5, ["name"] = "cloud_items:ongen_small"}, {["x"] = 3, ["y"] = 2, ["z"] = 6, ["name"] = "cloud_items:ongen_small"}, {["x"] = 3, ["y"] = 2, ["z"] = 7, ["name"] = "cloud_items:ongen_small"}, {["x"] = 3, ["y"] = 2, ["z"] = 8, ["name"] = "cloud_items:ongen_small"}, {["x"] = 3, ["y"] = 2, ["z"] = 9, ["name"] = "cloud_items:ongen_small"}, {["x"] = 3, ["y"] = 2, ["z"] = 10, ["name"] = "cloud_items:ongen_small"}, {["x"] = 3, ["y"] = 2, ["z"] = 11, ["name"] = "cloud_items:ongen_small"}, {["x"] = 3, ["y"] = 3, ["z"] = 3, ["name"] = "cloud_items:ongen_small"}, {["x"] = 3, ["y"] = 3, ["z"] = 4, ["name"] = "cloud_items:ongen_small"}, {["x"] = 3, ["y"] = 3, ["z"] = 5, ["name"] = "cloud_items:ongen_small"}, {["x"] = 3, ["y"] = 3, ["z"] = 6, ["name"] = "cloud_items:ongen_small"}, {["x"] = 3, ["y"] = 3, ["z"] = 7, ["name"] = "cloud_items:ongen_small"}, {["x"] = 3, ["y"] = 3, ["z"] = 8, ["name"] = "cloud_items:ongen_small"}, {["x"] = 3, ["y"] = 3, ["z"] = 9, ["name"] = "cloud_items:ongen_small"}, {["x"] = 3, ["y"] = 4, ["z"] = 5, ["name"] = "cloud_items:ongen_small"}, {["x"] = 3, ["y"] = 4, ["z"] = 6, ["name"] = "cloud_items:ongen_small"}, {["x"] = 3, ["y"] = 4, ["z"] = 7, ["name"] = "cloud_items:ongen_small"}, {["x"] = 4, ["y"] = 1, ["z"] = 0, ["name"] = "cloud_items:ongen_small"}, {["x"] = 4, ["y"] = 1, ["z"] = 1, ["name"] = "cloud_items:ongen_small"}, {["x"] = 4, ["y"] = 1, ["z"] = 2, ["name"] = "cloud_items:ongen_small"}, {["x"] = 4, ["y"] = 1, ["z"] = 3, ["name"] = "cloud_items:ongen_small"}, {["x"] = 4, ["y"] = 1, ["z"] = 4, ["name"] = "cloud_items:ongen_small"}, {["x"] = 4, ["y"] = 1, ["z"] = 5, ["name"] = "cloud_items:ongen_small"}, {["x"] = 4, ["y"] = 1, ["z"] = 6, ["name"] = "cloud_items:ongen_small"}, {["x"] = 4, ["y"] = 1, ["z"] = 7, ["name"] = "cloud_items:ongen_small"}, {["x"] = 4, ["y"] = 1, ["z"] = 8, ["name"] = "cloud_items:ongen_small"}, {["x"] = 4, ["y"] = 1, ["z"] = 9, ["name"] = "cloud_items:ongen_small"}, {["x"] = 4, ["y"] = 1, ["z"] = 10, ["name"] = "cloud_items:ongen_small"}, {["x"] = 4, ["y"] = 1, ["z"] = 11, ["name"] = "cloud_items:ongen_small"}, {["x"] = 4, ["y"] = 1, ["z"] = 12, ["name"] = "cloud_items:ongen_small"}, {["x"] = 4, ["y"] = 2, ["z"] = 1, ["name"] = "cloud_items:ongen_small"}, {["x"] = 4, ["y"] = 2, ["z"] = 2, ["name"] = "cloud_items:ongen_small"}, {["x"] = 4, ["y"] = 2, ["z"] = 3, ["name"] = "cloud_items:ongen_small"}, {["x"] = 4, ["y"] = 2, ["z"] = 4, ["name"] = "cloud_items:ongen_small"}, {["x"] = 4, ["y"] = 2, ["z"] = 5, ["name"] = "cloud_items:ongen_small"}, {["x"] = 4, ["y"] = 2, ["z"] = 6, ["name"] = "cloud_items:ongen_small"}, {["x"] = 4, ["y"] = 2, ["z"] = 7, ["name"] = "cloud_items:ongen_small"}, {["x"] = 4, ["y"] = 2, ["z"] = 8, ["name"] = "cloud_items:ongen_small"}, {["x"] = 4, ["y"] = 2, ["z"] = 9, ["name"] = "cloud_items:ongen_small"}, {["x"] = 4, ["y"] = 2, ["z"] = 10, ["name"] = "cloud_items:ongen_small"}, {["x"] = 4, ["y"] = 2, ["z"] = 11, ["name"] = "cloud_items:ongen_small"}, {["x"] = 4, ["y"] = 3, ["z"] = 3, ["name"] = "cloud_items:ongen_small"}, {["x"] = 4, ["y"] = 3, ["z"] = 4, ["name"] = "cloud_items:ongen_small"}, {["x"] = 4, ["y"] = 3, ["z"] = 5, ["name"] = "cloud_items:ongen_small"}, {["x"] = 4, ["y"] = 3, ["z"] = 6, ["name"] = "cloud_items:ongen_small"}, {["x"] = 4, ["y"] = 3, ["z"] = 7, ["name"] = "cloud_items:ongen_small"}, {["x"] = 4, ["y"] = 3, ["z"] = 8, ["name"] = "cloud_items:ongen_small"}, {["x"] = 4, ["y"] = 3, ["z"] = 9, ["name"] = "cloud_items:ongen_small"}, {["x"] = 4, ["y"] = 4, ["z"] = 5, ["name"] = "cloud_items:ongen_small"}, {["x"] = 4, ["y"] = 4, ["z"] = 6, ["name"] = "cloud_items:ongen_small"}, {["x"] = 4, ["y"] = 4, ["z"] = 7, ["name"] = "cloud_items:ongen_small"}, {["x"] = 5, ["y"] = 1, ["z"] = 2, ["name"] = "cloud_items:ongen_small"}, {["x"] = 5, ["y"] = 1, ["z"] = 3, ["name"] = "cloud_items:ongen_small"}, {["x"] = 5, ["y"] = 1, ["z"] = 4, ["name"] = "cloud_items:ongen_small"}, {["x"] = 5, ["y"] = 1, ["z"] = 5, ["name"] = "cloud_items:ongen_small"}, {["x"] = 5, ["y"] = 1, ["z"] = 6, ["name"] = "cloud_items:ongen_small"}, {["x"] = 5, ["y"] = 1, ["z"] = 7, ["name"] = "cloud_items:ongen_small"}, {["x"] = 5, ["y"] = 1, ["z"] = 8, ["name"] = "cloud_items:ongen_small"}, {["x"] = 5, ["y"] = 1, ["z"] = 9, ["name"] = "cloud_items:ongen_small"}, {["x"] = 5, ["y"] = 1, ["z"] = 10, ["name"] = "cloud_items:ongen_small"}, {["x"] = 5, ["y"] = 2, ["z"] = 3, ["name"] = "cloud_items:ongen_small"}, {["x"] = 5, ["y"] = 2, ["z"] = 4, ["name"] = "cloud_items:ongen_small"}, {["x"] = 5, ["y"] = 2, ["z"] = 5, ["name"] = "cloud_items:ongen_small"}, {["x"] = 5, ["y"] = 2, ["z"] = 6, ["name"] = "cloud_items:ongen_small"}, {["x"] = 5, ["y"] = 2, ["z"] = 7, ["name"] = "cloud_items:ongen_small"}, {["x"] = 5, ["y"] = 2, ["z"] = 8, ["name"] = "cloud_items:ongen_small"}, {["x"] = 5, ["y"] = 2, ["z"] = 9, ["name"] = "cloud_items:ongen_small"}, {["x"] = 5, ["y"] = 3, ["z"] = 4, ["name"] = "cloud_items:ongen_small"}, {["x"] = 5, ["y"] = 3, ["z"] = 5, ["name"] = "cloud_items:ongen_small"}, {["x"] = 5, ["y"] = 3, ["z"] = 6, ["name"] = "cloud_items:ongen_small"}, {["x"] = 5, ["y"] = 3, ["z"] = 7, ["name"] = "cloud_items:ongen_small"}, {["x"] = 5, ["y"] = 3, ["z"] = 8, ["name"] = "cloud_items:ongen_small"}, {["x"] = 6, ["y"] = 1, ["z"] = 2, ["name"] = "cloud_items:ongen_small"}, {["x"] = 6, ["y"] = 1, ["z"] = 3, ["name"] = "cloud_items:ongen_small"}, {["x"] = 6, ["y"] = 1, ["z"] = 4, ["name"] = "cloud_items:ongen_small"}, {["x"] = 6, ["y"] = 1, ["z"] = 5, ["name"] = "cloud_items:ongen_small"}, {["x"] = 6, ["y"] = 1, ["z"] = 6, ["name"] = "cloud_items:ongen_small"}, {["x"] = 6, ["y"] = 1, ["z"] = 7, ["name"] = "cloud_items:ongen_small"}, {["x"] = 6, ["y"] = 1, ["z"] = 8, ["name"] = "cloud_items:ongen_small"}, {["x"] = 6, ["y"] = 1, ["z"] = 9, ["name"] = "cloud_items:ongen_small"}, {["x"] = 6, ["y"] = 2, ["z"] = 4, ["name"] = "cloud_items:ongen_small"}, {["x"] = 6, ["y"] = 2, ["z"] = 5, ["name"] = "cloud_items:ongen_small"}, {["x"] = 6, ["y"] = 2, ["z"] = 6, ["name"] = "cloud_items:ongen_small"}, {["x"] = 6, ["y"] = 2, ["z"] = 7, ["name"] = "cloud_items:ongen_small"}, {["x"] = 6, ["y"] = 2, ["z"] = 8, ["name"] = "cloud_items:ongen_small"}, {["x"] = 7, ["y"] = 1, ["z"] = 4, ["name"] = "cloud_items:ongen_small"}, {["x"] = 7, ["y"] = 1, ["z"] = 5, ["name"] = "cloud_items:ongen_small"}, {["x"] = 7, ["y"] = 1, ["z"] = 6, ["name"] = "cloud_items:ongen_small"}, {["x"] = 7, ["y"] = 1, ["z"] = 7, ["name"] = "cloud_items:ongen_small"}, {["x"] = 7, ["y"] = 1, ["z"] = 8, ["name"] = "cloud_items:ongen_small"}, {["x"] = 7, ["y"] = 2, ["z"] = 5, ["name"] = "cloud_items:ongen_small"}, {["x"] = 7, ["y"] = 2, ["z"] = 6, ["name"] = "cloud_items:ongen_small"}, {["x"] = 7, ["y"] = 2, ["z"] = 7, ["name"] = "cloud_items:ongen_small"}, {["x"] = 8, ["y"] = 1, ["z"] = 5, ["name"] = "cloud_items:ongen_small"}, {["x"] = 8, ["y"] = 1, ["z"] = 6, ["name"] = "cloud_items:ongen_small"}, {["x"] = 8, ["y"] = 1, ["z"] = 7, ["name"] = "cloud_items:ongen_small"}}